Workbook

Sheet weekly_reporting_2025
A1: DATA SOURCE: Reports>Business Reports>Detail Page Sales Traffic By Parent
C2: WEEKLY PERFORMANCE | X2: =(#REF!+#REF!+#REF!+#REF!)-(monthly_reporting_2021!D17+monthly_reporting_2021!D23+monthly_reporting_2021!D29+monthly_reporting_2021!D35) -> #REF! | Y2: =((#REF!+#REF!+#REF!+#REF!)-(monthly_reporting_2021!E17+monthly_reporting_2021!E23+monthly_reporting_2021!E29+monthly_reporting_2021!E35))/(#REF!+#REF!+#REF!+#REF!) -> #REF!
C3: Total Sales | F3: Total Orders | K3: Total Units Sold
C4: =VLOOKUP("Current Week",$B$11:$Z$475,MATCH("SALES",$B$11:$Z$11,0),FALSE) -> 51870.5 | F4: =VLOOKUP("Current Week",$B$11:$Z$475,MATCH("Units Sold",$B$11:$Z$11,0),FALSE) -> 863 | K4: =VLOOKUP("Current Week",$B$11:$Z$475,MATCH("Ordered Items",$B$11:$Z$11,0),FALSE) -> 789
C5: =(C4-(VLOOKUP("Previous Week",$B$11:$Z$479,MATCH("SALES",$B$11:$Z$11,0),FALSE)))/C4 -> 0.15463606 | F5: =(F4-(VLOOKUP("Previous Week",$B$11:$Z$489,MATCH("Units Sold",$B$11:$Z$11,0),FALSE)))/F4 -> 0.16801854 | K5: =(K4-(VLOOKUP("Previous Week",$B$11:$Z$489,MATCH("Ordered Items",$B$11:$Z$11,0),FALSE)))/K4 -> 0.17490494
C7: Advertising Sales | F7: Advertising Spend | K7: ACoS
C8: =VLOOKUP("Current Week",$B$11:$Z$475,MATCH("AD SALES",$B$11:$Z$11,0),FALSE) -> 15352.2 | F8: =VLOOKUP("Current Week",$B$11:$Z$475,MATCH("SP AD SPEND",$B$11:$Z$11,0),FALSE) -> 7606.26 | K8: =F8/C8 -> 0.49545081
C9: =(C8-(VLOOKUP("Previous Week",$B$11:$Z$489,MATCH("AD SALES",$B$11:$Z$11,0),FALSE)))/C8 -> 0.044404059 | F9: =(F8-(VLOOKUP("Previous Week",$B$11:$Z$489,MATCH("SP AD SPEND",$B$11:$Z$11,0),FALSE)))/F8 -> 0.15952255 | K9: =(K8-(VLOOKUP("Previous Week",$B$11:$Z$489,MATCH("ACOS",$B$11:$Z$11,0),FALSE)))/K8 -> 0.12046775
D10: SALES METRICS | L10: ADVERTISING PERFORMANCE | V10: MoM | X10: YoY
A11: Month-Code | B11: DATE | C11: BRAND | D11: SALES | E11: UNITS SOLD | F11: ORDERED ITEMS | G11: UNITS PER ORDER | H11: SALES PER ORDER | I11: ASP | J11: SESSIONS (traffic) | K11: ORDERS PER SESSION (conversion) | L11: SP AD SPEND | M11: IMPRESSIONS | N11: UNIT SALES | O11: AD SALES | P11: ACoS | Q11: ROAS (return on ad send) | R11: TACoS (Total Advertsing Cost of Sales) | S11: REVENUE PERCENTAGE OF AD SALES | T11: ORGANIC SALES | U11: CPO | V11: SALES | W11: UNITS | X11: SALES | Y11: UNITS
A13: =IFERROR(IF(B13>0,MONTH(B13)&"-"&YEAR(B13),B13),) -> 12-2024 | B13: 45641 | C13: BeFlexible | D13: 489.65 | E13: 7 | F13: 6 | G13: =E13/F13 -> 1.1666667 | H13: =D13/E13 -> 69.95 | I13: =H13/G13 -> 59.957143 | J13: 43 | K13: =E13/J13 -> 0.1627907 | L13: 15.24 | M13: 3203 | N13: 0 | O13: 0 | P13: =L13/O13 -> #DIV/0! | Q13: =O13/L13 -> 0 | R13: =L13/D13 -> 0.031124272 | S13: =O13/D13 -> 0 | T13: =D13-O13 -> 489.65 | U13: =L13/N13 -> #DIV/0!
A14: =IFERROR(IF(B14>0,MONTH(B14)&"-"&YEAR(B14),B14),) -> 0 | C14: Better Bladder | D14: 15008.3 | E14: 215 | F14: 204 | G14: =E14/F14 -> 1.0539216 | H14: =D14/E14 -> 69.806047 | I14: =H14/G14 -> 66.234574 | J14: 1544 | K14: =E14/J14 -> 0.1392487 | L14: 1231.04 | M14: 184121 | N14: 62 | O14: 4371.6 | P14: =L14/O14 -> 0.28159941 | Q14: =O14/L14 -> 3.5511437 | R14: =L14/D14 -> 0.082023947 | S14: =O14/D14 -> 0.29127883 | T14: =D14-O14 -> 10636.7 | U14: =L14/N14 -> 19.855484
A15: =IFERROR(IF(B15>0,MONTH(B15)&"-"&YEAR(B15),B15),) -> 0 | C15: Grown American | D15: 5190.9 | E15: 82 | F15: 78 | G15: =E15/F15 -> 1.0512821 | H15: =D15/E15 -> 63.303659 | I15: =H15/G15 -> 60.215675 | J15: 444 | K15: =E15/J15 -> 0.18468468 | L15: 336.89 | M15: 53355 | N15: 11 | O15: 729.3 | P15: =L15/O15 -> 0.4619361 | Q15: =O15/L15 -> 2.1648016 | R15: =L15/D15 -> 0.064900114 | S15: =O15/D15 -> 0.14049587 | T15: =D15-O15 -> 4461.6 | U15: =L15/N15 -> 30.626364
A16: =IFERROR(IF(B16>0,MONTH(B16)&"-"&YEAR(B16),B16),) -> 0 | C16: Ideal Prostate | D16: 13598.13 | E16: 186 | F16: 177 | G16: =E16/F16 -> 1.0508475 | H16: =D16/E16 -> 73.108226 | I16: =H16/G16 -> 69.570731 | J16: 1053 | K16: =E16/J16 -> 0.17663818 | L16: 1329.14 | M16: 152039 | N16: 63 | O16: 4588.39 | P16: =L16/O16 -> 0.28967459 | Q16: =O16/L16 -> 3.4521495 | R16: =L16/D16 -> 0.097744322 | S16: =O16/D16 -> 0.33742801 | T16: =D16-O16 -> 9009.74 | U16: =L16/N16 -> 21.09746
C17: Prosvent | D17: 34530 | E17: 594 | F17: 534 | G17: =E17/F17 -> 1.1123596 | H17: =D17/E17 -> 58.131313 | I17: =H17/G17 -> 52.259463 | J17: 1945 | K17: =E17/J17 -> 0.30539846 | L17: 3165.15 | M17: 334486 | N17: 151 | O17: 9555 | P17: =L17/O17 -> 0.33125589 | Q17: =O17/L17 -> 3.0188143 | R17: =L17/D17 -> 0.091663771 | S17: =O17/D17 -> 0.2767159 | T17: =D17-O17 -> 24975 | U17: =L17/N17 -> 20.961258
C18: Cebria | D18: 2877 | E18: 77 | F18: 66 | G18: =E18/F18 -> 1.1666667 | H18: =D18/E18 -> 37.363636 | I18: =H18/G18 -> 32.025974 | J18: 178 | K18: =E18/J18 -> 0.43258427 | L18: 204.18 | M18: 110559 | N18: 12 | O18: 531 | P18: =L18/O18 -> 0.38451977 | Q18: =O18/L18 -> 2.6006465 | R18: =L18/D18 -> 0.07096976 | S18: =O18/D18 -> 0.18456726 | T18: =D18-O18 -> 2346 | U18: =L18/N18 -> 17.015
A19: =IFERROR(IF(B19>0,MONTH(B19)&"-"&YEAR(B19),B19),) -> 12-2024 | B19: 45647 | C19: Profemin | D19: 1483.65 | E19: 27 | F19: 26 | G19: =E19/F19 -> 1.0384615 | H19: =D19/E19 -> 54.95 | I19: =H19/G19 -> 52.914815 | J19: 57 | K19: =E19/J19 -> 0.47368421 | L19: 45.57 | M19: 9880 | N19: 1 | O19: 54.95 | P19: =L19/O19 -> 0.82929936 | Q19: =O19/L19 -> 1.2058372 | R19: =L19/D19 -> 0.030714791 | S19: =O19/D19 -> 0.037037037 | T19: =D19-O19 -> 1428.7 | U19: =L19/N19 -> 45.57
A20: =IFERROR(IF(B20>0,MONTH(B20)&"-"&YEAR(B20),B20),) -> 0 | B20: 2024 - Week 51 | D20: =SUM(D13:D19) -> 73177.63 | E20: =SUM(E13:E19) -> 1188 | F20: =SUM(F13:F19) -> 1091 | G20: =E20/F20 -> 1.0889093 | H20: =D20/E20 -> 61.597332 | I20: =H20/G20 -> 56.56792 | J20: =SUM(J13:J19) -> 5264 | K20: =E20/J20 -> 0.22568389 | L20: =SUM(L13:L19) -> 6327.21 | M20: =SUM(M13:M19) -> 847643 | N20: =SUM(N13:N19) -> 300 | O20: =SUM(O13:O19) -> 19830.24 | P20: =L20/O20 -> 0.31906876 | Q20: =O20/L20 -> 3.1341207 | R20: =L20/D20 -> 0.086463718 | S20: =O20/D20 -> 0.27098773 | T20: =SUM(T13:T19) -> 53347.39 | U20: =L20/N20 -> 21.0907 | V20: =IFERROR((D20-#REF!)/D20,) -> 0 | W20: =IFERROR((E20-#REF!)/E20,) -> 0 | X20: =IFERROR((D20-#REF!)/D20,) -> 0 | Y20: =IFERROR((E20-#REF!)/E20,) -> 0
A21: =IFERROR(IF(B21>0,MONTH(B21)&"-"&YEAR(B21),B21),) -> 12-2024 | B21: 45648 | C21: BeFlexible | D21: 279.8 | E21: 4 | F21: 4 | G21: =E21/F21 -> 1 | H21: =D21/E21 -> 69.95 | I21: =H21/G21 -> 69.95 | J21: 39 | K21: =E21/J21 -> 0.1025641 | L21: 31.25 | M21: 2623 | N21: 0 | O21: 0 | P21: =L21/O21 -> #DIV/0! | Q21: =O21/L21 -> 0 | R21: =L21/D21 -> 0.11168692 | S21: =O21/D21 -> 0 | T21: =D21-O21 -> 279.8 | U21: =L21/N21 -> #DIV/0!
A22: =IFERROR(IF(B22>0,MONTH(B22)&"-"&YEAR(B22),B22),) -> 0 | C22: Better Bladder | D22: 12879.85 | E22: 189 | F22: 180 | G22: =E22/F22 -> 1.05 | H22: =D22/E22 -> 68.147354 | I22: =H22/G22 -> 64.902242 | J22: 1603 | K22: =E22/J22 -> 0.11790393 | L22: 1300.66 | M22: 190376 | N22: 48 | O22: 3487.2 | P22: =L22/O22 -> 0.37298119 | Q22: =O22/L22 -> 2.6811004 | R22: =L22/D22 -> 0.1009841 | S22: =O22/D22 -> 0.27074849 | T22: =D22-O22 -> 9392.65 | U22: =L22/N22 -> 27.097083
A23: =IFERROR(IF(B23>0,MONTH(B23)&"-"&YEAR(B23),B23),) -> 0 | C23: Grown American | D23: 3756.9 | E23: 62 | F23: 55 | G23: =E23/F23 -> 1.1272727 | H23: =D23/E23 -> 60.595161 | I23: =H23/G23 -> 53.753772 | J23: 392 | K23: =E23/J23 -> 0.15816327 | L23: 329.68 | M23: 68679 | N23: 13 | O23: 634.35 | P23: =L23/O23 -> 0.51971309 | Q23: =O23/L23 -> 1.9241386 | R23: =L23/D23 -> 0.087753201 | S23: =O23/D23 -> 0.16884932 | T23: =D23-O23 -> 3122.55 | U23: =L23/N23 -> 25.36
A24: =IFERROR(IF(B24>0,MONTH(B24)&"-"&YEAR(B24),B24),) -> 0 | C24: Ideal Prostate | D24: 10387.44 | E24: 131 | F24: 120 | G24: =E24/F24 -> 1.0916667 | H24: =D24/E24 -> 79.293435 | I24: =H24/G24 -> 72.635208 | J24: 969 | K24: =E24/J24 -> 0.13519092 | L24: 1540.56 | M24: 102909 | N24: 66 | O24: 5670.95 | P24: =L24/O24 -> 0.27165819 | Q24: =O24/L24 -> 3.6810965 | R24: =L24/D24 -> 0.14830988 | S24: =O24/D24 -> 0.54594298 | T24: =D24-O24 -> 4716.49 | U24: =L24/N24 -> 23.341818
C25: Prosvent | D25: 33136 | E25: 568 | F25: 515 | G25: =E25/F25 -> 1.1029126 | H25: =D25/E25 -> 58.338028 | I25: =H25/G25 -> 52.894515 | J25: 2313 | K25: =E25/J25 -> 0.24556853 | L25: 3748.29 | M25: 348947 | N25: 152 | O25: 9816 | P25: =L25/O25 -> 0.38185513 | Q25: =O25/L25 -> 2.6187942 | R25: =L25/D25 -> 0.11311836 | S25: =O25/D25 -> 0.2962337 | T25: =D25-O25 -> 23320 | U25: =L25/N25 -> 24.659803
C26: Cebria | D26: 2142 | E26: 58 | F26: 51 | G26: =E26/F26 -> 1.1372549 | H26: =D26/E26 -> 36.931034 | I26: =H26/G26 -> 32.473841 | J26: 147 | K26: =E26/J26 -> 0.39455782 | L26: 148.3 | M26: 102280 | N26: 6 | O26: 231 | P26: =L26/O26 -> 0.64199134 | Q26: =O26/L26 -> 1.5576534 | R26: =L26/D26 -> 0.06923436 | S26: =O26/D26 -> 0.10784314 | T26: =D26-O26 -> 1911 | U26: =L26/N26 -> 24.716667
A27: =IFERROR(IF(B27>0,MONTH(B27)&"-"&YEAR(B27),B27),) -> 12-2024 | B27: 45654 | C27: Profemin | D27: 2088.1 | E27: 38 | F27: 31 | G27: =E27/F27 -> 1.2258065 | H27: =D27/E27 -> 54.95 | I27: =H27/G27 -> 44.827632 | J27: 109 | K27: =E27/J27 -> 0.34862385 | L27: 167.05 | M27: 23736 | N27: 4 | O27: 274.75 | P27: =L27/O27 -> 0.60800728 | Q27: =O27/L27 -> 1.6447172 | R27: =L27/D27 -> 0.080000958 | S27: =O27/D27 -> 0.13157895 | T27: =D27-O27 -> 1813.35 | U27: =L27/N27 -> 41.7625
A28: =IFERROR(IF(B28>0,MONTH(B28)&"-"&YEAR(B28),B28),) -> 0 | B28: 2024 - Week 52 | D28: =SUM(D21:D27) -> 64670.09 | E28: =SUM(E21:E27) -> 1050 | F28: =SUM(F21:F27) -> 956 | G28: =E28/F28 -> 1.0983264 | H28: =D28/E28 -> 61.590562 | I28: =H28/G28 -> 56.07674 | J28: =SUM(J21:J27) -> 5572 | K28: =E28/J28 -> 0.18844221 | L28: =SUM(L21:L27) -> 7265.79 | M28: =SUM(M21:M27) -> 839550 | N28: =SUM(N21:N27) -> 289 | O28: =SUM(O21:O27) -> 20114.25 | P28: =L28/O28 -> 0.361226 | Q28: =O28/L28 -> 2.76835 | R28: =L28/D28 -> 0.11235163 | S28: =O28/D28 -> 0.31102864 | T28: =SUM(T21:T27) -> 44555.84 | U28: =L28/N28 -> 25.141142 | V28: =IFERROR((D28-#REF!)/D28,) -> 0 | W28: =IFERROR((E28-#REF!)/E28,) -> 0 | X28: =IFERROR((D28-#REF!)/D28,) -> 0 | Y28: =IFERROR((E28-#REF!)/E28,) -> 0
A29: =IFERROR(IF(B29>0,MONTH(B29)&"-"&YEAR(B29),B29),) -> 12-2024 | B29: 45655 | C29: BeFlexible | D29: 559.6 | E29: 8 | F29: 4 | G29: =E29/F29 -> 2 | H29: =D29/E29 -> 69.95 | I29: =H29/G29 -> 34.975 | J29: 30 | K29: =E29/J29 -> 0.26666667 | L29: 27.25 | M29: 4171 | N29: 0 | O29: 0 | P29: =L29/O29 -> #DIV/0! | Q29: =O29/L29 -> 0 | R29: =L29/D29 -> 0.048695497 | S29: =O29/D29 -> 0 | T29: =D29-O29 -> 559.6 | U29: =L29/N29 -> #DIV/0!
A30: =IFERROR(IF(B30>0,MONTH(B30)&"-"&YEAR(B30),B30),) -> 0 | C30: Better Bladder | D30: 14778.45 | E30: 216 | F30: 204 | G30: =E30/F30 -> 1.0588235 | H30: =D30/E30 -> 68.41875 | I30: =H30/G30 -> 64.617708 | J30: 2053 | K30: =E30/J30 -> 0.10521189 | L30: 1911.36 | M30: 277055 | N30: 68 | O30: 5056.2 | P30: =L30/O30 -> 0.37802302 | Q30: =O30/L30 -> 2.6453415 | R30: =L30/D30 -> 0.12933427 | S30: =O30/D30 -> 0.34213331 | T30: =D30-O30 -> 9722.25 | U30: =L30/N30 -> 28.108235
A31: =IFERROR(IF(B31>0,MONTH(B31)&"-"&YEAR(B31),B31),) -> 0 | C31: Grown American | D31: 5605.6 | E31: 89 | F31: 82 | G31: =E31/F31 -> 1.0853659 | H31: =D31/E31 -> 62.98427 | I31: =H31/G31 -> 58.030451 | J31: 468 | K31: =E31/J31 -> 0.19017094 | L31: 421.12 | M31: 83864 | N31: 17 | O31: 1029 | P31: =L31/O31 -> 0.4092517 | Q31: =O31/L31 -> 2.443484 | R31: =L31/D31 -> 0.075124875 | S31: =O31/D31 -> 0.18356643 | T31: =D31-O31 -> 4576.6 | U31: =L31/N31 -> 24.771765
A32: =IFERROR(IF(B32>0,MONTH(B32)&"-"&YEAR(B32),B32),) -> 0 | C32: Ideal Prostate | D32: 10854.18 | E32: 134 | F32: 129 | G32: =E32/F32 -> 1.0387597 | H32: =D32/E32 -> 81.001343 | I32: =H32/G32 -> 77.978905 | J32: 1067 | K32: =E32/J32 -> 0.12558575 | L32: 1570.8 | M32: 147200 | N32: 50 | O32: 3951.17 | P32: =L32/O32 -> 0.39755313 | Q32: =O32/L32 -> 2.5153871 | R32: =L32/D32 -> 0.14471844 | S32: =O32/D32 -> 0.36402289 | T32: =D32-O32 -> 6903.01 | U32: =L32/N32 -> 31.416
C33: Prosvent | D33: 38341 | E33: 656 | F33: 594 | G33: =E33/F33 -> 1.1043771 | H33: =D33/E33 -> 58.446646 | I33: =H33/G33 -> 52.922725 | J33: 2883 | K33: =E33/J33 -> 0.22754076 | L33: 4657.15 | M33: 569735 | N33: 220 | O33: 13822 | P33: =L33/O33 -> 0.33693749 | Q33: =O33/L33 -> 2.9679096 | R33: =L33/D33 -> 0.12146658 | S33: =O33/D33 -> 0.36050181 | T33: =D33-O33 -> 24519 | U33: =L33/N33 -> 21.168864
C34: Cebria | D34: 3417 | E34: 92 | F34: 76 | G34: =E34/F34 -> 1.2105263 | H34: =D34/E34 -> 37.141304 | I34: =H34/G34 -> 30.681947 | J34: 245 | K34: =E34/J34 -> 0.3755102 | L34: 346.37 | M34: 173145 | N34: 23 | O34: 906 | P34: =L34/O34 -> 0.38230684 | Q34: =O34/L34 -> 2.6157 | R34: =L34/D34 -> 0.1013667 | S34: =O34/D34 -> 0.26514486 | T34: =D34-O34 -> 2511 | U34: =L34/N34 -> 15.059565
A35: =IFERROR(IF(B35>0,MONTH(B35)&"-"&YEAR(B35),B35),) -> 1-2025 | B35: 45661 | C35: Profemin | D35: 1923.25 | E35: 36 | F35: 30 | G35: =E35/F35 -> 1.2 | H35: =D35/E35 -> 53.423611 | I35: =H35/G35 -> 44.519676 | J35: 187 | K35: =E35/J35 -> 0.19251337 | L35: 279.84 | M35: 58995 | N35: 3 | O35: 219.8 | P35: =L35/O35 -> 1.2731574 | Q35: =O35/L35 -> 0.78544883 | R35: =L35/D35 -> 0.1455037 | S35: =O35/D35 -> 0.11428571 | T35: =D35-O35 -> 1703.45 | U35: =L35/N35 -> 93.28
A36: =IFERROR(IF(B36>0,MONTH(B36)&"-"&YEAR(B36),B36),) -> 0 | B36: 2025 - Week 1 | D36: =SUM(D29:D35) -> 75479.08 | E36: =SUM(E29:E35) -> 1231 | F36: =SUM(F29:F35) -> 1119 | G36: =E36/F36 -> 1.1000894 | H36: =D36/E36 -> 61.315256 | I36: =H36/G36 -> 55.736614 | J36: =SUM(J29:J35) -> 6933 | K36: =E36/J36 -> 0.17755661 | L36: =SUM(L29:L35) -> 9213.89 | M36: =SUM(M29:M35) -> 1314165 | N36: =SUM(N29:N35) -> 381 | O36: =SUM(O29:O35) -> 24984.17 | P36: =L36/O36 -> 0.36878912 | Q36: =O36/L36 -> 2.7115768 | R36: =L36/D36 -> 0.1220721 | S36: =O36/D36 -> 0.33100788 | T36: =SUM(T29:T35) -> 50494.91 | U36: =L36/N36 -> 24.183438 | V36: =IFERROR((D36-#REF!)/D36,) -> 0 | W36: =IFERROR((E36-#REF!)/E36,) -> 0 | X36: =IFERROR((D36-#REF!)/D36,) -> 0 | Y36: =IFERROR((E36-#REF!)/E36,) -> 0
A37: =IFERROR(IF(B37>0,MONTH(B37)&"-"&YEAR(B37),B37),) -> 1-2025 | B37: 45662 | C37: BeFlexible | D37: 279.8 | E37: 4 | F37: 4 | G37: =E37/F37 -> 1 | H37: =D37/E37 -> 69.95 | I37: =H37/G37 -> 69.95 | J37: 39 | K37: =E37/J37 -> 0.1025641 | L37: 19.2 | M37: 3087 | N37: 0 | O37: 0 | P37: =L37/O37 -> #DIV/0! | Q37: =O37/L37 -> 0 | R37: =L37/D37 -> 0.068620443 | S37: =O37/D37 -> 0 | T37: =D37-O37 -> 279.8 | U37: =L37/N37 -> #DIV/0!
A38: =IFERROR(IF(B38>0,MONTH(B38)&"-"&YEAR(B38),B38),) -> 0 | C38: Better Bladder | D38: 13819.1 | E38: 200 | F38: 189 | G38: =E38/F38 -> 1.0582011 | H38: =D38/E38 -> 69.0955 | I38: =H38/G38 -> 65.295248 | J38: 1916 | K38: =E38/J38 -> 0.10438413 | L38: 1928.76 | M38: 254417 | N38: 63 | O38: 4683.4 | P38: =L38/O38 -> 0.41182901 | Q38: =O38/L38 -> 2.4281922 | R38: =L38/D38 -> 0.13957204 | S38: =O38/D38 -> 0.33890774 | T38: =D38-O38 -> 9135.7 | U38: =L38/N38 -> 30.615238
A39: =IFERROR(IF(B39>0,MONTH(B39)&"-"&YEAR(B39),B39),) -> 0 | C39: Grown American | D39: 3631.95 | E39: 61 | F39: 57 | G39: =E39/F39 -> 1.0701754 | H39: =D39/E39 -> 59.540164 | I39: =H39/G39 -> 55.635891 | J39: 402 | K39: =E39/J39 -> 0.15174129 | L39: 257.2 | M39: 39572 | N39: 9 | O39: 499.5 | P39: =L39/O39 -> 0.51491491 | Q39: =O39/L39 -> 1.9420684 | R39: =L39/D39 -> 0.070815953 | S39: =O39/D39 -> 0.13752943 | T39: =D39-O39 -> 3132.45 | U39: =L39/N39 -> 28.577778
A40: =IFERROR(IF(B40>0,MONTH(B40)&"-"&YEAR(B40),B40),) -> 0 | C40: Ideal Prostate | D40: 15291.29 | E40: 212 | F40: 198 | G40: =E40/F40 -> 1.0707071 | H40: =D40/E40 -> 72.128726 | I40: =H40/G40 -> 67.365509 | J40: 1288 | K40: =E40/J40 -> 0.16459627 | L40: 1913.77 | M40: 275572 | N40: 66 | O40: 5665.75 | P40: =L40/O40 -> 0.33777876 | Q40: =O40/L40 -> 2.9605177 | R40: =L40/D40 -> 0.12515425 | S40: =O40/D40 -> 0.37052139 | T40: =D40-O40 -> 9625.54 | U40: =L40/N40 -> 28.996515
C41: Prosvent | D41: 36716 | E41: 634 | F41: 568 | G41: =E41/F41 -> 1.1161972 | H41: =D41/E41 -> 57.911672 | I41: =H41/G41 -> 51.883012 | J41: 2505 | K41: =E41/J41 -> 0.25309381 | L41: 4100.36 | M41: 596258 | N41: 193 | O41: 12410.95 | P41: =L41/O41 -> 0.33038244 | Q41: =O41/L41 -> 3.0267952 | R41: =L41/D41 -> 0.11167774 | S41: =O41/D41 -> 0.33802566 | T41: =D41-O41 -> 24305.05 | U41: =L41/N41 -> 21.245389
C42: Cebria | D42: 2403 | E42: 65 | F42: 58 | G42: =E42/F42 -> 1.1206897 | H42: =D42/E42 -> 36.969231 | I42: =H42/G42 -> 32.987929 | J42: 242 | K42: =E42/J42 -> 0.26859504 | L42: 352.75 | M42: 181718 | N42: 16 | O42: 603 | P42: =L42/O42 -> 0.58499171 | Q42: =O42/L42 -> 1.7094259 | R42: =L42/D42 -> 0.14679567 | S42: =O42/D42 -> 0.25093633 | T42: =D42-O42 -> 1800 | U42: =L42/N42 -> 22.046875
...

Sheet weekly_reporting_2025_idealPros
A1: DATA SOURCE: Detail Page Sales and Traffic
C2: WEEKLY PERFORMANCE | X2: =(#REF!+#REF!+#REF!+#REF!)-(monthly_reporting_2021!D17+monthly_reporting_2021!D23+monthly_reporting_2021!D29+monthly_reporting_2021!D35) -> #REF! | Y2: =((#REF!+#REF!+#REF!+#REF!)-(monthly_reporting_2021!E17+monthly_reporting_2021!E23+monthly_reporting_2021!E29+monthly_reporting_2021!E35))/(#REF!+#REF!+#REF!+#REF!) -> #REF!
C3: Total Sales | F3: Total Orders | K3: Total Units Sold
C4: =VLOOKUP("Current Week",$B$11:$Z$146,MATCH("SALES",$B$11:$Z$11,0),FALSE) -> 9462.3 | F4: =VLOOKUP("Current Week",$B$11:$Z$146,MATCH("Units Sold",$B$11:$Z$11,0),FALSE) -> 154 | K4: =VLOOKUP("Current Week",$B$11:$Z$146,MATCH("Ordered Items",$B$11:$Z$11,0),FALSE) -> 145
C5: =(C4-(VLOOKUP("Previous Week",$B$11:$Z$156,MATCH("SALES",$B$11:$Z$11,0),FALSE)))/C4 -> 0.052788434 | F5: =(F4-(VLOOKUP("Previous Week",$B$11:$Z$156,MATCH("Units Sold",$B$11:$Z$11,0),FALSE)))/F4 -> 0.064935065 | K5: =(K4-(VLOOKUP("Previous Week",$B$11:$Z$156,MATCH("Ordered Items",$B$11:$Z$11,0),FALSE)))/K4 -> 0.10344828
C7: Advertising Sales | F7: Advertising Spend | K7: ACoS
C8: =VLOOKUP("Current Week",$B$11:$Z$146,MATCH("AD SALES",$B$11:$Z$11,0),FALSE) -> 0 | F8: =VLOOKUP("Current Week",$B$11:$Z$146,MATCH("SP AD SPEND",$B$11:$Z$11,0),FALSE) -> 0 | K8: =F8/C8 -> #DIV/0!
C9: =(C8-(VLOOKUP("Previous Week",$B$11:$Z$156,MATCH("AD SALES",$B$11:$Z$11,0),FALSE)))/C8 -> #DIV/0! | F9: =(F8-(VLOOKUP("Previous Week",$B$11:$Z$156,MATCH("SP AD SPEND",$B$11:$Z$11,0),FALSE)))/F8 -> #DIV/0! | K9: =(K8-(VLOOKUP("Previous Week",$B$11:$Z$156,MATCH("ACOS",$B$11:$Z$11,0),FALSE)))/K8 -> #DIV/0!
D10: SALES METRICS | L10: ADVERTISING PERFORMANCE | V10: MoM | X10: YoY
A11: Month-Code | B11: DATE | C11: BRAND | D11: SALES | E11: UNITS SOLD | F11: ORDERED ITEMS | G11: UNITS PER ORDER | H11: SALES PER ORDER | I11: ASP | J11: SESSIONS (traffic) | K11: ORDERS PER SESSION (conversion) | L11: SP AD SPEND | M11: IMPRESSIONS | N11: UNIT SALES | O11: AD SALES | P11: ACoS | Q11: ROAS (return on ad send) | R11: TACoS (Total Advertsing Cost of Sales) | S11: REVENUE PERCENTAGE OF AD SALES | T11: ORGANIC SALES | U11: CPO | V11: SALES | W11: UNITS | X11: SALES | Y11: UNITS
A13: =IFERROR(IF(B13>0,MONTH(B13)&"-"&YEAR(B13),B13),) -> 3-2025 | B13: 45739 | C13: Ideal Prostate (B08BQ7JTP5) | D13: 5515.4 | E13: 92 | F13: 86 | G13: =E13/F13 -> 1.0697674 | H13: =D13/E13 -> 59.95 | I13: =H13/G13 -> 56.040217 | J13: 501 | K13: =E13/J13 -> 0.18363273
A14: =IFERROR(IF(B14>0,MONTH(B14)&"-"&YEAR(B14),B14),) -> 3-2025 | B14: 45745 | C14: Ideal Prostate Ultra (B08BQ8LGDS) | D14: 1888.65 | E14: 27 | F14: 23 | G14: =E14/F14 -> 1.173913 | H14: =D14/E14 -> 69.95 | I14: =H14/G14 -> 59.587037 | J14: 203 | K14: =E14/J14 -> 0.13300493
A15: =IFERROR(IF(B15>0,MONTH(B15)&"-"&YEAR(B15),B15),) -> 0 | B15: 2025 - Week 13 | D15: =SUM(D13:D14) -> 7404.05 | E15: =SUM(E13:E14) -> 119 | F15: =SUM(F13:F14) -> 109 | G15: =E15/F15 -> 1.0917431 | H15: =D15/E15 -> 62.218908 | I15: =H15/G15 -> 56.990428 | J15: =SUM(J13:J14) -> 704 | K15: =E15/J15 -> 0.16903409 | V15: =IFERROR((D15-#REF!)/D15,) -> 0 | W15: =IFERROR((E15-#REF!)/E15,) -> 0 | X15: =IFERROR((D15-#REF!)/D15,) -> 0 | Y15: =IFERROR((E15-#REF!)/E15,) -> 0
A16: =IFERROR(IF(B16>0,MONTH(B16)&"-"&YEAR(B16),B16),) -> 3-2025 | B16: 45746 | C16: Ideal Prostate | D16: 8393 | E16: 140 | F16: 120 | G16: =E16/F16 -> 1.1666667 | H16: =D16/E16 -> 59.95 | I16: =H16/G16 -> 51.385714 | J16: 630 | K16: =E16/J16 -> 0.22222222
A17: =IFERROR(IF(B17>0,MONTH(B17)&"-"&YEAR(B17),B17),) -> 4-2025 | B17: 45752 | C17: Ideal Prostate Ultra | D17: 2518.2 | E17: 36 | F17: 31 | G17: =E17/F17 -> 1.1612903 | H17: =D17/E17 -> 69.95 | I17: =H17/G17 -> 60.234722 | J17: 234 | K17: =E17/J17 -> 0.15384615
A18: =IFERROR(IF(B18>0,MONTH(B18)&"-"&YEAR(B18),B18),) -> 0 | B18: 2025 - Week 14 | D18: =SUM(D16:D17) -> 10911.2 | E18: =SUM(E16:E17) -> 176 | F18: =SUM(F16:F17) -> 151 | G18: =E18/F18 -> 1.1655629 | H18: =D18/E18 -> 61.995455 | I18: =H18/G18 -> 53.189282 | J18: =SUM(J16:J17) -> 864 | K18: =E18/J18 -> 0.2037037 | V18: =IFERROR((D18-#REF!)/D18,) -> 0 | W18: =IFERROR((E18-#REF!)/E18,) -> 0 | X18: =IFERROR((D18-#REF!)/D18,) -> 0 | Y18: =IFERROR((E18-#REF!)/E18,) -> 0
A19: =IFERROR(IF(B19>0,MONTH(B19)&"-"&YEAR(B19),B19),) -> 4-2025 | B19: 45753 | C19: Ideal Prostate | D19: 9651.95 | E19: 161 | F19: 145 | G19: =E19/F19 -> 1.1103448 | H19: =D19/E19 -> 59.95 | I19: =H19/G19 -> 53.992236 | J19: 684 | K19: =E19/J19 -> 0.23538012
A20: =IFERROR(IF(B20>0,MONTH(B20)&"-"&YEAR(B20),B20),) -> 4-2025 | B20: 45759 | C20: Ideal Prostate Ultra | D20: 2098.5 | E20: 30 | F20: 24 | G20: =E20/F20 -> 1.25 | H20: =D20/E20 -> 69.95 | I20: =H20/G20 -> 55.96 | J20: 192 | K20: =E20/J20 -> 0.15625
A21: =IFERROR(IF(B21>0,MONTH(B21)&"-"&YEAR(B21),B21),) -> 0 | B21: 2025 - Week 15 | D21: =SUM(D19:D20) -> 11750.45 | E21: =SUM(E19:E20) -> 191 | F21: =SUM(F19:F20) -> 169 | G21: =E21/F21 -> 1.1301775 | H21: =D21/E21 -> 61.520681 | I21: =H21/G21 -> 54.434529 | J21: =SUM(J19:J20) -> 876 | K21: =E21/J21 -> 0.21803653 | V21: =IFERROR((D21-#REF!)/D21,) -> 0 | W21: =IFERROR((E21-#REF!)/E21,) -> 0 | X21: =IFERROR((D21-#REF!)/D21,) -> 0 | Y21: =IFERROR((E21-#REF!)/E21,) -> 0
A22: =IFERROR(IF(B22>0,MONTH(B22)&"-"&YEAR(B22),B22),) -> 4-2025 | B22: 45760 | C22: Ideal Prostate (B08BQ7JTP5) | D22: 7553.7 | E22: 126 | F22: 115 | G22: =E22/F22 -> 1.0956522 | H22: =D22/E22 -> 59.95 | I22: =H22/G22 -> 54.71627 | J22: 527 | K22: =E22/J22 -> 0.23908918
A23: =IFERROR(IF(B23>0,MONTH(B23)&"-"&YEAR(B23),B23),) -> 4-2025 | B23: 45766 | C23: Ideal Prostate Ultra (B08BQ8LGDS) | D23: 2168.45 | E23: 31 | F23: 27 | G23: =E23/F23 -> 1.1481481 | H23: =D23/E23 -> 69.95 | I23: =H23/G23 -> 60.924194 | J23: 188 | K23: =E23/J23 -> 0.16489362
A24: =IFERROR(IF(B24>0,MONTH(B24)&"-"&YEAR(B24),B24),) -> 0 | B24: 2025 - Week 16 | D24: =SUM(D22:D23) -> 9722.15 | E24: =SUM(E22:E23) -> 157 | F24: =SUM(F22:F23) -> 142 | G24: =E24/F24 -> 1.1056338 | H24: =D24/E24 -> 61.924522 | I24: =H24/G24 -> 56.008167 | J24: =SUM(J22:J23) -> 715 | K24: =E24/J24 -> 0.21958042 | V24: =IFERROR((D24-#REF!)/D24,) -> 0 | W24: =IFERROR((E24-#REF!)/E24,) -> 0 | X24: =IFERROR((D24-#REF!)/D24,) -> 0 | Y24: =IFERROR((E24-#REF!)/E24,) -> 0
A25: =IFERROR(IF(B25>0,MONTH(B25)&"-"&YEAR(B25),B25),) -> 4-2025 | B25: 45767 | C25: Ideal Prostate (B08BQ7JTP5) | D25: 7253.95 | E25: 121 | F25: 110 | G25: =E25/F25 -> 1.1 | H25: =D25/E25 -> 59.95 | I25: =H25/G25 -> 54.5 | J25: 527 | K25: =E25/J25 -> 0.22960152
A26: =IFERROR(IF(B26>0,MONTH(B26)&"-"&YEAR(B26),B26),) -> 4-2025 | B26: 45773 | C26: Ideal Prostate Ultra (B08BQ8LGDS) | D26: 3217.7 | E26: 46 | F26: 40 | G26: =E26/F26 -> 1.15 | H26: =D26/E26 -> 69.95 | I26: =H26/G26 -> 60.826087 | J26: 209 | K26: =E26/J26 -> 0.22009569
A27: =IFERROR(IF(B27>0,MONTH(B27)&"-"&YEAR(B27),B27),) -> 0 | B27: 2025 - Week 17 | D27: =SUM(D25:D26) -> 10471.65 | E27: =SUM(E25:E26) -> 167 | F27: =SUM(F25:F26) -> 150 | G27: =E27/F27 -> 1.1133333 | H27: =D27/E27 -> 62.704491 | I27: =H27/G27 -> 56.321399 | J27: =SUM(J25:J26) -> 736 | K27: =E27/J27 -> 0.22690217 | V27: =IFERROR((D27-#REF!)/D27,) -> 0 | W27: =IFERROR((E27-#REF!)/E27,) -> 0 | X27: =IFERROR((D27-#REF!)/D27,) -> 0 | Y27: =IFERROR((E27-#REF!)/E27,) -> 0
A28: =IFERROR(IF(B28>0,MONTH(B28)&"-"&YEAR(B28),B28),) -> 4-2025 | B28: 45774 | C28: Ideal Prostate (B08BQ7JTP5) | D28: 8153.2 | E28: 136 | F28: 124 | G28: =E28/F28 -> 1.0967742 | H28: =D28/E28 -> 59.95 | I28: =H28/G28 -> 54.660294 | J28: 567 | K28: =E28/J28 -> 0.23985891
A29: =IFERROR(IF(B29>0,MONTH(B29)&"-"&YEAR(B29),B29),) -> 5-2025 | B29: 45780 | C29: Ideal Prostate Ultra (B08BQ8LGDS) | D29: 1888.65 | E29: 27 | F29: 23 | G29: =E29/F29 -> 1.173913 | H29: =D29/E29 -> 69.95 | I29: =H29/G29 -> 59.587037 | J29: 187 | K29: =E29/J29 -> 0.14438503
A30: =IFERROR(IF(B30>0,MONTH(B30)&"-"&YEAR(B30),B30),) -> 0 | B30: 2025 - Week 18 | D30: =SUM(D28:D29) -> 10041.85 | E30: =SUM(E28:E29) -> 163 | F30: =SUM(F28:F29) -> 147 | G30: =E30/F30 -> 1.1088435 | H30: =D30/E30 -> 61.606442 | I30: =H30/G30 -> 55.559184 | J30: =SUM(J28:J29) -> 754 | K30: =E30/J30 -> 0.21618037 | V30: =IFERROR((D30-#REF!)/D30,) -> 0 | W30: =IFERROR((E30-#REF!)/E30,) -> 0 | X30: =IFERROR((D30-#REF!)/D30,) -> 0 | Y30: =IFERROR((E30-#REF!)/E30,) -> 0
A31: =IFERROR(IF(B31>0,MONTH(B31)&"-"&YEAR(B31),B31),) -> 5-2025 | B31: 45781 | C31: Ideal Prostate (B08BQ7JTP5) | D31: 7733.55 | E31: 129 | F31: 113 | G31: =E31/F31 -> 1.1415929 | H31: =D31/E31 -> 59.95 | I31: =H31/G31 -> 52.514341 | J31: 643 | K31: =E31/J31 -> 0.20062208
A32: =IFERROR(IF(B32>0,MONTH(B32)&"-"&YEAR(B32),B32),) -> 5-2025 | B32: 45787 | C32: Ideal Prostate Ultra (B08BQ8LGDS) | D32: 2658.1 | E32: 38 | F32: 34 | G32: =E32/F32 -> 1.1176471 | H32: =D32/E32 -> 69.95 | I32: =H32/G32 -> 62.586842 | J32: 238 | K32: =E32/J32 -> 0.15966387
A33: =IFERROR(IF(B33>0,MONTH(B33)&"-"&YEAR(B33),B33),) -> 0 | B33: 2025 - Week 19 | D33: =SUM(D31:D32) -> 10391.65 | E33: =SUM(E31:E32) -> 167 | F33: =SUM(F31:F32) -> 147 | G33: =E33/F33 -> 1.1360544 | H33: =D33/E33 -> 62.225449 | I33: =H33/G33 -> 54.7733 | J33: =SUM(J31:J32) -> 881 | K33: =E33/J33 -> 0.18955732 | V33: =IFERROR((D33-#REF!)/D33,) -> 0 | W33: =IFERROR((E33-#REF!)/E33,) -> 0 | X33: =IFERROR((D33-#REF!)/D33,) -> 0 | Y33: =IFERROR((E33-#REF!)/E33,) -> 0
A34: =IFERROR(IF(B34>0,MONTH(B34)&"-"&YEAR(B34),B34),) -> 5-2025 | B34: 45788 | C34: Ideal Prostate (B08BQ7JTP5) | D34: 9711.9 | E34: 162 | F34: 138 | G34: =E34/F34 -> 1.173913 | H34: =D34/E34 -> 59.95 | I34: =H34/G34 -> 51.068519 | J34: 648 | K34: =E34/J34 -> 0.25
A35: =IFERROR(IF(B35>0,MONTH(B35)&"-"&YEAR(B35),B35),) -> 5-2025 | B35: 45794 | C35: Ideal Prostate Ultra (B08BQ8LGDS) | D35: 2298.35 | E35: 33 | F35: 28 | G35: =E35/F35 -> 1.1785714 | H35: =D35/E35 -> 69.64697 | I35: =H35/G35 -> 59.094399 | J35: 233 | K35: =E35/J35 -> 0.1416309
A36: =IFERROR(IF(B36>0,MONTH(B36)&"-"&YEAR(B36),B36),) -> 0 | B36: 2025 - Week 20 | D36: =SUM(D34:D35) -> 12010.25 | E36: =SUM(E34:E35) -> 195 | F36: =SUM(F34:F35) -> 166 | G36: =E36/F36 -> 1.1746988 | H36: =D36/E36 -> 61.591026 | I36: =H36/G36 -> 52.431335 | J36: =SUM(J34:J35) -> 881 | K36: =E36/J36 -> 0.22133939 | V36: =IFERROR((D36-#REF!)/D36,) -> 0 | W36: =IFERROR((E36-#REF!)/E36,) -> 0 | X36: =IFERROR((D36-#REF!)/D36,) -> 0 | Y36: =IFERROR((E36-#REF!)/E36,) -> 0
A37: =IFERROR(IF(B37>0,MONTH(B37)&"-"&YEAR(B37),B37),) -> 5-2025 | B37: 45795 | C37: Ideal Prostate (B08BQ7JTP5) | D37: 10611.15 | E37: 177 | F37: 154 | G37: =E37/F37 -> 1.1493506 | H37: =D37/E37 -> 59.95 | I37: =H37/G37 -> 52.159887 | J37: 660 | K37: =E37/J37 -> 0.26818182
A38: =IFERROR(IF(B38>0,MONTH(B38)&"-"&YEAR(B38),B38),) -> 5-2025 | B38: 45801 | C38: Ideal Prostate Ultra (B08BQ8LGDS) | D38: 2378.3 | E38: 34 | F38: 31 | G38: =E38/F38 -> 1.0967742 | H38: =D38/E38 -> 69.95 | I38: =H38/G38 -> 63.777941 | J38: 203 | K38: =E38/J38 -> 0.16748768
A39: =IFERROR(IF(B39>0,MONTH(B39)&"-"&YEAR(B39),B39),) -> 0 | B39: 2025 - Week 21 | D39: =SUM(D37:D38) -> 12989.45 | E39: =SUM(E37:E38) -> 211 | F39: =SUM(F37:F38) -> 185 | G39: =E39/F39 -> 1.1405405 | H39: =D39/E39 -> 61.561374 | I39: =H39/G39 -> 53.975613 | J39: =SUM(J37:J38) -> 863 | K39: =E39/J39 -> 0.24449594 | V39: =IFERROR((D39-#REF!)/D39,) -> 0 | W39: =IFERROR((E39-#REF!)/E39,) -> 0 | X39: =IFERROR((D39-#REF!)/D39,) -> 0 | Y39: =IFERROR((E39-#REF!)/E39,) -> 0
A40: =IFERROR(IF(B40>0,MONTH(B40)&"-"&YEAR(B40),B40),) -> 5-2025 | B40: 45802 | C40: Ideal Prostate (B08BQ7JTP5) | D40: 9352.2 | E40: 156 | F40: 146 | G40: =E40/F40 -> 1.0684932 | H40: =D40/E40 -> 59.95 | I40: =H40/G40 -> 56.107051 | J40: 591 | K40: =E40/J40 -> 0.26395939
A41: =IFERROR(IF(B41>0,MONTH(B41)&"-"&YEAR(B41),B41),) -> 5-2025 | B41: 45808 | C41: Ideal Prostate Ultra (B08BQ8LGDS) | D41: 2728.05 | E41: 39 | F41: 36 | G41: =E41/F41 -> 1.0833333 | H41: =D41/E41 -> 69.95 | I41: =H41/G41 -> 64.569231 | J41: 205 | K41: =E41/J41 -> 0.1902439
A42: =IFERROR(IF(B42>0,MONTH(B42)&"-"&YEAR(B42),B42),) -> 0 | B42: 2025 - Week 22 | D42: =SUM(D40:D41) -> 12080.25 | E42: =SUM(E40:E41) -> 195 | F42: =SUM(F40:F41) -> 182 | G42: =E42/F42 -> 1.0714286 | H42: =D42/E42 -> 61.95 | I42: =H42/G42 -> 57.82 | J42: =SUM(J40:J41) -> 796 | K42: =E42/J42 -> 0.24497487 | V42: =IFERROR((D42-#REF!)/D42,) -> 0 | W42: =IFERROR((E42-#REF!)/E42,) -> 0 | X42: =IFERROR((D42-#REF!)/D42,) -> 0 | Y42: =IFERROR((E42-#REF!)/E42,) -> 0
...

Sheet WALMART_weekly_reporting_2025-B
A1: WALMART - DATA SOURCES: https://seller.walmart.com/analytics/overview/item-sale; https://seller.walmart.com/analytics/reports; And Intentwise
C2: WEEKLY PERFORMANCE | X2: =(#REF!+#REF!+#REF!+#REF!)-(monthly_reporting_2021!D17+monthly_reporting_2021!D23+monthly_reporting_2021!D29+monthly_reporting_2021!D35) -> #REF! | Y2: =((#REF!+#REF!+#REF!+#REF!)-(monthly_reporting_2021!E17+monthly_reporting_2021!E23+monthly_reporting_2021!E29+monthly_reporting_2021!E35))/(#REF!+#REF!+#REF!+#REF!) -> #REF!
C3: Total Sales | F3: Total Orders | K3: Total Units Sold
C4: =VLOOKUP("Current Week",$B$11:$X$289,MATCH("SALES",$B$11:$X$11,0),FALSE) -> 21426.35 | F4: =VLOOKUP("Current Week",$B$11:$X$289,MATCH("Units Sold",$B$11:$X$11,0),FALSE) -> 154 | K4: =VLOOKUP("Current Week",$B$11:$X$289,MATCH("Ordered Items",$B$11:$X$11,0),FALSE) -> 133
C5: =(C4-(VLOOKUP("Previous Week",$B$11:$X$293,MATCH("SALES",$B$11:$X$11,0),FALSE)))/C4 -> 0.54579338 | F5: =(F4-(VLOOKUP("Previous Week",$B$11:$X$293,MATCH("Units Sold",$B$11:$X$11,0),FALSE)))/F4 -> 0.34415584 | K5: =(K4-(VLOOKUP("Previous Week",$B$11:$X$293,MATCH("Ordered Items",$B$11:$X$11,0),FALSE)))/K4 -> 0.23308271
C7: Advertising Sales | F7: Advertising Spend | K7: ACoS
C8: =VLOOKUP("Current Week",$B$11:$X$289,MATCH("AD SALES",$B$11:$X$11,0),FALSE) -> 2909.81 | F8: =VLOOKUP("Current Week",$B$11:$X$289,MATCH("SP AD SPEND",$B$11:$X$11,0),FALSE) -> 1088.4 | K8: =F8/C8 -> 0.37404504
C9: =(C8-(VLOOKUP("Previous Week",$B$11:$X$293,MATCH("AD SALES",$B$11:$X$11,0),FALSE)))/C8 -> -0.016296597 | F9: =(F8-(VLOOKUP("Previous Week",$B$11:$X$293,MATCH("SP AD SPEND",$B$11:$X$11,0),FALSE)))/F8 -> 0.0067346564 | K9: =(K8-(VLOOKUP("Previous Week",$B$11:$X$293,MATCH("ACOS",$B$11:$X$11,0),FALSE)))/K8 -> 0.022661941
D10: SALES METRICS | L10: ADVERTISING PERFORMANCE | V10: MoM | X10: YoY
A11: Month-Code | B11: DATE | C11: BRAND | D11: SALES | E11: UNITS SOLD | F11: ORDERED ITEMS | G11: UNITS PER ORDER | H11: SALES PER ORDER | I11: ASP | J11: SP AD SPEND | K11: IMPRESSIONS | L11: UNIT SALES | M11: AD SALES | N11: ACoS | O11: ROAS (return on ad send) | P11: TACoS (Total Advertsing Cost of Sales) | Q11: REVENUE PERCENTAGE OF AD SALES | R11: ORGANIC SALES | S11: CPO | T11: SALES | U11: UNITS | V11: SALES | W11: UNITS
B13: 45641 | C13: AirDoctor | D13: 10331.1 | E13: 29 | F13: 30 | G13: =E13/F13 -> 0.96666667 | H13: =D13/E13 -> 356.24483 | I13: =H13/G13 -> 368.52913 | J13: 93.48 | K13: 23980 | L13: 12 | M13: 2862.3 | N13: =J13/M13 -> 0.03265905 | O13: =M13/J13 -> 30.619384 | P13: =J13/D13 -> 0.0090484072 | Q13: =M13/D13 -> 0.27705665 | R13: =D13-M13 -> 7468.8 | S13: =J13/L13 -> 7.79
C14: AquaTru | D14: 8314.03 | E14: 39 | F14: 46 | G14: =E14/F14 -> 0.84782609 | H14: =D14/E14 -> 213.18026 | I14: =H14/G14 -> 251.44338 | J14: 174.95 | K14: 16451 | L14: 5 | M14: 654.9 | N14: =J14/M14 -> 0.26714002 | O14: =M14/J14 -> 3.7433552 | P14: =J14/D14 -> 0.021042743 | Q14: =M14/D14 -> 0.078770464 | R14: =D14-M14 -> 7659.13 | S14: =J14/L14 -> 34.99
C15: Beflexible | D15: 0 | E15: 0 | F15: 0 | G15: =E15/F15 -> #DIV/0! | H15: =D15/E15 -> #DIV/0! | I15: =H15/G15 -> #DIV/0! | J15: 0 | K15: 0 | L15: 0 | M15: 0 | N15: =J15/M15 -> #DIV/0! | O15: =M15/J15 -> #DIV/0! | P15: =J15/D15 -> #DIV/0! | Q15: =M15/D15 -> #DIV/0! | R15: =D15-M15 -> 0 | S15: =J15/L15 -> #DIV/0!
C16: Better Bladder | D16: 59.95 | E16: 1 | F16: 1 | G16: =E16/F16 -> 1 | H16: =D16/E16 -> 59.95 | I16: =H16/G16 -> 59.95 | J16: 58.66 | K16: 3967 | L16: 1 | M16: 59.95 | N16: =J16/M16 -> 0.97848207 | O16: =M16/J16 -> 1.0219911 | P16: =J16/D16 -> 0.97848207 | Q16: =M16/D16 -> 1 | R16: =D16-M16 -> 0 | S16: =J16/L16 -> 58.66
C17: Cebria | D17: 0 | E17: 0 | F17: 0 | G17: =E17/F17 -> #DIV/0! | H17: =D17/E17 -> #DIV/0! | I17: =H17/G17 -> #DIV/0! | J17: 0 | K17: 0 | L17: 0 | M17: 0 | N17: =J17/M17 -> #DIV/0! | O17: =M17/J17 -> #DIV/0! | P17: =J17/D17 -> #DIV/0! | Q17: =M17/D17 -> #DIV/0! | R17: =D17-M17 -> 0 | S17: =J17/L17 -> #DIV/0!
C18: GA Grown American | D18: 239.96 | E18: 4 | F18: 4 | G18: =E18/F18 -> 1 | H18: =D18/E18 -> 59.99 | I18: =H18/G18 -> 59.99 | J18: 41.79 | K18: 11511 | L18: 1 | M18: 59.99 | N18: =J18/M18 -> 0.6966161 | O18: =M18/J18 -> 1.4355109 | P18: =J18/D18 -> 0.17415403 | Q18: =M18/D18 -> 0.25 | R18: =D18-M18 -> 179.97 | S18: =J18/L18 -> 41.79
C19: Ideal Prostate | D19: 689.73 | E19: 11 | F19: 10 | G19: =E19/F19 -> 1.1 | H19: =D19/E19 -> 62.702727 | I19: =H19/G19 -> 57.002479 | J19: 160.43 | K19: 4358 | L19: 4 | M19: 279.8 | N19: =J19/M19 -> 0.57337384 | O19: =M19/J19 -> 1.7440628 | P19: =J19/D19 -> 0.23259826 | Q19: =M19/D19 -> 0.40566599 | R19: =D19-M19 -> 409.93 | S19: =J19/L19 -> 40.1075
B20: to | C20: Miracle Blade | D20: 162.73 | E20: 4 | F20: 7 | G20: =E20/F20 -> 0.57142857 | H20: =D20/E20 -> 40.6825 | I20: =H20/G20 -> 71.194375 | J20: 159.89 | K20: 17913 | L20: 0 | M20: 0 | N20: =J20/M20 -> #DIV/0! | O20: =M20/J20 -> 0 | P20: =J20/D20 -> 0.98254778 | Q20: =M20/D20 -> 0 | R20: =D20-M20 -> 162.73 | S20: =J20/L20 -> #DIV/0!
C21: Paint Zoom | D21: -4.96 | E21: -1 | F21: 1 | G21: =E21/F21 -> -1 | H21: =D21/E21 -> 4.96 | I21: =H21/G21 -> -4.96 | J21: 79.62 | K21: 182108 | L21: 1 | M21: 84.96 | N21: =J21/M21 -> 0.93714689 | O21: =M21/J21 -> 1.0670686 | P21: =J21/D21 -> -16.052419 | Q21: =M21/D21 -> -17.129032 | R21: =D21-M21 -> -89.92 | S21: =J21/L21 -> 79.62
C22: Profemin | D22: 274.75 | E22: 5 | F22: 4 | G22: =E22/F22 -> 1.25 | H22: =D22/E22 -> 54.95 | I22: =H22/G22 -> 43.96 | J22: 0 | K22: 0 | L22: 0 | M22: 0 | N22: =J22/M22 -> #DIV/0! | O22: =M22/J22 -> #DIV/0! | P22: =J22/D22 -> 0 | Q22: =M22/D22 -> 0 | R22: =D22-M22 -> 274.75 | S22: =J22/L22 -> #DIV/0!
C23: Prosvent | D23: 2437.8 | E23: 29 | F23: 24 | G23: =E23/F23 -> 1.2083333 | H23: =D23/E23 -> 84.062069 | I23: =H23/G23 -> 69.568609 | J23: 63.47 | K23: 12313 | L23: 6 | M23: 579.7 | N23: =J23/M23 -> 0.10948767 | O23: =M23/J23 -> 9.1334489 | P23: =J23/D23 -> 0.02603577 | Q23: =M23/D23 -> 0.23779637 | R23: =D23-M23 -> 1858.1 | S23: =J23/L23 -> 10.578333
C24: SaniTru | D24: 67.96 | E24: 1 | F24: 1 | G24: =E24/F24 -> 1 | H24: =D24/E24 -> 67.96 | I24: =H24/G24 -> 67.96 | J24: 2.14 | K24: 10943 | L24: 0 | M24: 0 | N24: =J24/M24 -> #DIV/0! | O24: =M24/J24 -> 0 | P24: =J24/D24 -> 0.031489111 | Q24: =M24/D24 -> 0 | R24: =D24-M24 -> 67.96 | S24: =J24/L24 -> #DIV/0!
C25: Rotorazer Saw | D25: -139.37 | E25: 0 | F25: 3 | G25: =E25/F25 -> 0 | H25: =D25/E25 -> #DIV/0! | I25: =H25/G25 -> #DIV/0! | J25: 21.79 | K25: 21569 | L25: 0 | M25: 0 | N25: =J25/M25 -> #DIV/0! | O25: =M25/J25 -> 0 | P25: =J25/D25 -> -0.15634642 | Q25: =M25/D25 -> 0 | R25: =D25-M25 -> -139.37 | S25: =J25/L25 -> #DIV/0!
C26: Superthotics | D26: 0 | E26: 0 | F26: 0 | G26: =E26/F26 -> #DIV/0! | H26: =D26/E26 -> #DIV/0! | I26: =H26/G26 -> #DIV/0! | J26: 3.1 | K26: 1684 | L26: 0 | M26: 0 | N26: =J26/M26 -> #DIV/0! | O26: =M26/J26 -> 0 | P26: =J26/D26 -> #DIV/0! | Q26: =M26/D26 -> #DIV/0! | R26: =D26-M26 -> 0 | S26: =J26/L26 -> #DIV/0!
C27: Therabotanics | D27: 0 | E27: 0 | F27: 0 | G27: =E27/F27 -> #DIV/0! | H27: =D27/E27 -> #DIV/0! | I27: =H27/G27 -> #DIV/0! | J27: 0 | K27: 0 | L27: 0 | M27: 0 | N27: =J27/M27 -> #DIV/0! | O27: =M27/J27 -> #DIV/0! | P27: =J27/D27 -> #DIV/0! | Q27: =M27/D27 -> #DIV/0! | R27: =D27-M27 -> 0 | S27: =J27/L27 -> #DIV/0!
C28: WALKFIT | D28: 900.09 | E28: 28 | F28: 26 | G28: =E28/F28 -> 1.0769231 | H28: =D28/E28 -> 32.146071 | I28: =H28/G28 -> 29.849923 | J28: 164.56 | K28: 45377 | L28: 18 | M28: 474.72 | N28: =J28/M28 -> 0.34664644 | O28: =M28/J28 -> 2.8847837 | P28: =J28/D28 -> 0.18282616 | Q28: =M28/D28 -> 0.52741393 | R28: =D28-M28 -> 425.37 | S28: =J28/L28 -> 9.1422222
A29: =IFERROR(IF(B29>0,MONTH(B29)&"-"&YEAR(B29),B29),) -> 12-2024 | B29: 45647 | C29: AromaTru | D29: 9.8 | E29: 0 | F29: 1 | G29: =E29/F29 -> 0 | H29: =D29/E29 -> #DIV/0! | I29: =H29/G29 -> #DIV/0! | J29: 0 | K29: 12458 | L29: 0 | M29: 0 | N29: =J29/M29 -> #DIV/0! | O29: =M29/J29 -> #DIV/0! | P29: =J29/D29 -> 0 | Q29: =M29/D29 -> 0 | R29: =D29-M29 -> 9.8 | S29: =J29/L29 -> #DIV/0!
A30: =IFERROR(IF(B30>0,MONTH(B30)&"-"&YEAR(B30),B30),) -> 0 | B30: 2024 - Week 51 | D30: =SUM(D13:D29) -> 23343.57 | E30: =SUM(E13:E29) -> 150 | F30: =SUM(F13:F29) -> 158 | G30: =E30/F30 -> 0.94936709 | H30: =D30/E30 -> 155.6238 | I30: =H30/G30 -> 163.92374 | J30: =SUM(J13:J29) -> 1023.88 | K30: =SUM(K13:K29) -> 364632 | L30: =SUM(L13:L29) -> 48 | M30: =SUM(M13:M29) -> 5056.32 | N30: =J30/M30 -> 0.2024951 | O30: =M30/J30 -> 4.9383912 | P30: =J30/D30 -> 0.043861329 | Q30: =M30/D30 -> 0.2166044 | R30: =SUM(R13:R29) -> 18287.25 | S30: =J30/L30 -> 21.330833 | T30: =IFERROR((D30-#REF!)/D30,) -> 0 | U30: =IFERROR((E30-#REF!)/E30,) -> 0 | V30: =IFERROR((D30-monthly_reporting_2021!D49)/D30, ) -> 1 | W30: =IFERROR((E30-monthly_reporting_2021!E49)/E30, ) -> 1
B31: 45648 | C31: AirDoctor | D31: 12504.3 | E31: 32 | F31: 32 | G31: =E31/F31 -> 1 | H31: =D31/E31 -> 390.75937 | I31: =H31/G31 -> 390.75937 | J31: 106.38 | K31: 23406 | L31: 10 | M31: 4010.3 | N31: =J31/M31 -> 0.026526694 | O31: =M31/J31 -> 37.697876 | P31: =J31/D31 -> 0.0085074734 | Q31: =M31/D31 -> 0.32071367 | R31: =D31-M31 -> 8494 | S31: =J31/L31 -> 10.638
C32: AquaTru | D32: 5241.86 | E32: 31 | F32: 37 | G32: =E32/F32 -> 0.83783784 | H32: =D32/E32 -> 169.09226 | I32: =H32/G32 -> 201.81979 | J32: 104.84 | K32: 18706 | L32: 1 | M32: 79.95 | N32: =J32/M32 -> 1.3113196 | O32: =M32/J32 -> 0.76259061 | P32: =J32/D32 -> 0.020000534 | Q32: =M32/D32 -> 0.01525222 | R32: =D32-M32 -> 5161.91 | S32: =J32/L32 -> 104.84
C33: Beflexible | D33: 139.9 | E33: 2 | F33: 1 | G33: =E33/F33 -> 2 | H33: =D33/E33 -> 69.95 | I33: =H33/G33 -> 34.975 | J33: 0 | K33: 0 | L33: 0 | M33: 0 | N33: =J33/M33 -> #DIV/0! | O33: =M33/J33 -> #DIV/0! | P33: =J33/D33 -> 0 | Q33: =M33/D33 -> 0 | R33: =D33-M33 -> 139.9 | S33: =J33/L33 -> #DIV/0!
C34: Better Bladder | D34: 359.7 | E34: 6 | F34: 5 | G34: =E34/F34 -> 1.2 | H34: =D34/E34 -> 59.95 | I34: =H34/G34 -> 49.958333 | J34: 15.23 | K34: 1618 | L34: 0 | M34: 0 | N34: =J34/M34 -> #DIV/0! | O34: =M34/J34 -> 0 | P34: =J34/D34 -> 0.04234084 | Q34: =M34/D34 -> 0 | R34: =D34-M34 -> 359.7 | S34: =J34/L34 -> #DIV/0!
C35: Cebria | D35: 0 | E35: 0 | F35: 0 | G35: =E35/F35 -> #DIV/0! | H35: =D35/E35 -> #DIV/0! | I35: =H35/G35 -> #DIV/0! | J35: 0 | K35: 0 | L35: 0 | M35: 0 | N35: =J35/M35 -> #DIV/0! | O35: =M35/J35 -> #DIV/0! | P35: =J35/D35 -> #DIV/0! | Q35: =M35/D35 -> #DIV/0! | R35: =D35-M35 -> 0 | S35: =J35/L35 -> #DIV/0!
C36: GA Grown American | D36: 119.98 | E36: 2 | F36: 1 | G36: =E36/F36 -> 2 | H36: =D36/E36 -> 59.99 | I36: =H36/G36 -> 29.995 | J36: 41.55 | K36: 9951 | L36: 0 | M36: 0 | N36: =J36/M36 -> #DIV/0! | O36: =M36/J36 -> 0 | P36: =J36/D36 -> 0.34630772 | Q36: =M36/D36 -> 0 | R36: =D36-M36 -> 119.98 | S36: =J36/L36 -> #DIV/0!
C37: Ideal Prostate | D37: 849.35 | E37: 13 | F37: 8 | G37: =E37/F37 -> 1.625 | H37: =D37/E37 -> 65.334615 | I37: =H37/G37 -> 40.205917 | J37: 151.87 | K37: 3720 | L37: 1 | M37: 69.95 | N37: =J37/M37 -> 2.1711222 | O37: =M37/J37 -> 0.4605913 | P37: =J37/D37 -> 0.17880732 | Q37: =M37/D37 -> 0.082357097 | R37: =D37-M37 -> 779.4 | S37: =J37/L37 -> 151.87
B38: to | C38: Miracle Blade | D38: 765.75 | E38: 11 | F38: 14 | G38: =E38/F38 -> 0.78571429 | H38: =D38/E38 -> 69.613636 | I38: =H38/G38 -> 88.599174 | J38: 243.42 | K38: 28115 | L38: 4 | M38: 150.89 | N38: =J38/M38 -> 1.6132282 | O38: =M38/J38 -> 0.61987511 | P38: =J38/D38 -> 0.31788443 | Q38: =M38/D38 -> 0.19704865 | R38: =D38-M38 -> 614.86 | S38: =J38/L38 -> 60.855
C39: Paint Zoom | D39: 0 | E39: 0 | F39: 0 | G39: =E39/F39 -> #DIV/0! | H39: =D39/E39 -> #DIV/0! | I39: =H39/G39 -> #DIV/0! | J39: 53.92 | K39: 167085 | L39: 0 | M39: 0 | N39: =J39/M39 -> #DIV/0! | O39: =M39/J39 -> 0 | P39: =J39/D39 -> #DIV/0! | Q39: =M39/D39 -> #DIV/0! | R39: =D39-M39 -> 0 | S39: =J39/L39 -> #DIV/0!
C40: Profemin | D40: 0 | E40: 0 | F40: 1 | G40: =E40/F40 -> 0 | H40: =D40/E40 -> #DIV/0! | I40: =H40/G40 -> #DIV/0! | J40: 0 | K40: 0 | L40: 0 | M40: 0 | N40: =J40/M40 -> #DIV/0! | O40: =M40/J40 -> #DIV/0! | P40: =J40/D40 -> #DIV/0! | Q40: =M40/D40 -> #DIV/0! | R40: =D40-M40 -> 0 | S40: =J40/L40 -> #DIV/0!
C41: Prosvent | D41: 766.15 | E41: 15 | F41: 14 | G41: =E41/F41 -> 1.0714286 | H41: =D41/E41 -> 51.076667 | I41: =H41/G41 -> 47.671556 | J41: 56.99 | K41: 12059 | L41: 1 | M41: 67 | N41: =J41/M41 -> 0.85059701 | O41: =M41/J41 -> 1.1756448 | P41: =J41/D41 -> 0.074384912 | Q41: =M41/D41 -> 0.087450238 | R41: =D41-M41 -> 699.15 | S41: =J41/L41 -> 56.99
C42: SaniTru | D42: -10.91 | E42: 1 | F42: 1 | G42: =E42/F42 -> 1 | H42: =D42/E42 -> -10.91 | I42: =H42/G42 -> -10.91 | J42: 8.58 | K42: 10088 | L42: 1 | M42: 19.99 | N42: =J42/M42 -> 0.42921461 | O42: =M42/J42 -> 2.3298368 | P42: =J42/D42 -> -0.78643446 | Q42: =M42/D42 -> -1.832264 | R42: =D42-M42 -> -30.9 | S42: =J42/L42 -> 8.58
...

Sheet WALMART_weekly_reporting_2024-B
A1: WALMART - DATA SOURCES: https://seller.walmart.com/analytics/overview/item-sale; https://seller.walmart.com/analytics/reports; And Intentwise
C2: WEEKLY PERFORMANCE | X2: =(#REF!+#REF!+#REF!+#REF!)-(monthly_reporting_2021!D17+monthly_reporting_2021!D23+monthly_reporting_2021!D29+monthly_reporting_2021!D35) -> #REF! | Y2: =((#REF!+#REF!+#REF!+#REF!)-(monthly_reporting_2021!E17+monthly_reporting_2021!E23+monthly_reporting_2021!E29+monthly_reporting_2021!E35))/(#REF!+#REF!+#REF!+#REF!) -> #REF!
C3: Total Sales | F3: Total Orders | K3: Total Units Sold
C4: =VLOOKUP("Current Week",$B$11:$X$266,MATCH("SALES",$B$11:$X$11,0),FALSE) -> 21475.38 | F4: =VLOOKUP("Current Week",$B$11:$X$266,MATCH("Units Sold",$B$11:$X$11,0),FALSE) -> 129 | K4: =VLOOKUP("Current Week",$B$11:$X$266,MATCH("Ordered Items",$B$11:$X$11,0),FALSE) -> 131
C5: =(C4-(VLOOKUP("Previous Week",$B$11:$X$270,MATCH("SALES",$B$11:$X$11,0),FALSE)))/C4 -> -0.086992174 | F5: =(F4-(VLOOKUP("Previous Week",$B$11:$X$270,MATCH("Units Sold",$B$11:$X$11,0),FALSE)))/F4 -> -0.1627907 | K5: =(K4-(VLOOKUP("Previous Week",$B$11:$X$270,MATCH("Ordered Items",$B$11:$X$11,0),FALSE)))/K4 -> -0.20610687
C7: Advertising Sales | F7: Advertising Spend | K7: ACoS
C8: =VLOOKUP("Current Week",$B$11:$X$266,MATCH("AD SALES",$B$11:$X$11,0),FALSE) -> 4541.92 | F8: =VLOOKUP("Current Week",$B$11:$X$266,MATCH("SP AD SPEND",$B$11:$X$11,0),FALSE) -> 902.48 | K8: =F8/C8 -> 0.19870011
C9: =(C8-(VLOOKUP("Previous Week",$B$11:$X$270,MATCH("AD SALES",$B$11:$X$11,0),FALSE)))/C8 -> -0.11325607 | F9: =(F8-(VLOOKUP("Previous Week",$B$11:$X$270,MATCH("SP AD SPEND",$B$11:$X$11,0),FALSE)))/F8 -> -0.13451822 | K9: =(K8-(VLOOKUP("Previous Week",$B$11:$X$270,MATCH("ACOS",$B$11:$X$11,0),FALSE)))/K8 -> -0.019099064
D10: SALES METRICS | L10: ADVERTISING PERFORMANCE | V10: MoM | X10: YoY
A11: Month-Code | B11: DATE | C11: BRAND | D11: SALES | E11: UNITS SOLD | F11: ORDERED ITEMS | G11: UNITS PER ORDER | H11: SALES PER ORDER | I11: ASP | J11: SP AD SPEND | K11: IMPRESSIONS | L11: UNIT SALES | M11: AD SALES | N11: ACoS | O11: ROAS (return on ad send) | P11: TACoS (Total Advertsing Cost of Sales) | Q11: REVENUE PERCENTAGE OF AD SALES | R11: ORGANIC SALES | S11: CPO | T11: SALES | U11: UNITS | V11: SALES | W11: UNITS
A13: =IFERROR(IF(B13>0,MONTH(B13)&"-"&YEAR(B13),B13),) -> 9-2024 | B13: 45557 | C13: AirDoctor | G13: =E13/F13 -> #DIV/0! | H13: =D13/E13 -> #DIV/0! | I13: =H13/G13 -> #DIV/0! | N13: =J13/M13 -> #DIV/0! | O13: =M13/J13 -> #DIV/0! | P13: =J13/D13 -> #DIV/0! | Q13: =M13/D13 -> #DIV/0! | R13: =D13-M13 -> 0 | S13: =J13/L13 -> #DIV/0!
C14: AquaTru | G14: =E14/F14 -> #DIV/0! | H14: =D14/E14 -> #DIV/0! | I14: =H14/G14 -> #DIV/0! | N14: =J14/M14 -> #DIV/0! | O14: =M14/J14 -> #DIV/0! | P14: =J14/D14 -> #DIV/0! | Q14: =M14/D14 -> #DIV/0! | R14: =D14-M14 -> 0 | S14: =J14/L14 -> #DIV/0!
C15: GA Grown American | G15: =E15/F15 -> #DIV/0! | H15: =D15/E15 -> #DIV/0! | I15: =H15/G15 -> #DIV/0! | N15: =J15/M15 -> #DIV/0! | O15: =M15/J15 -> #DIV/0! | P15: =J15/D15 -> #DIV/0! | Q15: =M15/D15 -> #DIV/0! | R15: =D15-M15 -> 0 | S15: =J15/L15 -> #DIV/0!
C16: Ideal Prostate | G16: =E16/F16 -> #DIV/0! | H16: =D16/E16 -> #DIV/0! | I16: =H16/G16 -> #DIV/0! | N16: =J16/M16 -> #DIV/0! | O16: =M16/J16 -> #DIV/0! | P16: =J16/D16 -> #DIV/0! | Q16: =M16/D16 -> #DIV/0! | R16: =D16-M16 -> 0 | S16: =J16/L16 -> #DIV/0!
C17: Miracle Blade | G17: =E17/F17 -> #DIV/0! | H17: =D17/E17 -> #DIV/0! | I17: =H17/G17 -> #DIV/0! | N17: =J17/M17 -> #DIV/0! | O17: =M17/J17 -> #DIV/0! | P17: =J17/D17 -> #DIV/0! | Q17: =M17/D17 -> #DIV/0! | R17: =D17-M17 -> 0 | S17: =J17/L17 -> #DIV/0!
C18: Paint Zoom | G18: =E18/F18 -> #DIV/0! | H18: =D18/E18 -> #DIV/0! | I18: =H18/G18 -> #DIV/0! | N18: =J18/M18 -> #DIV/0! | O18: =M18/J18 -> #DIV/0! | P18: =J18/D18 -> #DIV/0! | Q18: =M18/D18 -> #DIV/0! | R18: =D18-M18 -> 0 | S18: =J18/L18 -> #DIV/0!
C19: Profemin | G19: =E19/F19 -> #DIV/0! | H19: =D19/E19 -> #DIV/0! | I19: =H19/G19 -> #DIV/0! | N19: =J19/M19 -> #DIV/0! | O19: =M19/J19 -> #DIV/0! | P19: =J19/D19 -> #DIV/0! | Q19: =M19/D19 -> #DIV/0! | R19: =D19-M19 -> 0 | S19: =J19/L19 -> #DIV/0!
C20: Prosvent | G20: =E20/F20 -> #DIV/0! | H20: =D20/E20 -> #DIV/0! | I20: =H20/G20 -> #DIV/0! | N20: =J20/M20 -> #DIV/0! | O20: =M20/J20 -> #DIV/0! | P20: =J20/D20 -> #DIV/0! | Q20: =M20/D20 -> #DIV/0! | R20: =D20-M20 -> 0 | S20: =J20/L20 -> #DIV/0!
C21: Rotorazer Saw | G21: =E21/F21 -> #DIV/0! | H21: =D21/E21 -> #DIV/0! | I21: =H21/G21 -> #DIV/0! | N21: =J21/M21 -> #DIV/0! | O21: =M21/J21 -> #DIV/0! | P21: =J21/D21 -> #DIV/0! | Q21: =M21/D21 -> #DIV/0! | R21: =D21-M21 -> 0 | S21: =J21/L21 -> #DIV/0!
C22: Superthotics | G22: =E22/F22 -> #DIV/0! | H22: =D22/E22 -> #DIV/0! | I22: =H22/G22 -> #DIV/0! | N22: =J22/M22 -> #DIV/0! | O22: =M22/J22 -> #DIV/0! | P22: =J22/D22 -> #DIV/0! | Q22: =M22/D22 -> #DIV/0! | R22: =D22-M22 -> 0 | S22: =J22/L22 -> #DIV/0!
C23: Therabotanics | G23: =E23/F23 -> #DIV/0! | H23: =D23/E23 -> #DIV/0! | I23: =H23/G23 -> #DIV/0! | N23: =J23/M23 -> #DIV/0! | O23: =M23/J23 -> #DIV/0! | P23: =J23/D23 -> #DIV/0! | Q23: =M23/D23 -> #DIV/0! | R23: =D23-M23 -> 0 | S23: =J23/L23 -> #DIV/0!
A24: =IFERROR(IF(B24>0,MONTH(B24)&"-"&YEAR(B24),B24),) -> 9-2024 | B24: 45563 | C24: WALKFIT | G24: =E24/F24 -> #DIV/0! | H24: =D24/E24 -> #DIV/0! | I24: =H24/G24 -> #DIV/0! | N24: =J24/M24 -> #DIV/0! | O24: =M24/J24 -> #DIV/0! | P24: =J24/D24 -> #DIV/0! | Q24: =M24/D24 -> #DIV/0! | R24: =D24-M24 -> 0 | S24: =J24/L24 -> #DIV/0!
A25: =IFERROR(IF(B25>0,MONTH(B25)&"-"&YEAR(B25),B25),) -> 0 | B25: Week 39 | D25: =SUM(D13:D24) -> 0 | E25: =SUM(E13:E24) -> 0 | F25: =SUM(F13:F24) -> 0 | G25: =E25/F25 -> #DIV/0! | H25: =D25/E25 -> #DIV/0! | I25: =H25/G25 -> #DIV/0! | J25: =SUM(J13:J24) -> 0 | K25: =SUM(K13:K24) -> 0 | L25: =SUM(L13:L24) -> 0 | M25: =SUM(M13:M24) -> 0 | N25: =J25/M25 -> #DIV/0! | O25: =M25/J25 -> #DIV/0! | P25: =J25/D25 -> #DIV/0! | Q25: =M25/D25 -> #DIV/0! | R25: =SUM(R13:R24) -> 0 | S25: =J25/L25 -> #DIV/0! | T25: =IFERROR((D25-#REF!)/D25,) -> 0 | U25: =IFERROR((E25-#REF!)/E25,) -> 0 | V25: =IFERROR((D25-monthly_reporting_2021!D49)/D25, ) -> 0 | W25: =IFERROR((E25-monthly_reporting_2021!E49)/E25, ) -> 0
A26: =IFERROR(IF(B26>0,MONTH(B26)&"-"&YEAR(B26),B26),) -> 9-2024 | B26: 45564 | C26: AirDoctor | D26: 803.8 | E26: 5 | F26: 6 | G26: =E26/F26 -> 0.83333333 | H26: =D26/E26 -> 160.76 | I26: =H26/G26 -> 192.912 | J26: 65.67 | K26: 13527 | L26: 3 | M26: 389 | N26: =J26/M26 -> 0.16881748 | O26: =M26/J26 -> 5.9235572 | P26: =J26/D26 -> 0.081699428 | Q26: =M26/D26 -> 0.48395123 | R26: =D26-M26 -> 414.8 | S26: =J26/L26 -> 21.89
C27: AquaTru | D27: 1080.7 | E27: 14 | F27: 11 | G27: =E27/F27 -> 1.2727273 | H27: =D27/E27 -> 77.192857 | I27: =H27/G27 -> 60.651531 | J27: 1 | K27: 1334 | L27: 0 | M27: 0 | N27: =J27/M27 -> #DIV/0! | O27: =M27/J27 -> 0 | P27: =J27/D27 -> 0.00092532618 | Q27: =M27/D27 -> 0 | R27: =D27-M27 -> 1080.7 | S27: =J27/L27 -> #DIV/0!
C28: Beflexible | D28: 0 | E28: 0 | F28: 0 | G28: =E28/F28 -> #DIV/0! | H28: =D28/E28 -> #DIV/0! | I28: =H28/G28 -> #DIV/0! | J28: 0 | K28: 0 | L28: 0 | M28: 0 | N28: =J28/M28 -> #DIV/0! | O28: =M28/J28 -> #DIV/0! | P28: =J28/D28 -> #DIV/0! | Q28: =M28/D28 -> #DIV/0! | R28: =D28-M28 -> 0 | S28: =J28/L28 -> #DIV/0!
C29: Better Bladder | D29: 899.25 | E29: 15 | F29: 10 | G29: =E29/F29 -> 1.5 | H29: =D29/E29 -> 59.95 | I29: =H29/G29 -> 39.966667 | J29: 54.67 | K29: 4307 | L29: 7 | M29: 419.65 | N29: =J29/M29 -> 0.13027523 | O29: =M29/J29 -> 7.6760563 | P29: =J29/D29 -> 0.060795107 | Q29: =M29/D29 -> 0.46666667 | R29: =D29-M29 -> 479.6 | S29: =J29/L29 -> 7.81
C30: Cebria | D30: 0 | E30: 0 | F30: 0 | G30: =E30/F30 -> #DIV/0! | H30: =D30/E30 -> #DIV/0! | I30: =H30/G30 -> #DIV/0! | J30: 0 | K30: 0 | L30: 0 | M30: 0 | N30: =J30/M30 -> #DIV/0! | O30: =M30/J30 -> #DIV/0! | P30: =J30/D30 -> #DIV/0! | Q30: =M30/D30 -> #DIV/0! | R30: =D30-M30 -> 0 | S30: =J30/L30 -> #DIV/0!
C31: GA Grown American | D31: 115.02 | E31: 2 | F31: 2 | G31: =E31/F31 -> 1 | H31: =D31/E31 -> 57.51 | I31: =H31/G31 -> 57.51 | J31: 5.55 | K31: 0 | L31: 0 | M31: 0 | N31: =J31/M31 -> #DIV/0! | O31: =M31/J31 -> 0 | P31: =J31/D31 -> 0.048252478 | Q31: =M31/D31 -> 0 | R31: =D31-M31 -> 115.02 | S31: =J31/L31 -> #DIV/0!
C32: Ideal Prostate | D32: 369.7 | E32: 6 | F32: 6 | G32: =E32/F32 -> 1 | H32: =D32/E32 -> 61.616667 | I32: =H32/G32 -> 61.616667 | J32: 6.48 | K32: 4126 | L32: 0 | M32: 0 | N32: =J32/M32 -> #DIV/0! | O32: =M32/J32 -> 0 | P32: =J32/D32 -> 0.017527725 | Q32: =M32/D32 -> 0 | R32: =D32-M32 -> 369.7 | S32: =J32/L32 -> #DIV/0!
B33: to | C33: Miracle Blade | D33: 332.96 | E33: 4 | F33: 4 | G33: =E33/F33 -> 1 | H33: =D33/E33 -> 83.24 | I33: =H33/G33 -> 83.24 | J33: 0.85 | K33: 1816 | L33: 0 | M33: 0 | N33: =J33/M33 -> #DIV/0! | O33: =M33/J33 -> 0 | P33: =J33/D33 -> 0.0025528592 | Q33: =M33/D33 -> 0 | R33: =D33-M33 -> 332.96 | S33: =J33/L33 -> #DIV/0!
C34: Paint Zoom | D34: 0 | E34: 0 | F34: 1 | G34: =E34/F34 -> 0 | H34: =D34/E34 -> #DIV/0! | I34: =H34/G34 -> #DIV/0! | J34: 54.18 | K34: 94 | L34: 1 | M34: 99.95 | N34: =J34/M34 -> 0.54207104 | O34: =M34/J34 -> 1.8447767 | P34: =J34/D34 -> #DIV/0! | Q34: =M34/D34 -> #DIV/0! | R34: =D34-M34 -> -99.95 | S34: =J34/L34 -> 54.18
C35: Profemin | D35: 0 | E35: 0 | F35: 0 | G35: =E35/F35 -> #DIV/0! | H35: =D35/E35 -> #DIV/0! | I35: =H35/G35 -> #DIV/0! | J35: 0 | K35: 213470 | L35: 0 | M35: 0 | N35: =J35/M35 -> #DIV/0! | O35: =M35/J35 -> #DIV/0! | P35: =J35/D35 -> #DIV/0! | Q35: =M35/D35 -> #DIV/0! | R35: =D35-M35 -> 0 | S35: =J35/L35 -> #DIV/0!
C36: Prosvent | D36: 607.55 | E36: 5 | F36: 5 | G36: =E36/F36 -> 1 | H36: =D36/E36 -> 121.51 | I36: =H36/G36 -> 121.51 | J36: 0 | K36: 0 | L36: 0 | M36: 0 | N36: =J36/M36 -> #DIV/0! | O36: =M36/J36 -> #DIV/0! | P36: =J36/D36 -> 0 | Q36: =M36/D36 -> 0 | R36: =D36-M36 -> 607.55 | S36: =J36/L36 -> #DIV/0!
C37: SaniTru | D37: 0 | E37: 0 | F37: 0 | G37: =E37/F37 -> #DIV/0! | H37: =D37/E37 -> #DIV/0! | I37: =H37/G37 -> #DIV/0! | J37: 0 | K37: 8 | L37: 0 | M37: 0 | N37: =J37/M37 -> #DIV/0! | O37: =M37/J37 -> #DIV/0! | P37: =J37/D37 -> #DIV/0! | Q37: =M37/D37 -> #DIV/0! | R37: =D37-M37 -> 0 | S37: =J37/L37 -> #DIV/0!
C38: Rotorazer Saw | D38: 0 | E38: 0 | F38: 0 | G38: =E38/F38 -> #DIV/0! | H38: =D38/E38 -> #DIV/0! | I38: =H38/G38 -> #DIV/0! | J38: 0 | K38: 0 | L38: 0 | M38: 0 | N38: =J38/M38 -> #DIV/0! | O38: =M38/J38 -> #DIV/0! | P38: =J38/D38 -> #DIV/0! | Q38: =M38/D38 -> #DIV/0! | R38: =D38-M38 -> 0 | S38: =J38/L38 -> #DIV/0!
C39: Superthotics | D39: 20.7 | E39: 0 | F39: 1 | G39: =E39/F39 -> 0 | H39: =D39/E39 -> #DIV/0! | I39: =H39/G39 -> #DIV/0! | J39: 0 | K39: 1048 | L39: 0 | M39: 0 | N39: =J39/M39 -> #DIV/0! | O39: =M39/J39 -> #DIV/0! | P39: =J39/D39 -> 0 | Q39: =M39/D39 -> 0 | R39: =D39-M39 -> 20.7 | S39: =J39/L39 -> #DIV/0!
C40: Therabotanics | D40: 0 | E40: 0 | F40: 0 | G40: =E40/F40 -> #DIV/0! | H40: =D40/E40 -> #DIV/0! | I40: =H40/G40 -> #DIV/0! | J40: 0 | K40: 0 | L40: 0 | M40: 0 | N40: =J40/M40 -> #DIV/0! | O40: =M40/J40 -> #DIV/0! | P40: =J40/D40 -> #DIV/0! | Q40: =M40/D40 -> #DIV/0! | R40: =D40-M40 -> 0 | S40: =J40/L40 -> #DIV/0!
C41: WALKFIT | D41: 519.35 | E41: 13 | F41: 12 | G41: =E41/F41 -> 1.0833333 | H41: =D41/E41 -> 39.95 | I41: =H41/G41 -> 36.876923 | J41: 19.06 | K41: 11339 | L41: 6 | M41: 199.75 | N41: =J41/M41 -> 0.095419274 | O41: =M41/J41 -> 10.480063 | P41: =J41/D41 -> 0.036699721 | Q41: =M41/D41 -> 0.38461538 | R41: =D41-M41 -> 319.6 | S41: =J41/L41 -> 3.1766667
A42: =IFERROR(IF(B42>0,MONTH(B42)&"-"&YEAR(B42),B42),) -> 10-2024 | B42: 45570 | C42: AromaTru | D42: 0 | E42: 0 | F42: 0 | G42: =E42/F42 -> #DIV/0! | H42: =D42/E42 -> #DIV/0! | I42: =H42/G42 -> #DIV/0! | J42: 0 | K42: 0 | L42: 0 | M42: 0 | N42: =J42/M42 -> #DIV/0! | O42: =M42/J42 -> #DIV/0! | P42: =J42/D42 -> #DIV/0! | Q42: =M42/D42 -> #DIV/0! | R42: =D42-M42 -> 0 | S42: =J42/L42 -> #DIV/0!
...

Sheet weekly_reporting_2024
A1: DATA SOURCE: Reports>Business Reports>Detail Page Sales Traffic By Parent
C2: WEEKLY PERFORMANCE | X2: =(#REF!+#REF!+#REF!+#REF!)-(monthly_reporting_2021!D17+monthly_reporting_2021!D23+monthly_reporting_2021!D29+monthly_reporting_2021!D35) -> #REF! | Y2: =((#REF!+#REF!+#REF!+#REF!)-(monthly_reporting_2021!E17+monthly_reporting_2021!E23+monthly_reporting_2021!E29+monthly_reporting_2021!E35))/(#REF!+#REF!+#REF!+#REF!) -> #REF!
C3: Total Sales | F3: Total Orders | K3: Total Units Sold
C4: =VLOOKUP("Current Week",$B$11:$Z$429,MATCH("SALES",$B$11:$Z$11,0),FALSE) -> 64670.09 | F4: =VLOOKUP("Current Week",$B$11:$Z$429,MATCH("Units Sold",$B$11:$Z$11,0),FALSE) -> 1050 | K4: =VLOOKUP("Current Week",$B$11:$Z$429,MATCH("Ordered Items",$B$11:$Z$11,0),FALSE) -> 956
C5: =(C4-(VLOOKUP("Previous Week",$B$11:$Z$433,MATCH("SALES",$B$11:$Z$11,0),FALSE)))/C4 -> -0.13155293 | F5: =(F4-(VLOOKUP("Previous Week",$B$11:$Z$433,MATCH("Units Sold",$B$11:$Z$11,0),FALSE)))/F4 -> -0.13142857 | K5: =(K4-(VLOOKUP("Previous Week",$B$11:$Z$433,MATCH("Ordered Items",$B$11:$Z$11,0),FALSE)))/K4 -> -0.14121339
C7: Advertising Sales | F7: Advertising Spend | K7: ACoS
C8: =VLOOKUP("Current Week",$B$11:$Z$429,MATCH("AD SALES",$B$11:$Z$11,0),FALSE) -> 20114.25 | F8: =VLOOKUP("Current Week",$B$11:$Z$429,MATCH("SP AD SPEND",$B$11:$Z$11,0),FALSE) -> 7265.79 | K8: =F8/C8 -> 0.361226
C9: =(C8-(VLOOKUP("Previous Week",$B$11:$Z$433,MATCH("AD SALES",$B$11:$Z$11,0),FALSE)))/C8 -> 0.01411984 | F9: =(F8-(VLOOKUP("Previous Week",$B$11:$Z$433,MATCH("SP AD SPEND",$B$11:$Z$11,0),FALSE)))/F8 -> 0.12917797 | K9: =(K8-(VLOOKUP("Previous Week",$B$11:$Z$433,MATCH("ACOS",$B$11:$Z$11,0),FALSE)))/K8 -> 0.116706
D10: SALES METRICS | L10: ADVERTISING PERFORMANCE | V10: MoM | X10: YoY
A11: Month-Code | B11: DATE | C11: BRAND | D11: SALES | E11: UNITS SOLD | F11: ORDERED ITEMS | G11: UNITS PER ORDER | H11: SALES PER ORDER | I11: ASP | J11: SESSIONS (traffic) | K11: ORDERS PER SESSION (conversion) | L11: SP AD SPEND | M11: IMPRESSIONS | N11: UNIT SALES | O11: AD SALES | P11: ACoS | Q11: ROAS (return on ad send) | R11: TACoS (Total Advertsing Cost of Sales) | S11: REVENUE PERCENTAGE OF AD SALES | T11: ORGANIC SALES | U11: CPO | V11: SALES | W11: UNITS | X11: SALES | Y11: UNITS
A13: =IFERROR(IF(B13>0,MONTH(B13)&"-"&YEAR(B13),B13),) -> 12-2023 | B13: 45284 | C13: BeFlexible | D13: 699.5 | E13: 10 | F13: 9 | G13: =E13/F13 -> 1.1111111 | H13: =D13/E13 -> 69.95 | I13: =H13/G13 -> 62.955 | J13: 707 | K13: =E13/J13 -> 0.014144272 | L13: 162.81 | M13: 82349 | N13: 3 | O13: 209.85 | P13: =L13/O13 -> 0.77583989 | Q13: =O13/L13 -> 1.2889257 | R13: =L13/D13 -> 0.23275197 | S13: =O13/D13 -> 0.3 | T13: =D13-O13 -> 489.65 | U13: =L13/N13 -> 54.27
A14: =IFERROR(IF(B14>0,MONTH(B14)&"-"&YEAR(B14),B14),) -> 0 | C14: Better Bladder | D14: 13659.15 | E14: 199 | F14: 189 | G14: =E14/F14 -> 1.0529101 | H14: =D14/E14 -> 68.638945 | I14: =H14/G14 -> 65.189752 | J14: 1496 | K14: =E14/J14 -> 0.13302139 | L14: 1741.48 | M14: 253958 | N14: 86 | O14: 6494.9 | P14: =L14/O14 -> 0.26813038 | Q14: =O14/L14 -> 3.7295289 | R14: =L14/D14 -> 0.12749549 | S14: =O14/D14 -> 0.47549811 | T14: =D14-O14 -> 7164.25 | U14: =L14/N14 -> 20.249767
A15: =IFERROR(IF(B15>0,MONTH(B15)&"-"&YEAR(B15),B15),) -> 0 | C15: Grown American | D15: 9261.05 | E15: 179 | F15: 169 | G15: =E15/F15 -> 1.0591716 | H15: =D15/E15 -> 51.737709 | I15: =H15/G15 -> 48.847335 | J15: 1530 | K15: =E15/J15 -> 0.11699346 | L15: 1053.7 | M15: 64225 | N15: 72 | O15: 3266.25 | P15: =L15/O15 -> 0.32260237 | Q15: =O15/L15 -> 3.0997912 | R15: =L15/D15 -> 0.1137776 | S15: =O15/D15 -> 0.35268679 | T15: =D15-O15 -> 5994.8 | U15: =L15/N15 -> 14.634722
A16: =IFERROR(IF(B16>0,MONTH(B16)&"-"&YEAR(B16),B16),) -> 0 | C16: Ideal Prostate | D16: 10757.44 | E16: 152 | F16: 144 | G16: =E16/F16 -> 1.0555556 | H16: =D16/E16 -> 70.772632 | I16: =H16/G16 -> 67.047756 | J16: 967 | K16: =E16/J16 -> 0.15718718 | L16: 1071.59 | M16: 150867 | N16: 60 | O16: 4505.45 | P16: =L16/O16 -> 0.23784306 | Q16: =O16/L16 -> 4.2044532 | R16: =L16/D16 -> 0.099613849 | S16: =O16/D16 -> 0.41882176 | T16: =D16-O16 -> 6251.99 | U16: =L16/N16 -> 17.859833
C17: Prosvent | D17: 31741 | E17: 547 | F17: 486 | G17: =E17/F17 -> 1.1255144 | H17: =D17/E17 -> 58.027422 | I17: =H17/G17 -> 51.556357 | J17: 1950 | K17: =E17/J17 -> 0.28051282 | L17: 3422.86 | M17: 231750 | N17: 159 | O17: 10877.95 | P17: =L17/O17 -> 0.31466039 | Q17: =O17/L17 -> 3.1780295 | R17: =L17/D17 -> 0.10783718 | S17: =O17/D17 -> 0.34270974 | T17: =D17-O17 -> 20863.05 | U17: =L17/N17 -> 21.527421
A18: =IFERROR(IF(B18>0,MONTH(B18)&"-"&YEAR(B18),B18),) -> 12-2023 | B18: 45290 | C18: Cebria | D18: 2991.7 | E18: 58 | F18: 49 | G18: =E18/F18 -> 1.1836735 | H18: =D18/E18 -> 51.581034 | I18: =H18/G18 -> 43.577081 | J18: 229 | K18: =E18/J18 -> 0.25327511 | L18: 247.83 | M18: 232130 | N18: 15 | O18: 918.35 | P18: =L18/O18 -> 0.26986443 | Q18: =O18/L18 -> 3.7055643 | R18: =L18/D18 -> 0.082839188 | S18: =O18/D18 -> 0.30696594 | T18: =D18-O18 -> 2073.35 | U18: =L18/N18 -> 16.522
A19: =IFERROR(IF(B19>0,MONTH(B19)&"-"&YEAR(B19),B19),) -> 12-2023 | B19: December 2023 | D19: =SUM(D13:D18) -> 69109.84 | E19: =SUM(E13:E18) -> 1145 | F19: =SUM(F13:F18) -> 1046 | G19: =E19/F19 -> 1.0946463 | H19: =D19/E19 -> 60.357939 | I19: =H19/G19 -> 55.139218 | J19: =SUM(J13:J18) -> 6879 | K19: =E19/J19 -> 0.16644861 | L19: =SUM(L13:L18) -> 7700.27 | M19: =SUM(M13:M18) -> 1015279 | N19: =SUM(N13:N18) -> 395 | O19: =SUM(O13:O18) -> 26272.75 | P19: =L19/O19 -> 0.29308961 | Q19: =O19/L19 -> 3.4119258 | R19: =L19/D19 -> 0.11142075 | S19: =O19/D19 -> 0.38015932 | T19: =SUM(T13:T18) -> 42837.09 | U19: =L19/N19 -> 19.494354 | V19: =IFERROR((D19-#REF!)/D19,) -> 0 | W19: =IFERROR((E19-#REF!)/E19,) -> 0 | X19: =IFERROR((D19-monthly_reporting_2021!D49)/D19, ) -> 1 | Y19: =IFERROR((E19-monthly_reporting_2021!E49)/E19, ) -> 1
