Workbook

Sheet WALMART_weekly_reporting_2026-B
A1: WALMART - DATA SOURCES: https://seller.walmart.com/analytics/overview/item-sale; https://seller.walmart.com/analytics/reports; And Intentwise
C2: WEEKLY PERFORMANCE | Y2: =(#REF!+#REF!+#REF!+#REF!)-(monthly_reporting_2021!E17+monthly_reporting_2021!E23+monthly_reporting_2021!E29+monthly_reporting_2021!E35) -> #REF! | Z2: =((#REF!+#REF!+#REF!+#REF!)-(monthly_reporting_2021!F17+monthly_reporting_2021!F23+monthly_reporting_2021!F29+monthly_reporting_2021!F35))/(#REF!+#REF!+#REF!+#REF!) -> #REF!
C3: Total Sales | G3: Total Orders | L3: Total Units Sold
C4: =VLOOKUP("Current Week",$B$11:$Y$255,match("SALES",$B$11:$Y$11,0),FALSE) -> 24957.31 | G4: =VLOOKUP("Current Week",$B$11:$Y$255,match("Units Sold",$B$11:$Y$11,0),FALSE) -> 202 | L4: =VLOOKUP("Current Week",$B$11:$Y$255,match("Ordered Items",$B$11:$Y$11,0),FALSE) -> 220
C5: =(C4-(VLOOKUP("Previous Week",$B$11:$Y$260,match("SALES",$B$11:$Y$11,0),FALSE)))/C4 -> 0.10970293 | G5: =(G4-(VLOOKUP("Previous Week",$B$11:$Y$260,match("Units Sold",$B$11:$Y$11,0),FALSE)))/G4 -> -0.14356436 | L5: =(L4-(VLOOKUP("Previous Week",$B$11:$Y$260,match("Ordered Items",$B$11:$Y$11,0),FALSE)))/L4 -> -0.095454545
C7: Advertising Sales | G7: Advertising Spend | L7: ACoS
C8: =VLOOKUP("Current Week",$B$11:$Y$255,match("AD SALES",$B$11:$Y$11,0),FALSE) -> 11089.94 | G8: =VLOOKUP("Current Week",$B$11:$Y$255,match("SP AD SPEND",$B$11:$Y$11,0),FALSE) -> 3174.03 | L8: =G8/C8 -> 0.28620804
C9: =(C8-(VLOOKUP("Previous Week",$B$11:$Y$260,match("AD SALES",$B$11:$Y$11,0),FALSE)))/C8 -> 0.42563891 | G9: =(G8-(VLOOKUP("Previous Week",$B$11:$Y$260,match("SP AD SPEND",$B$11:$Y$11,0),FALSE)))/G8 -> 0.14245927 | L9: =(L8-(VLOOKUP("Previous Week",$B$11:$Y$260,match("ACOS",$B$11:$Y$11,0),FALSE)))/L8 -> -0.49303417
D10: SALES METRICS | M10: ADVERTISING PERFORMANCE | W10: MoM | Y10: YoY
A11: Month-Code | B11: DATE | C11: BRAND | D11: SALES | E11: Average Sales Price by Brand | F11: UNITS SOLD | G11: ORDERED ITEMS | H11: UNITS PER ORDER | I11: SALES PER ORDER | J11: ASP | K11: SP AD SPEND | L11: IMPRESSIONS | M11: UNIT SALES | N11: AD SALES | O11: ACoS | P11: ROAS (return on ad send) | Q11: TACoS (Total Advertsing Cost of Sales) | R11: REVENUE PERCENTAGE OF AD SALES | S11: ORGANIC SALES | T11: CPO | U11: SALES | V11: UNITS | W11: SALES | X11: UNITS
B13: 46012 | C13: AirDoctor | D13: 7936.51 | F13: 30 | G13: 30 | H13: =F13/G13 -> 1 | I13: =D13/F13 -> 264.55033 | J13: =I13/H13 -> 264.55033 | K13: 1654.24 | L13: 263207 | M13: 16 | N13: 4466.73 | O13: =K13/N13 -> 0.37034699 | P13: =N13/K13 -> 2.7001705 | Q13: =K13/D13 -> 0.20843419 | R13: =N13/D13 -> 0.56280783 | S13: =D13-N13 -> 3469.78 | T13: =K13/M13 -> 103.39
C14: AquaTru | D14: 19206.39 | F14: 104 | G14: 119 | H14: =F14/G14 -> 0.87394958 | I14: =D14/F14 -> 184.67683 | J14: =I14/H14 -> 211.31291 | K14: 1288.08 | L14: 442713 | M14: 37 | N14: 6713.65 | O14: =K14/N14 -> 0.19185987 | P14: =N14/K14 -> 5.2121374 | Q14: =K14/D14 -> 0.06706518 | R14: =N14/D14 -> 0.34955294 | S14: =D14-N14 -> 12492.74 | T14: =K14/M14 -> 34.812973
C15: Beflexible | D15: 0 | F15: 0 | G15: 0 | H15: =F15/G15 -> #DIV/0! | I15: =D15/F15 -> #DIV/0! | J15: =I15/H15 -> #DIV/0! | K15: 7.5 | L15: 288 | M15: 0 | N15: 0 | O15: =(K15/N15) -> #DIV/0! | P15: =N15/K15 -> 0 | Q15: =K15/D15 -> #DIV/0! | R15: =N15/D15 -> #DIV/0! | S15: =D15-N15 -> 0 | T15: =K15/M15 -> #DIV/0!
C16: Better Bladder | D16: 545.55 | F16: 9 | G16: 10 | H16: =F16/G16 -> 0.9 | I16: =D16/F16 -> 60.616667 | J16: =I16/H16 -> 67.351852 | K16: 184.21 | L16: 16259 | M16: 1 | N16: 59.95 | O16: =K16/N16 -> 3.0727273 | P16: =N16/K16 -> 0.32544379 | Q16: =K16/D16 -> 0.33765924 | R16: =N16/D16 -> 0.1098891 | S16: =D16-N16 -> 485.6 | T16: =K16/M16 -> 184.21
C17: Ideal Prostate | D17: 589.55 | F17: 9 | G17: 9 | H17: =F17/G17 -> 1 | I17: =D17/F17 -> 65.505556 | J17: =I17/H17 -> 65.505556 | K17: 52.21 | L17: 18056 | M17: 7 | N17: 479.65 | O17: =K17/N17 -> 0.1088502 | P17: =N17/K17 -> 9.1869374 | Q17: =K17/D17 -> 0.08855907 | R17: =N17/D17 -> 0.81358663 | S17: =D17-N17 -> 109.9 | T17: =K17/M17 -> 7.4585714
B18: to | C18: Miracle Blade | D18: -70.63 | F18: -2 | G18: 1 | H18: =F18/G18 -> -2 | I18: =D18/F18 -> 35.315 | J18: =I18/H18 -> -17.6575 | K18: 8.48 | L18: 697 | M18: 0 | N18: 0 | O18: =K18/N18 -> #DIV/0! | P18: =N18/K18 -> 0 | Q18: =K18/D18 -> -0.1200623 | R18: =N18/D18 -> 0 | S18: =D18-N18 -> -70.63 | T18: =K18/M18 -> #DIV/0!
C19: Paint Zoom | D19: 0 | F19: 0 | G19: 0 | H19: =F19/G19 -> #DIV/0! | I19: =D19/F19 -> #DIV/0! | J19: =I19/H19 -> #DIV/0! | K19: 0 | L19: 0 | M19: 0 | N19: 0 | O19: =K19/N19 -> #DIV/0! | P19: =N19/K19 -> #DIV/0! | Q19: =K19/D19 -> #DIV/0! | R19: =N19/D19 -> #DIV/0! | S19: =D19-N19 -> 0 | T19: =K19/M19 -> #DIV/0!
C20: Profemin | D20: 0 | F20: 0 | G20: 0 | H20: =F20/G20 -> #DIV/0! | I20: =D20/F20 -> #DIV/0! | J20: =I20/H20 -> #DIV/0! | K20: 0 | L20: 0 | M20: 0 | N20: 0 | O20: =K20/N20 -> #DIV/0! | P20: =N20/K20 -> #DIV/0! | Q20: =K20/D20 -> #DIV/0! | R20: =N20/D20 -> #DIV/0! | S20: =D20-N20 -> 0 | T20: =K20/M20 -> #DIV/0!
C21: Prosvent | D21: 2629.8 | F21: 29 | G21: 28 | H21: =F21/G21 -> 1.0357143 | I21: =D21/F21 -> 90.682759 | J21: =I21/H21 -> 87.555767 | K21: 668.15 | L21: 36463 | M21: 17 | N21: 1466.87 | O21: =K21/N21 -> 0.45549367 | P21: =N21/K21 -> 2.1954202 | Q21: =K21/D21 -> 0.25406875 | R21: =N21/D21 -> 0.55778766 | S21: =D21-N21 -> 1162.93 | T21: =K21/M21 -> 39.302941
C22: SaniTru | D22: 59.97 | F22: 3 | G22: 4 | H22: =F22/G22 -> 0.75 | I22: =D22/F22 -> 19.99 | J22: =I22/H22 -> 26.653333 | K22: 136.24 | L22: 47577 | M22: 2 | N22: 39.98 | O22: =K22/N22 -> 3.4077039 | P22: =N22/K22 -> 0.29345273 | Q22: =K22/D22 -> 2.2718026 | R22: =N22/D22 -> 0.66666667 | S22: =D22-N22 -> 19.99 | T22: =K22/M22 -> 68.12
C23: Rotorazer Saw | D23: 78.59 | F23: 0 | G23: 2 | H23: =F23/G23 -> 0 | I23: =D23/F23 -> #DIV/0! | J23: =I23/H23 -> #DIV/0! | K23: 36.36 | L23: 10972 | M23: 1 | N23: 154.46 | O23: =K23/N23 -> 0.23540075 | P23: =N23/K23 -> 4.2480748 | Q23: =K23/D23 -> 0.46265428 | R23: =N23/D23 -> 1.96539 | S23: =D23-N23 -> -75.87 | T23: =K23/M23 -> 36.36
C24: Superthotics | D24: 190.8 | F24: 4 | G24: 4 | H24: =F24/G24 -> 1 | I24: =D24/F24 -> 47.7 | J24: =I24/H24 -> 47.7 | K24: 80.52 | L24: 40401 | M24: 3 | N24: 134.85 | O24: =K24/N24 -> 0.5971079 | P24: =N24/K24 -> 1.6747392 | Q24: =K24/D24 -> 0.42201258 | R24: =N24/D24 -> 0.70676101 | S24: =D24-N24 -> 55.95 | T24: =K24/M24 -> 26.84
C25: Therabotanics | D25: 0 | F25: 0 | G25: 0 | H25: =F25/G25 -> #DIV/0! | I25: =D25/F25 -> #DIV/0! | J25: =I25/H25 -> #DIV/0! | K25: 0 | L25: 0 | M25: 0 | N25: 0 | O25: =K25/N25 -> #DIV/0! | P25: =N25/K25 -> #DIV/0! | Q25: =K25/D25 -> #DIV/0! | R25: =N25/D25 -> #DIV/0! | S25: =D25-N25 -> 0 | T25: =K25/M25 -> #DIV/0!
C26: WALKFIT | D26: 1312.67 | F26: 34 | G26: 31 | H26: =F26/G26 -> 1.0967742 | I26: =D26/F26 -> 38.607941 | J26: =I26/H26 -> 35.201358 | K26: 269.35 | L26: 50705 | M26: 13 | N26: 403.73 | O26: =K26/N26 -> 0.66715379 | P26: =N26/K26 -> 1.4989048 | Q26: =K26/D26 -> 0.20519247 | R26: =N26/D26 -> 0.30756397 | S26: =D26-N26 -> 908.94 | T26: =K26/M26 -> 20.719231
C27: Ultmax | D27: -29.95 | F27: -1 | G27: 0 | H27: =F27/G27 -> #DIV/0! | I27: =D27/F27 -> 29.95 | J27: =I27/H27 -> #DIV/0! | K27: 0 | L27: 0 | M27: 0 | N27: 0 | O27: =K27/N27 -> #DIV/0! | P27: =N27/K27 -> #DIV/0! | Q27: =K27/D27 -> 0 | R27: =N27/D27 -> 0 | S27: =D27-N27 -> -29.95 | T27: =K27/M27 -> #DIV/0!
C28: Ionic Pro | D28: 4625.06 | F28: 26 | G28: 28 | H28: =F28/G28 -> 0.92857143 | I28: =D28/F28 -> 177.88692 | J28: =I28/H28 -> 191.57053 | K28: 692.49 | L28: 44157 | M28: 11 | N28: 1670.89 | O28: =K28/N28 -> 0.4144438 | P28: =N28/K28 -> 2.4128724 | Q28: =K28/D28 -> 0.14972563 | R28: =N28/D28 -> 0.36126883 | S28: =D28-N28 -> 2954.17 | T28: =K28/M28 -> 62.953636
A29: =iferror(if(B29>0,month(B29)&"-"&year(B29),B29),) -> 12-2025 | B29: 46018 | C29: AromaTru | D29: 0 | F29: 0 | G29: 0 | H29: =F29/G29 -> #DIV/0! | I29: =D29/F29 -> #DIV/0! | J29: =I29/H29 -> #DIV/0! | K29: 16.97 | L29: 17393 | M29: 0 | N29: 0 | O29: =K29/N29 -> #DIV/0! | P29: =N29/K29 -> 0 | Q29: =K29/D29 -> #DIV/0! | R29: =N29/D29 -> #DIV/0! | S29: =D29-N29 -> 0 | T29: =K29/M29 -> #DIV/0!
A30: =iferror(if(B30>0,month(B30)&"-"&year(B30),B30),) | B30: 2025 - Week 52 | D30: =SUM(D13:D29) -> 37074.31 | F30: =SUM(F13:F29) -> 245 | G30: =SUM(G13:G29) -> 266 | H30: =F30/G30 -> 0.92105263 | I30: =D30/F30 -> 151.32371 | J30: =I30/H30 -> 164.29432 | K30: =SUM(K13:K29) -> 5094.8 | L30: =SUM(L13:L29) -> 988888 | M30: =SUM(M13:M29) -> 108 | N30: =SUM(N13:N29) -> 15590.76 | O30: =K30/N30 -> 0.3267833 | P30: =N30/K30 -> 3.0601319 | Q30: =K30/D30 -> 0.1374213 | R30: =N30/D30 -> 0.42052731 | S30: =SUM(S13:S29) -> 21483.55 | T30: =K30/M30 -> 47.174074 | U30: =IFERROR((D30-#REF!)/D30,) | V30: =IFERROR((F30-#REF!)/F30,) | W30: =IFERROR((D30-#REF!)/D30, ) | X30: =IFERROR((F30-#REF!)/F30, )
B31: 46019 | C31: AirDoctor | D31: 13519.5 | F31: 57 | G31: 57 | H31: =F31/G31 -> 1 | I31: =D31/F31 -> 237.18421 | J31: =I31/H31 -> 237.18421 | K31: 1867.63 | L31: 249548 | M31: 23 | N31: 5019.44 | O31: =K31/N31 -> 0.37207936 | P31: =N31/K31 -> 2.6875987 | Q31: =K31/D31 -> 0.13814342 | R31: =N31/D31 -> 0.37127409 | S31: =D31-N31 -> 8500.06 | T31: =K31/M31 -> 81.201304
C32: AquaTru | D32: 18767.79 | F32: 145 | G32: 161 | H32: =F32/G32 -> 0.90062112 | I32: =D32/F32 -> 129.43303 | J32: =I32/H32 -> 143.7153 | K32: 1072.07 | L32: 465644 | M32: 32 | N32: 3923.85 | O32: =K32/N32 -> 0.2732189 | P32: =N32/K32 -> 3.6600688 | Q32: =K32/D32 -> 0.057122868 | R32: =N32/D32 -> 0.20907363 | S32: =D32-N32 -> 14843.94 | T32: =K32/M32 -> 33.502187
C33: Beflexible | D33: 0 | F33: 0 | G33: 0 | H33: =F33/G33 -> #DIV/0! | I33: =D33/F33 -> #DIV/0! | J33: =I33/H33 -> #DIV/0! | K33: 0 | L33: 376 | M33: 0 | N33: 0 | O33: =(K33/N33) -> #DIV/0! | P33: =N33/K33 -> #DIV/0! | Q33: =K33/D33 -> #DIV/0! | R33: =N33/D33 -> #DIV/0! | S33: =D33-N33 -> 0 | T33: =K33/M33 -> #DIV/0!
C34: Better Bladder | D34: 125.9 | F34: 2 | G34: 2 | H34: =F34/G34 -> 1 | I34: =D34/F34 -> 62.95 | J34: =I34/H34 -> 62.95 | K34: 298.8 | L34: 26455 | M34: 5 | N34: 299.75 | O34: =K34/N34 -> 0.99683069 | P34: =N34/K34 -> 1.0031794 | Q34: =K34/D34 -> 2.3733122 | R34: =N34/D34 -> 2.3808578 | S34: =D34-N34 -> -173.85 | T34: =K34/M34 -> 59.76
C35: Ideal Prostate | D35: 359.7 | F35: 6 | G35: 6 | H35: =F35/G35 -> 1 | I35: =D35/F35 -> 59.95 | J35: =I35/H35 -> 59.95 | K35: 105.72 | L35: 27117 | M35: 2 | N35: 129.9 | O35: =K35/N35 -> 0.81385681 | P35: =N35/K35 -> 1.2287174 | Q35: =K35/D35 -> 0.29391159 | R35: =N35/D35 -> 0.36113428 | S35: =D35-N35 -> 229.8 | T35: =K35/M35 -> 52.86
B36: to | C36: Miracle Blade | D36: -60.73 | F36: 0 | G36: 1 | H36: =F36/G36 -> 0 | I36: =D36/F36 -> #DIV/0! | J36: =I36/H36 -> #DIV/0! | K36: 83.88 | L36: 253679 | M36: 0 | N36: 0 | O36: =K36/N36 -> #DIV/0! | P36: =N36/K36 -> 0 | Q36: =K36/D36 -> -1.3811955 | R36: =N36/D36 -> 0 | S36: =D36-N36 -> -60.73 | T36: =K36/M36 -> #DIV/0!
C37: Paint Zoom | D37: 0 | F37: 0 | G37: 0 | H37: =F37/G37 -> #DIV/0! | I37: =D37/F37 -> #DIV/0! | J37: =I37/H37 -> #DIV/0! | K37: 0 | L37: 0 | M37: 0 | N37: 0 | O37: =K37/N37 -> #DIV/0! | P37: =N37/K37 -> #DIV/0! | Q37: =K37/D37 -> #DIV/0! | R37: =N37/D37 -> #DIV/0! | S37: =D37-N37 -> 0 | T37: =K37/M37 -> #DIV/0!
C38: Profemin | D38: 0 | F38: 0 | G38: 0 | H38: =F38/G38 -> #DIV/0! | I38: =D38/F38 -> #DIV/0! | J38: =I38/H38 -> #DIV/0! | K38: 0 | L38: 0 | M38: 0 | N38: 0 | O38: =K38/N38 -> #DIV/0! | P38: =N38/K38 -> #DIV/0! | Q38: =K38/D38 -> #DIV/0! | R38: =N38/D38 -> #DIV/0! | S38: =D38-N38 -> 0 | T38: =K38/M38 -> #DIV/0!
C39: Prosvent | D39: 3534.27 | F39: 49 | G39: 51 | H39: =F39/G39 -> 0.96078431 | I39: =D39/F39 -> 72.127959 | J39: =I39/H39 -> 75.071958 | K39: 799.06 | L39: 59789 | M39: 14 | N39: 877.86 | O39: =K39/N39 -> 0.91023626 | P39: =N39/K39 -> 1.0986159 | Q39: =K39/D39 -> 0.22608912 | R39: =N39/D39 -> 0.2483851 | S39: =D39-N39 -> 2656.41 | T39: =K39/M39 -> 57.075714
C40: SaniTru | D40: 59.97 | F40: 3 | G40: 3 | H40: =F40/G40 -> 1 | I40: =D40/F40 -> 19.99 | J40: =I40/H40 -> 19.99 | K40: 356.37 | L40: 105893 | M40: 2 | N40: 39.98 | O40: =K40/N40 -> 8.9137069 | P40: =N40/K40 -> 0.11218677 | Q40: =K40/D40 -> 5.9424712 | R40: =N40/D40 -> 0.66666667 | S40: =D40-N40 -> 19.99 | T40: =K40/M40 -> 178.185
C41: Rotorazer Saw | D41: 1547.97 | F41: 13 | G41: 13 | H41: =F41/G41 -> 1 | I41: =D41/F41 -> 119.07462 | J41: =I41/H41 -> 119.07462 | K41: 74.14 | L41: 10788 | M41: 1 | N41: 0 | O41: =K41/N41 -> #DIV/0! | P41: =N41/K41 -> 0 | Q41: =K41/D41 -> 0.047894985 | R41: =N41/D41 -> 0 | S41: =D41-N41 -> 1547.97 | T41: =K41/M41 -> 74.14
C42: Superthotics | D42: 209.8 | F42: 4 | G42: 4 | H42: =F42/G42 -> 1 | I42: =D42/F42 -> 52.45 | J42: =I42/H42 -> 52.45 | K42: 72.7 | L42: 40190 | M42: 3 | N42: 164.85 | O42: =K42/N42 -> 0.44100698 | P42: =N42/K42 -> 2.2675378 | Q42: =K42/D42 -> 0.3465205 | R42: =N42/D42 -> 0.78574833 | S42: =D42-N42 -> 44.95 | T42: =K42/M42 -> 24.233333
...

Sheet SEM campaigns summary + total f
A1: WALMART - DATA SOURCES: https://seller.walmart.com/analytics/overview/item-sale; https://seller.walmart.com/analytics/reports; And Intentwise
C2: WEEKLY PERFORMANCE | X2: =(#REF!+#REF!+#REF!+#REF!)-(monthly_reporting_2021!D17+monthly_reporting_2021!D23+monthly_reporting_2021!D29+monthly_reporting_2021!D35) -> #REF! | Y2: =((#REF!+#REF!+#REF!+#REF!)-(monthly_reporting_2021!E17+monthly_reporting_2021!E23+monthly_reporting_2021!E29+monthly_reporting_2021!E35))/(#REF!+#REF!+#REF!+#REF!) -> #REF!
C3: Total Sales | F3: Total Orders | K3: Total Units Sold
C4: =VLOOKUP("Current Week",$B$11:$X$268,match("SALES",$B$11:$X$11,0),FALSE) -> 24957.31 | F4: =VLOOKUP("Current Week",$B$11:$X$268,match("Units Sold",$B$11:$X$11,0),FALSE) -> 202 | K4: =VLOOKUP("Current Week",$B$11:$X$268,match("Ordered Items",$B$11:$X$11,0),FALSE) -> 220
C5: =(C4-(VLOOKUP("Previous Week",$B$11:$X$273,match("SALES",$B$11:$X$11,0),FALSE)))/C4 -> 0.10970293 | F5: =(F4-(VLOOKUP("Previous Week",$B$11:$X$273,match("Units Sold",$B$11:$X$11,0),FALSE)))/F4 -> -0.14356436 | K5: =(K4-(VLOOKUP("Previous Week",$B$11:$X$273,match("Ordered Items",$B$11:$X$11,0),FALSE)))/K4 -> -0.095454545
C7: Advertising Sales | F7: Advertising Spend | K7: ACoS
C8: =VLOOKUP("Current Week",$B$11:$X$268,match("AD SALES",$B$11:$X$11,0),FALSE) -> 21577.88 | F8: =VLOOKUP("Current Week",$B$11:$X$268,match("SP AD SPEND",$B$11:$X$11,0),FALSE) -> 8091.58 | K8: =F8/C8 -> 0.37499421
C9: =(C8-(VLOOKUP("Previous Week",$B$11:$X$273,match("AD SALES",$B$11:$X$11,0),FALSE)))/C8 -> 0.286435 | F9: =(F8-(VLOOKUP("Previous Week",$B$11:$X$273,match("SP AD SPEND",$B$11:$X$11,0),FALSE)))/F8 -> -0.0089401575 | K9: =(K8-(VLOOKUP("Previous Week",$B$11:$X$273,match("ACOS",$B$11:$X$11,0),FALSE)))/K8 -> -0.41394288
D10: SALES METRICS | L10: ADVERTISING PERFORMANCE | V10: MoM | X10: YoY
A11: Month-Code | B11: DATE | C11: BRAND | D11: SALES | E11: UNITS SOLD | F11: ORDERED ITEMS | G11: UNITS PER ORDER | H11: SALES PER ORDER | I11: ASP | J11: SP AD SPEND | K11: IMPRESSIONS | L11: UNIT SALES | M11: AD SALES | N11: ACoS | O11: ROAS (return on ad send) | P11: TACoS (Total Advertsing Cost of Sales) | Q11: REVENUE PERCENTAGE OF AD SALES | R11: ORGANIC SALES | S11: CPO | T11: SALES | U11: UNITS | V11: SALES | W11: UNITS
B13: 46012 | C13: AirDoctor | D13: 7936.51 | E13: 30 | F13: 30 | G13: =E13/F13 -> 1 | H13: =D13/E13 -> 264.55033 | I13: =H13/G13 -> 264.55033 | J13: 1654.24 | K13: 263207 | L13: 16 | M13: 4466.73 | N13: =J13/M13 -> 0.37034699 | O13: =M13/J13 -> 2.7001705 | P13: =J13/D13 -> 0.20843419 | Q13: =M13/D13 -> 0.56280783 | R13: =D13-M13 -> 3469.78 | S13: =J13/L13 -> 103.39
C14: AquaTru | D14: 19206.39 | E14: 104 | F14: 119 | G14: =E14/F14 -> 0.87394958 | H14: =D14/E14 -> 184.67683 | I14: =H14/G14 -> 211.31291 | J14: 1288.08 | K14: 442713 | L14: 37 | M14: 6713.65 | N14: =J14/M14 -> 0.19185987 | O14: =M14/J14 -> 5.2121374 | P14: =J14/D14 -> 0.06706518 | Q14: =M14/D14 -> 0.34955294 | R14: =D14-M14 -> 12492.74 | S14: =J14/L14 -> 34.812973
C15: Beflexible | D15: 0 | E15: 0 | F15: 0 | G15: =E15/F15 -> #DIV/0! | H15: =D15/E15 -> #DIV/0! | I15: =H15/G15 -> #DIV/0! | J15: 7.5 | K15: 288 | L15: 0 | M15: 0 | N15: =(J15/M15) -> #DIV/0! | O15: =M15/J15 -> 0 | P15: =J15/D15 -> #DIV/0! | Q15: =M15/D15 -> #DIV/0! | R15: =D15-M15 -> 0 | S15: =J15/L15 -> #DIV/0!
C16: Better Bladder | D16: 545.55 | E16: 9 | F16: 10 | G16: =E16/F16 -> 0.9 | H16: =D16/E16 -> 60.616667 | I16: =H16/G16 -> 67.351852 | J16: 184.21 | K16: 16259 | L16: 1 | M16: 59.95 | N16: =J16/M16 -> 3.0727273 | O16: =M16/J16 -> 0.32544379 | P16: =J16/D16 -> 0.33765924 | Q16: =M16/D16 -> 0.1098891 | R16: =D16-M16 -> 485.6 | S16: =J16/L16 -> 184.21
C17: Ideal Prostate | D17: 589.55 | E17: 9 | F17: 9 | G17: =E17/F17 -> 1 | H17: =D17/E17 -> 65.505556 | I17: =H17/G17 -> 65.505556 | J17: 52.21 | K17: 18056 | L17: 7 | M17: 479.65 | N17: =J17/M17 -> 0.1088502 | O17: =M17/J17 -> 9.1869374 | P17: =J17/D17 -> 0.08855907 | Q17: =M17/D17 -> 0.81358663 | R17: =D17-M17 -> 109.9 | S17: =J17/L17 -> 7.4585714
B18: to | C18: Miracle Blade | D18: -70.63 | E18: -2 | F18: 1 | G18: =E18/F18 -> -2 | H18: =D18/E18 -> 35.315 | I18: =H18/G18 -> -17.6575 | J18: 8.48 | K18: 697 | L18: 0 | M18: 0 | N18: =J18/M18 -> #DIV/0! | O18: =M18/J18 -> 0 | P18: =J18/D18 -> -0.1200623 | Q18: =M18/D18 -> 0 | R18: =D18-M18 -> -70.63 | S18: =J18/L18 -> #DIV/0!
C19: Paint Zoom | D19: 0 | E19: 0 | F19: 0 | G19: =E19/F19 -> #DIV/0! | H19: =D19/E19 -> #DIV/0! | I19: =H19/G19 -> #DIV/0! | J19: 0 | K19: 0 | L19: 0 | M19: 0 | N19: =J19/M19 -> #DIV/0! | O19: =M19/J19 -> #DIV/0! | P19: =J19/D19 -> #DIV/0! | Q19: =M19/D19 -> #DIV/0! | R19: =D19-M19 -> 0 | S19: =J19/L19 -> #DIV/0!
C20: Profemin | D20: 0 | E20: 0 | F20: 0 | G20: =E20/F20 -> #DIV/0! | H20: =D20/E20 -> #DIV/0! | I20: =H20/G20 -> #DIV/0! | J20: 0 | K20: 0 | L20: 0 | M20: 0 | N20: =J20/M20 -> #DIV/0! | O20: =M20/J20 -> #DIV/0! | P20: =J20/D20 -> #DIV/0! | Q20: =M20/D20 -> #DIV/0! | R20: =D20-M20 -> 0 | S20: =J20/L20 -> #DIV/0!
C21: Prosvent | D21: 2629.8 | E21: 29 | F21: 28 | G21: =E21/F21 -> 1.0357143 | H21: =D21/E21 -> 90.682759 | I21: =H21/G21 -> 87.555767 | J21: 668.15 | K21: 36463 | L21: 17 | M21: 1466.87 | N21: =J21/M21 -> 0.45549367 | O21: =M21/J21 -> 2.1954202 | P21: =J21/D21 -> 0.25406875 | Q21: =M21/D21 -> 0.55778766 | R21: =D21-M21 -> 1162.93 | S21: =J21/L21 -> 39.302941
C22: SaniTru | D22: 59.97 | E22: 3 | F22: 4 | G22: =E22/F22 -> 0.75 | H22: =D22/E22 -> 19.99 | I22: =H22/G22 -> 26.653333 | J22: 136.24 | K22: 47577 | L22: 2 | M22: 39.98 | N22: =J22/M22 -> 3.4077039 | O22: =M22/J22 -> 0.29345273 | P22: =J22/D22 -> 2.2718026 | Q22: =M22/D22 -> 0.66666667 | R22: =D22-M22 -> 19.99 | S22: =J22/L22 -> 68.12
C23: Rotorazer Saw | D23: 78.59 | E23: 0 | F23: 2 | G23: =E23/F23 -> 0 | H23: =D23/E23 -> #DIV/0! | I23: =H23/G23 -> #DIV/0! | J23: 36.36 | K23: 10972 | L23: 1 | M23: 154.46 | N23: =J23/M23 -> 0.23540075 | O23: =M23/J23 -> 4.2480748 | P23: =J23/D23 -> 0.46265428 | Q23: =M23/D23 -> 1.96539 | R23: =D23-M23 -> -75.87 | S23: =J23/L23 -> 36.36
C24: Superthotics | D24: 190.8 | E24: 4 | F24: 4 | G24: =E24/F24 -> 1 | H24: =D24/E24 -> 47.7 | I24: =H24/G24 -> 47.7 | J24: 80.52 | K24: 40401 | L24: 3 | M24: 134.85 | N24: =J24/M24 -> 0.5971079 | O24: =M24/J24 -> 1.6747392 | P24: =J24/D24 -> 0.42201258 | Q24: =M24/D24 -> 0.70676101 | R24: =D24-M24 -> 55.95 | S24: =J24/L24 -> 26.84
C25: Therabotanics | D25: 0 | E25: 0 | F25: 0 | G25: =E25/F25 -> #DIV/0! | H25: =D25/E25 -> #DIV/0! | I25: =H25/G25 -> #DIV/0! | J25: 0 | K25: 0 | L25: 0 | M25: 0 | N25: =J25/M25 -> #DIV/0! | O25: =M25/J25 -> #DIV/0! | P25: =J25/D25 -> #DIV/0! | Q25: =M25/D25 -> #DIV/0! | R25: =D25-M25 -> 0 | S25: =J25/L25 -> #DIV/0!
C26: WALKFIT | D26: 1312.67 | E26: 34 | F26: 31 | G26: =E26/F26 -> 1.0967742 | H26: =D26/E26 -> 38.607941 | I26: =H26/G26 -> 35.201358 | J26: 269.35 | K26: 50705 | L26: 13 | M26: 403.73 | N26: =J26/M26 -> 0.66715379 | O26: =M26/J26 -> 1.4989048 | P26: =J26/D26 -> 0.20519247 | Q26: =M26/D26 -> 0.30756397 | R26: =D26-M26 -> 908.94 | S26: =J26/L26 -> 20.719231
C27: Ultmax | D27: -29.95 | E27: -1 | F27: 0 | G27: =E27/F27 -> #DIV/0! | H27: =D27/E27 -> 29.95 | I27: =H27/G27 -> #DIV/0! | J27: 0 | K27: 0 | L27: 0 | M27: 0 | N27: =J27/M27 -> #DIV/0! | O27: =M27/J27 -> #DIV/0! | P27: =J27/D27 -> 0 | Q27: =M27/D27 -> 0 | R27: =D27-M27 -> -29.95 | S27: =J27/L27 -> #DIV/0!
C28: Ionic Pro | D28: 4625.06 | E28: 26 | F28: 28 | G28: =E28/F28 -> 0.92857143 | H28: =D28/E28 -> 177.88692 | I28: =H28/G28 -> 191.57053 | J28: 692.49 | K28: 44157 | L28: 11 | M28: 1670.89 | N28: =J28/M28 -> 0.4144438 | O28: =M28/J28 -> 2.4128724 | P28: =J28/D28 -> 0.14972563 | Q28: =M28/D28 -> 0.36126883 | R28: =D28-M28 -> 2954.17 | S28: =J28/L28 -> 62.953636
C29: AromaTru | D29: 0 | E29: 0 | F29: 0 | G29: =E29/F29 -> #DIV/0! | H29: =D29/E29 -> #DIV/0! | I29: =H29/G29 -> #DIV/0! | J29: 16.97 | K29: 17393 | L29: 0 | M29: 0 | N29: =J29/M29 -> #DIV/0! | O29: =M29/J29 -> 0 | P29: =J29/D29 -> #DIV/0! | Q29: =M29/D29 -> #DIV/0! | R29: =D29-M29 -> 0 | S29: =J29/L29 -> #DIV/0!
A30: =iferror(if(B30>0,month(B30)&"-"&year(B30),B30),) -> 12-2025 | B30: 46018 | C30: SEM Campaigns | D30: 0 | E30: 0 | F30: 0 | G30: =E30/F30 -> #DIV/0! | H30: =D30/E30 -> #DIV/0! | I30: =H30/G30 -> #DIV/0! | J30: 6654.44 | K30: 465451 | L30: 0 | M30: 18889.62 | N30: =J30/M30 -> 0.35228025 | O30: =M30/J30 -> 2.8386491 | P30: =J30/D30 -> #DIV/0! | Q30: =M30/D30 -> #DIV/0! | R30: =D30-M30 -> -18889.62 | S30: =J30/L30 -> #DIV/0!
A31: =iferror(if(B31>0,month(B31)&"-"&year(B31),B31),) | B31: 2025 - Week 52 | D31: =SUM(D13:D30) -> 37074.31 | E31: =SUM(E13:E30) -> 245 | F31: =SUM(F13:F30) -> 266 | G31: =E31/F31 -> 0.92105263 | H31: =D31/E31 -> 151.32371 | I31: =H31/G31 -> 164.29432 | J31: =SUM(J13:J30) -> 11749.24 | K31: =SUM(K13:K30) -> 1454339 | L31: =SUM(L13:L30) -> 108 | M31: =SUM(M13:M30) -> 34480.38 | N31: =J31/M31 -> 0.34075146 | O31: =M31/J31 -> 2.9346902 | P31: =J31/D31 -> 0.31691055 | Q31: =M31/D31 -> 0.9300343 | R31: =SUM(R13:R30) -> 2593.93 | S31: =J31/L31 -> 108.78926 | T31: =IFERROR((D31-#REF!)/D31,) | U31: =IFERROR((E31-#REF!)/E31,) | V31: =IFERROR((D31-#REF!)/D31, ) | W31: =IFERROR((E31-#REF!)/E31, )
B32: 46019 | C32: AirDoctor | D32: 13519.5 | E32: 57 | F32: 57 | G32: =E32/F32 -> 1 | H32: =D32/E32 -> 237.18421 | I32: =H32/G32 -> 237.18421 | J32: 1867.63 | K32: 249548 | L32: 23 | M32: 5019.44 | N32: =J32/M32 -> 0.37207936 | O32: =M32/J32 -> 2.6875987 | P32: =J32/D32 -> 0.13814342 | Q32: =M32/D32 -> 0.37127409 | R32: =D32-M32 -> 8500.06 | S32: =J32/L32 -> 81.201304
C33: AquaTru | D33: 18767.79 | E33: 145 | F33: 161 | G33: =E33/F33 -> 0.90062112 | H33: =D33/E33 -> 129.43303 | I33: =H33/G33 -> 143.7153 | J33: 1072.07 | K33: 465644 | L33: 32 | M33: 3923.85 | N33: =J33/M33 -> 0.2732189 | O33: =M33/J33 -> 3.6600688 | P33: =J33/D33 -> 0.057122868 | Q33: =M33/D33 -> 0.20907363 | R33: =D33-M33 -> 14843.94 | S33: =J33/L33 -> 33.502187
C34: Beflexible | D34: 0 | E34: 0 | F34: 0 | G34: =E34/F34 -> #DIV/0! | H34: =D34/E34 -> #DIV/0! | I34: =H34/G34 -> #DIV/0! | J34: 0 | K34: 376 | L34: 0 | M34: 0 | N34: =(J34/M34) -> #DIV/0! | O34: =M34/J34 -> #DIV/0! | P34: =J34/D34 -> #DIV/0! | Q34: =M34/D34 -> #DIV/0! | R34: =D34-M34 -> 0 | S34: =J34/L34 -> #DIV/0!
C35: Better Bladder | D35: 125.9 | E35: 2 | F35: 2 | G35: =E35/F35 -> 1 | H35: =D35/E35 -> 62.95 | I35: =H35/G35 -> 62.95 | J35: 298.8 | K35: 26455 | L35: 5 | M35: 299.75 | N35: =J35/M35 -> 0.99683069 | O35: =M35/J35 -> 1.0031794 | P35: =J35/D35 -> 2.3733122 | Q35: =M35/D35 -> 2.3808578 | R35: =D35-M35 -> -173.85 | S35: =J35/L35 -> 59.76
C36: Ideal Prostate | D36: 359.7 | E36: 6 | F36: 6 | G36: =E36/F36 -> 1 | H36: =D36/E36 -> 59.95 | I36: =H36/G36 -> 59.95 | J36: 105.72 | K36: 27117 | L36: 2 | M36: 129.9 | N36: =J36/M36 -> 0.81385681 | O36: =M36/J36 -> 1.2287174 | P36: =J36/D36 -> 0.29391159 | Q36: =M36/D36 -> 0.36113428 | R36: =D36-M36 -> 229.8 | S36: =J36/L36 -> 52.86
B37: to | C37: Miracle Blade | D37: -60.73 | E37: 0 | F37: 1 | G37: =E37/F37 -> 0 | H37: =D37/E37 -> #DIV/0! | I37: =H37/G37 -> #DIV/0! | J37: 83.88 | K37: 253679 | L37: 0 | M37: 0 | N37: =J37/M37 -> #DIV/0! | O37: =M37/J37 -> 0 | P37: =J37/D37 -> -1.3811955 | Q37: =M37/D37 -> 0 | R37: =D37-M37 -> -60.73 | S37: =J37/L37 -> #DIV/0!
C38: Paint Zoom | D38: 0 | E38: 0 | F38: 0 | G38: =E38/F38 -> #DIV/0! | H38: =D38/E38 -> #DIV/0! | I38: =H38/G38 -> #DIV/0! | J38: 0 | K38: 0 | L38: 0 | M38: 0 | N38: =J38/M38 -> #DIV/0! | O38: =M38/J38 -> #DIV/0! | P38: =J38/D38 -> #DIV/0! | Q38: =M38/D38 -> #DIV/0! | R38: =D38-M38 -> 0 | S38: =J38/L38 -> #DIV/0!
C39: Profemin | D39: 0 | E39: 0 | F39: 0 | G39: =E39/F39 -> #DIV/0! | H39: =D39/E39 -> #DIV/0! | I39: =H39/G39 -> #DIV/0! | J39: 0 | K39: 0 | L39: 0 | M39: 0 | N39: =J39/M39 -> #DIV/0! | O39: =M39/J39 -> #DIV/0! | P39: =J39/D39 -> #DIV/0! | Q39: =M39/D39 -> #DIV/0! | R39: =D39-M39 -> 0 | S39: =J39/L39 -> #DIV/0!
C40: Prosvent | D40: 3534.27 | E40: 49 | F40: 51 | G40: =E40/F40 -> 0.96078431 | H40: =D40/E40 -> 72.127959 | I40: =H40/G40 -> 75.071958 | J40: 799.06 | K40: 59789 | L40: 14 | M40: 877.86 | N40: =J40/M40 -> 0.91023626 | O40: =M40/J40 -> 1.0986159 | P40: =J40/D40 -> 0.22608912 | Q40: =M40/D40 -> 0.2483851 | R40: =D40-M40 -> 2656.41 | S40: =J40/L40 -> 57.075714
C41: SaniTru | D41: 59.97 | E41: 3 | F41: 3 | G41: =E41/F41 -> 1 | H41: =D41/E41 -> 19.99 | I41: =H41/G41 -> 19.99 | J41: 356.37 | K41: 105893 | L41: 2 | M41: 39.98 | N41: =J41/M41 -> 8.9137069 | O41: =M41/J41 -> 0.11218677 | P41: =J41/D41 -> 5.9424712 | Q41: =M41/D41 -> 0.66666667 | R41: =D41-M41 -> 19.99 | S41: =J41/L41 -> 178.185
C42: Rotorazer Saw | D42: 1547.97 | E42: 13 | F42: 13 | G42: =E42/F42 -> 1 | H42: =D42/E42 -> 119.07462 | I42: =H42/G42 -> 119.07462 | J42: 74.14 | K42: 10788 | L42: 1 | M42: 0 | N42: =J42/M42 -> #DIV/0! | O42: =M42/J42 -> 0 | P42: =J42/D42 -> 0.047894985 | Q42: =M42/D42 -> 0 | R42: =D42-M42 -> 1547.97 | S42: =J42/L42 -> 74.14
...

Sheet SEM Campaigns Data 2026
A1: WALMART - DATA SOURCES: https://seller.walmart.com/advertising/search-engine-marketing/
C2: WEEKLY PERFORMANCE | X2: =(#REF!+#REF!+#REF!+#REF!)-(monthly_reporting_2021!D17+monthly_reporting_2021!D23+monthly_reporting_2021!D29+monthly_reporting_2021!D35) -> #REF! | Y2: =((#REF!+#REF!+#REF!+#REF!)-(monthly_reporting_2021!E17+monthly_reporting_2021!E23+monthly_reporting_2021!E29+monthly_reporting_2021!E35))/(#REF!+#REF!+#REF!+#REF!) -> #REF!
A3: Total Sales | D3: Total Orders | I3: Total Units Sold
A4: =VLOOKUP("Current Week",$B$11:$X$208,match("SALES",$B$11:$X$11,0),FALSE) -> 0 | D4: =VLOOKUP("Current Week",$B$11:$X$208,match("Units Sold",$B$11:$X$11,0),FALSE) -> 0 | I4: =VLOOKUP("Current Week",$B$11:$X$208,match("Ordered Items",$B$11:$X$11,0),FALSE) -> 0
A5: =(A4-(VLOOKUP("Previous Week",$B$11:$X$213,match("SALES",$B$11:$X$11,0),FALSE)))/A4 -> #DIV/0! | D5: =(D4-(VLOOKUP("Previous Week",$B$11:$X$213,match("Units Sold",$B$11:$X$11,0),FALSE)))/D4 -> #DIV/0! | I5: =(I4-(VLOOKUP("Previous Week",$B$11:$X$213,match("Ordered Items",$B$11:$X$11,0),FALSE)))/I4 -> #DIV/0!
A7: Advertising Sales | D7: Advertising Spend | I7: ACoS
A8: =VLOOKUP("Current Week",$B$11:$X$208,match("AD SALES",$B$11:$X$11,0),FALSE) -> 10487.94 | D8: =VLOOKUP("Current Week",$B$11:$X$208,match("SP AD SPEND",$B$11:$X$11,0),FALSE) -> 4917.55 | I8: =D8/A8 -> 0.46887663
A9: =(A8-(VLOOKUP("Previous Week",$B$11:$X$213,match("AD SALES",$B$11:$X$11,0),FALSE)))/A8 -> 0.13924088 | D9: =(D8-(VLOOKUP("Previous Week",$B$11:$X$213,match("SP AD SPEND",$B$11:$X$11,0),FALSE)))/D8 -> -0.10666084 | I9: =(I8-(VLOOKUP("Previous Week",$B$11:$X$213,match("ACOS",$B$11:$X$11,0),FALSE)))/I8 -> -0.28568006
D10: SALES METRICS | L10: ADVERTISING PERFORMANCE | V10: MoM | X10: YoY
A11: Month-Code | B11: DATE | C11: Campaign Name | D11: SALES | E11: UNITS SOLD | F11: ORDERED ITEMS | G11: UNITS PER ORDER | H11: SALES PER ORDER | I11: ASP | J11: SP AD SPEND | K11: IMPRESSIONS | L11: UNIT SALES | M11: AD SALES | N11: ACoS | O11: ROAS (return on ad send) | P11: TACoS (Total Advertsing Cost of Sales) | Q11: REVENUE PERCENTAGE OF AD SALES | R11: ORGANIC SALES | S11: CPO | T11: SALES | U11: UNITS | V11: SALES | W11: UNITS
B13: 46012 | C13: Dielon - AquaTru - Highly Recommended | G13: =E13/F13 -> #DIV/0! | H13: =D13/E13 -> #DIV/0! | I13: =H13/G13 -> #DIV/0! | J13: 2974.57 | K13: 115078 | M13: 10437.51 | N13: =J13/M13 -> 0.28498847 | O13: =M13/J13 -> 3.5089139 | P13: =J13/D13 -> #DIV/0! | Q13: =M13/D13 -> #DIV/0! | R13: =D13-M13 -> -10437.51 | S13: =J13/L13 -> #DIV/0!
C14: Dielon - Ideal Prostate - Highly Recommended | G14: =E14/F14 -> #DIV/0! | H14: =D14/E14 -> #DIV/0! | I14: =H14/G14 -> #DIV/0! | J14: 145.64 | K14: 19906 | M14: 319.75 | N14: =J14/M14 -> 0.45548084 | O14: =M14/J14 -> 2.195482 | P14: =J14/D14 -> #DIV/0! | Q14: =M14/D14 -> #DIV/0! | R14: =D14-M14 -> -319.75 | S14: =J14/L14 -> #DIV/0!
C15: Dielon - Prosvent - Highly Recommended | G15: =E15/F15 -> #DIV/0! | H15: =D15/E15 -> #DIV/0! | I15: =H15/G15 -> #DIV/0! | J15: 161.15 | K15: 19653 | M15: 993.57 | N15: =(J15/M15) -> 0.1621929 | O15: =M15/J15 -> 6.165498 | P15: =J15/D15 -> #DIV/0! | Q15: =M15/D15 -> #DIV/0! | R15: =D15-M15 -> -993.57 | S15: =J15/L15 -> #DIV/0!
C16: Dielon - Better Bladder - Highly Recommended | G16: =E16/F16 -> #DIV/0! | H16: =D16/E16 -> #DIV/0! | I16: =H16/G16 -> #DIV/0! | J16: 195.37 | K16: 28885 | M16: 359.7 | N16: =J16/M16 -> 0.54314707 | O16: =M16/J16 -> 1.841122 | P16: =J16/D16 -> #DIV/0! | Q16: =M16/D16 -> #DIV/0! | R16: =D16-M16 -> -359.7 | S16: =J16/L16 -> #DIV/0!
C17: Dielon - Rotorazer - Highly Recommended | G17: =E17/F17 -> #DIV/0! | H17: =D17/E17 -> #DIV/0! | I17: =H17/G17 -> #DIV/0! | J17: 11.15 | K17: 1607 | M17: 0 | N17: =J17/M17 -> #DIV/0! | O17: =M17/J17 -> 0 | P17: =J17/D17 -> #DIV/0! | Q17: =M17/D17 -> #DIV/0! | R17: =D17-M17 -> 0 | S17: =J17/L17 -> #DIV/0!
C18: Dielon - Superthotics - Highly Recommended | G18: =E18/F18 -> #DIV/0! | H18: =D18/E18 -> #DIV/0! | I18: =H18/G18 -> #DIV/0! | J18: 215.11 | K18: 27058 | M18: 22.48 | N18: =J18/M18 -> 9.5689502 | O18: =M18/J18 -> 0.10450467 | P18: =J18/D18 -> #DIV/0! | Q18: =M18/D18 -> #DIV/0! | R18: =D18-M18 -> -22.48 | S18: =J18/L18 -> #DIV/0!
C19: Dielon - AirDoctor Filter - Highly Recommended | G19: =E19/F19 -> #DIV/0! | H19: =D19/E19 -> #DIV/0! | I19: =H19/G19 -> #DIV/0! | J19: 452.36 | K19: 16814 | M19: 1418.79 | N19: =J19/M19 -> 0.31883506 | O19: =M19/J19 -> 3.1364179 | P19: =J19/D19 -> #DIV/0! | Q19: =M19/D19 -> #DIV/0! | R19: =D19-M19 -> -1418.79 | S19: =J19/L19 -> #DIV/0!
B20: to | C20: Dielon - AquaTru Filters- Highly Recommended | G20: =E20/F20 -> #DIV/0! | H20: =D20/E20 -> #DIV/0! | I20: =H20/G20 -> #DIV/0! | J20: 147.77 | K20: 6193 | M20: 217.13 | N20: =J20/M20 -> 0.68056003 | O20: =M20/J20 -> 1.4693781 | P20: =J20/D20 -> #DIV/0! | Q20: =M20/D20 -> #DIV/0! | R20: =D20-M20 -> -217.13 | S20: =J20/L20 -> #DIV/0!
C21: Dielon - AirDoctor Main - Highly Recommended | G21: =E21/F21 -> #DIV/0! | H21: =D21/E21 -> #DIV/0! | I21: =H21/G21 -> #DIV/0! | J21: 1782.88 | K21: 165168 | M21: 1677.74 | N21: =J21/M21 -> 1.0626676 | O21: =M21/J21 -> 0.941028 | P21: =J21/D21 -> #DIV/0! | Q21: =M21/D21 -> #DIV/0! | R21: =D21-M21 -> -1677.74 | S21: =J21/L21 -> #DIV/0!
C22: Dielon - Walkfit Platinum - Highly Recommended | G22: =E22/F22 -> #DIV/0! | H22: =D22/E22 -> #DIV/0! | I22: =H22/G22 -> #DIV/0! | J22: 128.2 | K22: 23119 | M22: 427.86 | N22: =J22/M22 -> 0.29963072 | O22: =M22/J22 -> 3.3374415 | P22: =J22/D22 -> #DIV/0! | Q22: =M22/D22 -> #DIV/0! | R22: =D22-M22 -> -427.86 | S22: =J22/L22 -> #DIV/0!
C23: Dielon - Ionic Pro - Highly Suggested | J23: 440.24 | K23: 41970 | M23: 3015.09 | N23: =J23/M23 -> 0.14601223 | O23: =M23/J23 -> 6.8487416 | P23: =J23/D23 -> #DIV/0! | Q23: =M23/D23 -> #DIV/0! | R23: =D23-M23 -> -3015.09 | S23: =J23/L23 -> #DIV/0!
A24: =iferror(if(B24>0,month(B24)&"-"&year(B24),B24),) -> 12-2025 | B24: 46018 | C24: Dielon - Grown American - Highly Recommended | G24: =E24/F24 -> #DIV/0! | H24: =D24/E24 -> #DIV/0! | I24: =H24/G24 -> #DIV/0! | J24: 0 | K24: 0 | M24: 0 | N24: =J24/M24 -> #DIV/0! | O24: =M24/J24 -> #DIV/0! | P24: =J24/D24 -> #DIV/0! | Q24: =M24/D24 -> #DIV/0! | R24: =D24-M24 -> 0 | S24: =J24/L24 -> #DIV/0!
A25: =iferror(if(B25>0,month(B25)&"-"&year(B25),B25),) | B25: 2025 - Week 52 | D25: =SUM(D13:D24) -> 0 | E25: =SUM(E13:E24) -> 0 | F25: =SUM(F13:F24) -> 0 | G25: =E25/F25 -> #DIV/0! | H25: =D25/E25 -> #DIV/0! | I25: =H25/G25 -> #DIV/0! | J25: =SUM(J13:J24) -> 6654.44 | K25: =SUM(K13:K24) -> 465451 | L25: =SUM(L13:L24) -> 0 | M25: =SUM(M13:M24) -> 18889.62 | N25: =J25/M25 -> 0.35228025 | O25: =M25/J25 -> 2.8386491 | P25: =J25/D25 -> #DIV/0! | Q25: =M25/D25 -> #DIV/0! | R25: =SUM(R13:R24) -> -18889.62 | S25: =J25/L25 -> #DIV/0! | T25: =IFERROR((D25-#REF!)/D25,) | U25: =IFERROR((E25-#REF!)/E25,) | V25: =IFERROR((D25-#REF!)/D25, ) | W25: =IFERROR((E25-#REF!)/E25, )
B26: 46019 | C26: Dielon - AquaTru - Highly Recommended | G26: =E26/F26 -> #DIV/0! | H26: =D26/E26 -> #DIV/0! | I26: =H26/G26 -> #DIV/0! | J26: 1881.73 | K26: 105735 | M26: 7796.98 | N26: =J26/M26 -> 0.24134088 | O26: =M26/J26 -> 4.1435169 | P26: =J26/D26 -> #DIV/0! | Q26: =M26/D26 -> #DIV/0! | R26: =D26-M26 -> -7796.98 | S26: =J26/L26 -> #DIV/0!
C27: Dielon - Ideal Prostate - Highly Recommended | G27: =E27/F27 -> #DIV/0! | H27: =D27/E27 -> #DIV/0! | I27: =H27/G27 -> #DIV/0! | J27: 121.46 | K27: 15074 | M27: 509.6 | N27: =J27/M27 -> 0.2383438 | O27: =M27/J27 -> 4.19562 | P27: =J27/D27 -> #DIV/0! | Q27: =M27/D27 -> #DIV/0! | R27: =D27-M27 -> -509.6 | S27: =J27/L27 -> #DIV/0!
C28: Dielon - Prosvent - Highly Recommended | G28: =E28/F28 -> #DIV/0! | H28: =D28/E28 -> #DIV/0! | I28: =H28/G28 -> #DIV/0! | J28: 424.73 | K28: 66686 | M28: 1592.61 | N28: =(J28/M28) -> 0.26668802 | O28: =M28/J28 -> 3.7496998 | P28: =J28/D28 -> #DIV/0! | Q28: =M28/D28 -> #DIV/0! | R28: =D28-M28 -> -1592.61 | S28: =J28/L28 -> #DIV/0!
C29: Dielon - Better Bladder - Highly Recommended | G29: =E29/F29 -> #DIV/0! | H29: =D29/E29 -> #DIV/0! | I29: =H29/G29 -> #DIV/0! | J29: 78.85 | K29: 48745 | M29: 182.85 | N29: =J29/M29 -> 0.43122778 | O29: =M29/J29 -> 2.3189601 | P29: =J29/D29 -> #DIV/0! | Q29: =M29/D29 -> #DIV/0! | R29: =D29-M29 -> -182.85 | S29: =J29/L29 -> #DIV/0!
C30: Dielon - Rotorazer - Highly Recommended | G30: =E30/F30 -> #DIV/0! | H30: =D30/E30 -> #DIV/0! | I30: =H30/G30 -> #DIV/0! | J30: 228.46 | K30: 24816 | M30: 959.68 | N30: =J30/M30 -> 0.23805852 | O30: =M30/J30 -> 4.2006478 | P30: =J30/D30 -> #DIV/0! | Q30: =M30/D30 -> #DIV/0! | R30: =D30-M30 -> -959.68 | S30: =J30/L30 -> #DIV/0!
C31: Dielon - Superthotics - Highly Recommended | G31: =E31/F31 -> #DIV/0! | H31: =D31/E31 -> #DIV/0! | I31: =H31/G31 -> #DIV/0! | J31: 33.91 | K31: 21585 | M31: 22.48 | N31: =J31/M31 -> 1.508452 | O31: =M31/J31 -> 0.66293129 | P31: =J31/D31 -> #DIV/0! | Q31: =M31/D31 -> #DIV/0! | R31: =D31-M31 -> -22.48 | S31: =J31/L31 -> #DIV/0!
C32: Dielon - AirDoctor Filter - Highly Recommended | G32: =E32/F32 -> #DIV/0! | H32: =D32/E32 -> #DIV/0! | I32: =H32/G32 -> #DIV/0! | J32: 651.49 | K32: 29812 | M32: 3259.38 | N32: =J32/M32 -> 0.19988157 | O32: =M32/J32 -> 5.0029624 | P32: =J32/D32 -> #DIV/0! | Q32: =M32/D32 -> #DIV/0! | R32: =D32-M32 -> -3259.38 | S32: =J32/L32 -> #DIV/0!
B33: to | C33: Dielon - AquaTru Filters- Highly Recommended | G33: =E33/F33 -> #DIV/0! | H33: =D33/E33 -> #DIV/0! | I33: =H33/G33 -> #DIV/0! | J33: 29.45 | K33: 10095 | M33: 717.79 | N33: =J33/M33 -> 0.041028713 | O33: =M33/J33 -> 24.373175 | P33: =J33/D33 -> #DIV/0! | Q33: =M33/D33 -> #DIV/0! | R33: =D33-M33 -> -717.79 | S33: =J33/L33 -> #DIV/0!
C34: Dielon - AirDoctor Main - Highly Recommended | G34: =E34/F34 -> #DIV/0! | H34: =D34/E34 -> #DIV/0! | I34: =H34/G34 -> #DIV/0! | J34: 888.27 | K34: 108458 | M34: 662.4 | N34: =J34/M34 -> 1.3409873 | O34: =M34/J34 -> 0.74571921 | P34: =J34/D34 -> #DIV/0! | Q34: =M34/D34 -> #DIV/0! | R34: =D34-M34 -> -662.4 | S34: =J34/L34 -> #DIV/0!
C35: Dielon - Walkfit Platinum - Highly Recommended | G35: =E35/F35 -> #DIV/0! | H35: =D35/E35 -> #DIV/0! | I35: =H35/G35 -> #DIV/0! | J35: 115.71 | K35: 20775 | M35: 404.63 | N35: =J35/M35 -> 0.28596496 | O35: =M35/J35 -> 3.496932 | P35: =J35/D35 -> #DIV/0! | Q35: =M35/D35 -> #DIV/0! | R35: =D35-M35 -> -404.63 | S35: =J35/L35 -> #DIV/0!
C36: Dielon - Ionic Pro - Highly Suggested | J36: 425.83 | K36: 55401 | M36: 2105.6 | N36: =J36/M36 -> 0.20223689 | O36: =M36/J36 -> 4.9446962 | P36: =J36/D36 -> #DIV/0! | Q36: =M36/D36 -> #DIV/0! | R36: =D36-M36 -> -2105.6 | S36: =J36/L36 -> #DIV/0!
A37: =iferror(if(B37>0,month(B37)&"-"&year(B37),B37),) -> 1-2026 | B37: 46025 | C37: Dielon - Grown American - Highly Recommended | G37: =E37/F37 -> #DIV/0! | H37: =D37/E37 -> #DIV/0! | I37: =H37/G37 -> #DIV/0! | J37: 0 | K37: 0 | M37: 0 | N37: =J37/M37 -> #DIV/0! | O37: =M37/J37 -> #DIV/0! | P37: =J37/D37 -> #DIV/0! | Q37: =M37/D37 -> #DIV/0! | R37: =D37-M37 -> 0 | S37: =J37/L37 -> #DIV/0!
A38: =iferror(if(B38>0,month(B38)&"-"&year(B38),B38),) | B38: 2026 - Week 1 | D38: =SUM(D26:D37) -> 0 | E38: =SUM(E26:E37) -> 0 | F38: =SUM(F26:F37) -> 0 | G38: =E38/F38 -> #DIV/0! | H38: =D38/E38 -> #DIV/0! | I38: =H38/G38 -> #DIV/0! | J38: =SUM(J26:J37) -> 4879.89 | K38: =SUM(K26:K37) -> 507182 | L38: =SUM(L26:L37) -> 0 | M38: =SUM(M26:M37) -> 18214 | N38: =J38/M38 -> 0.26791973 | O38: =M38/J38 -> 3.7324612 | P38: =J38/D38 -> #DIV/0! | Q38: =M38/D38 -> #DIV/0! | R38: =SUM(R26:R37) -> -18214 | S38: =J38/L38 -> #DIV/0! | T38: =IFERROR((D38-#REF!)/D38,) | U38: =IFERROR((E38-#REF!)/E38,) | V38: =IFERROR((D38-#REF!)/D38, ) | W38: =IFERROR((E38-#REF!)/E38, )
B39: 46026 | C39: Dielon - AquaTru - Highly Recommended | G39: =E39/F39 -> #DIV/0! | H39: =D39/E39 -> #DIV/0! | I39: =H39/G39 -> #DIV/0! | J39: 924.26 | K39: 92918 | M39: 2364.44 | N39: =J39/M39 -> 0.39090017 | O39: =M39/J39 -> 2.5581979 | P39: =J39/D39 -> #DIV/0! | Q39: =M39/D39 -> #DIV/0! | R39: =D39-M39 -> -2364.44 | S39: =J39/L39 -> #DIV/0!
C40: Dielon - Ideal Prostate - Highly Recommended | G40: =E40/F40 -> #DIV/0! | H40: =D40/E40 -> #DIV/0! | I40: =H40/G40 -> #DIV/0! | J40: 99.21 | K40: 12548 | M40: 289.77 | N40: =J40/M40 -> 0.34237499 | O40: =M40/J40 -> 2.9207741 | P40: =J40/D40 -> #DIV/0! | Q40: =M40/D40 -> #DIV/0! | R40: =D40-M40 -> -289.77 | S40: =J40/L40 -> #DIV/0!
C41: Dielon - Prosvent - Highly Recommended | G41: =E41/F41 -> #DIV/0! | H41: =D41/E41 -> #DIV/0! | I41: =H41/G41 -> #DIV/0! | J41: 408.49 | K41: 66262 | M41: 1174.35 | N41: =(J41/M41) -> 0.34784349 | O41: =M41/J41 -> 2.8748562 | P41: =J41/D41 -> #DIV/0! | Q41: =M41/D41 -> #DIV/0! | R41: =D41-M41 -> -1174.35 | S41: =J41/L41 -> #DIV/0!
C42: Dielon - Better Bladder - Highly Recommended | G42: =E42/F42 -> #DIV/0! | H42: =D42/E42 -> #DIV/0! | I42: =H42/G42 -> #DIV/0! | J42: 199.42 | K42: 37771 | M42: 341.73 | N42: =J42/M42 -> 0.58356012 | O42: =M42/J42 -> 1.7136195 | P42: =J42/D42 -> #DIV/0! | Q42: =M42/D42 -> #DIV/0! | R42: =D42-M42 -> -341.73 | S42: =J42/L42 -> #DIV/0!
...

Sheet WALMART_weekly_reporting_2025-B
A1: WALMART - DATA SOURCES: https://seller.walmart.com/analytics/overview/item-sale; https://seller.walmart.com/analytics/reports; And Intentwise
C2: WEEKLY PERFORMANCE | Y2: =(#REF!+#REF!+#REF!+#REF!)-(monthly_reporting_2021!E17+monthly_reporting_2021!E23+monthly_reporting_2021!E29+monthly_reporting_2021!E35) -> #REF! | Z2: =((#REF!+#REF!+#REF!+#REF!)-(monthly_reporting_2021!F17+monthly_reporting_2021!F23+monthly_reporting_2021!F29+monthly_reporting_2021!F35))/(#REF!+#REF!+#REF!+#REF!) -> #REF!
C3: Total Sales | G3: Total Orders | L3: Total Units Sold
C4: =VLOOKUP("Current Week",$B$11:$Y$982,match("SALES",$B$11:$Y$11,0),FALSE) -> 45850.88 | G4: =VLOOKUP("Current Week",$B$11:$Y$982,match("Units Sold",$B$11:$Y$11,0),FALSE) -> 342 | L4: =VLOOKUP("Current Week",$B$11:$Y$982,match("Ordered Items",$B$11:$Y$11,0),FALSE) -> 362
C5: =(C4-(VLOOKUP("Previous Week",$B$11:$Y$987,match("SALES",$B$11:$Y$11,0),FALSE)))/C4 -> 0.19141552 | G5: =(G4-(VLOOKUP("Previous Week",$B$11:$Y$987,match("Units Sold",$B$11:$Y$11,0),FALSE)))/G4 -> 0.28362573 | L5: =(L4-(VLOOKUP("Previous Week",$B$11:$Y$987,match("Ordered Items",$B$11:$Y$11,0),FALSE)))/L4 -> 0.26519337
C7: Advertising Sales | G7: Advertising Spend | L7: ACoS
C8: =VLOOKUP("Current Week",$B$11:$Y$982,match("AD SALES",$B$11:$Y$11,0),FALSE) -> 14363.4 | G8: =VLOOKUP("Current Week",$B$11:$Y$982,match("SP AD SPEND",$B$11:$Y$11,0),FALSE) -> 5806.71 | L8: =G8/C8 -> 0.40427127
C9: =(C8-(VLOOKUP("Previous Week",$B$11:$Y$987,match("AD SALES",$B$11:$Y$11,0),FALSE)))/C8 -> -0.08545052 | G9: =(G8-(VLOOKUP("Previous Week",$B$11:$Y$987,match("SP AD SPEND",$B$11:$Y$11,0),FALSE)))/G8 -> 0.12260127 | L9: =(L8-(VLOOKUP("Previous Week",$B$11:$Y$987,match("ACOS",$B$11:$Y$11,0),FALSE)))/L8 -> 0.19167321
D10: SALES METRICS | M10: ADVERTISING PERFORMANCE | W10: MoM | Y10: YoY
A11: Month-Code | B11: DATE | C11: BRAND | D11: SALES | E11: Average Sales Price by Brand | F11: UNITS SOLD | G11: ORDERED ITEMS | H11: UNITS PER ORDER | I11: SALES PER ORDER | J11: ASP | K11: SP AD SPEND | L11: IMPRESSIONS | M11: UNIT SALES | N11: AD SALES | O11: ACoS | P11: ROAS (return on ad send) | Q11: TACoS (Total Advertsing Cost of Sales) | R11: REVENUE PERCENTAGE OF AD SALES | S11: ORGANIC SALES | T11: CPO | U11: SALES | V11: UNITS | W11: SALES | X11: UNITS
B13: 45641 | C13: AirDoctor | D13: 10331.1 | F13: 29 | G13: 30 | H13: =F13/G13 -> 0.96666667 | I13: =D13/F13 -> 356.24483 | J13: =I13/H13 -> 368.52913 | K13: 93.48 | L13: 23980 | M13: 12 | N13: 2862.3 | O13: =K13/N13 -> 0.03265905 | P13: =N13/K13 -> 30.619384 | Q13: =K13/D13 -> 0.0090484072 | R13: =N13/D13 -> 0.27705665 | S13: =D13-N13 -> 7468.8 | T13: =K13/M13 -> 7.79
C14: AquaTru | D14: 8314.03 | F14: 39 | G14: 46 | H14: =F14/G14 -> 0.84782609 | I14: =D14/F14 -> 213.18026 | J14: =I14/H14 -> 251.44338 | K14: 174.95 | L14: 16451 | M14: 5 | N14: 654.9 | O14: =K14/N14 -> 0.26714002 | P14: =N14/K14 -> 3.7433552 | Q14: =K14/D14 -> 0.021042743 | R14: =N14/D14 -> 0.078770464 | S14: =D14-N14 -> 7659.13 | T14: =K14/M14 -> 34.99
C15: Beflexible | D15: 0 | F15: 0 | G15: 0 | H15: =F15/G15 -> #DIV/0! | I15: =D15/F15 -> #DIV/0! | J15: =I15/H15 -> #DIV/0! | K15: 0 | L15: 0 | M15: 0 | N15: 0 | O15: =K15/N15 -> #DIV/0! | P15: =N15/K15 -> #DIV/0! | Q15: =K15/D15 -> #DIV/0! | R15: =N15/D15 -> #DIV/0! | S15: =D15-N15 -> 0 | T15: =K15/M15 -> #DIV/0!
C16: Better Bladder | D16: 59.95 | F16: 1 | G16: 1 | H16: =F16/G16 -> 1 | I16: =D16/F16 -> 59.95 | J16: =I16/H16 -> 59.95 | K16: 58.66 | L16: 3967 | M16: 1 | N16: 59.95 | O16: =K16/N16 -> 0.97848207 | P16: =N16/K16 -> 1.0219911 | Q16: =K16/D16 -> 0.97848207 | R16: =N16/D16 -> 1 | S16: =D16-N16 -> 0 | T16: =K16/M16 -> 58.66
C17: Cebria | D17: 0 | F17: 0 | G17: 0 | H17: =F17/G17 -> #DIV/0! | I17: =D17/F17 -> #DIV/0! | J17: =I17/H17 -> #DIV/0! | K17: 0 | L17: 0 | M17: 0 | N17: 0 | O17: =K17/N17 -> #DIV/0! | P17: =N17/K17 -> #DIV/0! | Q17: =K17/D17 -> #DIV/0! | R17: =N17/D17 -> #DIV/0! | S17: =D17-N17 -> 0 | T17: =K17/M17 -> #DIV/0!
C18: GA Grown American | D18: 239.96 | F18: 4 | G18: 4 | H18: =F18/G18 -> 1 | I18: =D18/F18 -> 59.99 | J18: =I18/H18 -> 59.99 | K18: 41.79 | L18: 11511 | M18: 1 | N18: 59.99 | O18: =K18/N18 -> 0.6966161 | P18: =N18/K18 -> 1.4355109 | Q18: =K18/D18 -> 0.17415403 | R18: =N18/D18 -> 0.25 | S18: =D18-N18 -> 179.97 | T18: =K18/M18 -> 41.79
C19: Ideal Prostate | D19: 689.73 | F19: 11 | G19: 10 | H19: =F19/G19 -> 1.1 | I19: =D19/F19 -> 62.702727 | J19: =I19/H19 -> 57.002479 | K19: 160.43 | L19: 4358 | M19: 4 | N19: 279.8 | O19: =K19/N19 -> 0.57337384 | P19: =N19/K19 -> 1.7440628 | Q19: =K19/D19 -> 0.23259826 | R19: =N19/D19 -> 0.40566599 | S19: =D19-N19 -> 409.93 | T19: =K19/M19 -> 40.1075
B20: to | C20: Miracle Blade | D20: 162.73 | F20: 4 | G20: 7 | H20: =F20/G20 -> 0.57142857 | I20: =D20/F20 -> 40.6825 | J20: =I20/H20 -> 71.194375 | K20: 159.89 | L20: 17913 | M20: 0 | N20: 0 | O20: =K20/N20 -> #DIV/0! | P20: =N20/K20 -> 0 | Q20: =K20/D20 -> 0.98254778 | R20: =N20/D20 -> 0 | S20: =D20-N20 -> 162.73 | T20: =K20/M20 -> #DIV/0!
C21: Paint Zoom | D21: -4.96 | F21: -1 | G21: 1 | H21: =F21/G21 -> -1 | I21: =D21/F21 -> 4.96 | J21: =I21/H21 -> -4.96 | K21: 79.62 | L21: 182108 | M21: 1 | N21: 84.96 | O21: =K21/N21 -> 0.93714689 | P21: =N21/K21 -> 1.0670686 | Q21: =K21/D21 -> -16.052419 | R21: =N21/D21 -> -17.129032 | S21: =D21-N21 -> -89.92 | T21: =K21/M21 -> 79.62
C22: Profemin | D22: 274.75 | F22: 5 | G22: 4 | H22: =F22/G22 -> 1.25 | I22: =D22/F22 -> 54.95 | J22: =I22/H22 -> 43.96 | K22: 0 | L22: 0 | M22: 0 | N22: 0 | O22: =K22/N22 -> #DIV/0! | P22: =N22/K22 -> #DIV/0! | Q22: =K22/D22 -> 0 | R22: =N22/D22 -> 0 | S22: =D22-N22 -> 274.75 | T22: =K22/M22 -> #DIV/0!
C23: Prosvent | D23: 2437.8 | F23: 29 | G23: 24 | H23: =F23/G23 -> 1.2083333 | I23: =D23/F23 -> 84.062069 | J23: =I23/H23 -> 69.568609 | K23: 63.47 | L23: 12313 | M23: 6 | N23: 579.7 | O23: =K23/N23 -> 0.10948767 | P23: =N23/K23 -> 9.1334489 | Q23: =K23/D23 -> 0.02603577 | R23: =N23/D23 -> 0.23779637 | S23: =D23-N23 -> 1858.1 | T23: =K23/M23 -> 10.578333
C24: SaniTru | D24: 67.96 | F24: 1 | G24: 1 | H24: =F24/G24 -> 1 | I24: =D24/F24 -> 67.96 | J24: =I24/H24 -> 67.96 | K24: 2.14 | L24: 10943 | M24: 0 | N24: 0 | O24: =K24/N24 -> #DIV/0! | P24: =N24/K24 -> 0 | Q24: =K24/D24 -> 0.031489111 | R24: =N24/D24 -> 0 | S24: =D24-N24 -> 67.96 | T24: =K24/M24 -> #DIV/0!
C25: Rotorazer Saw | D25: -139.37 | F25: 0 | G25: 3 | H25: =F25/G25 -> 0 | I25: =D25/F25 -> #DIV/0! | J25: =I25/H25 -> #DIV/0! | K25: 21.79 | L25: 21569 | M25: 0 | N25: 0 | O25: =K25/N25 -> #DIV/0! | P25: =N25/K25 -> 0 | Q25: =K25/D25 -> -0.15634642 | R25: =N25/D25 -> 0 | S25: =D25-N25 -> -139.37 | T25: =K25/M25 -> #DIV/0!
C26: Superthotics | D26: 0 | F26: 0 | G26: 0 | H26: =F26/G26 -> #DIV/0! | I26: =D26/F26 -> #DIV/0! | J26: =I26/H26 -> #DIV/0! | K26: 3.1 | L26: 1684 | M26: 0 | N26: 0 | O26: =K26/N26 -> #DIV/0! | P26: =N26/K26 -> 0 | Q26: =K26/D26 -> #DIV/0! | R26: =N26/D26 -> #DIV/0! | S26: =D26-N26 -> 0 | T26: =K26/M26 -> #DIV/0!
C27: Therabotanics | D27: 0 | F27: 0 | G27: 0 | H27: =F27/G27 -> #DIV/0! | I27: =D27/F27 -> #DIV/0! | J27: =I27/H27 -> #DIV/0! | K27: 0 | L27: 0 | M27: 0 | N27: 0 | O27: =K27/N27 -> #DIV/0! | P27: =N27/K27 -> #DIV/0! | Q27: =K27/D27 -> #DIV/0! | R27: =N27/D27 -> #DIV/0! | S27: =D27-N27 -> 0 | T27: =K27/M27 -> #DIV/0!
C28: WALKFIT | D28: 900.09 | F28: 28 | G28: 26 | H28: =F28/G28 -> 1.0769231 | I28: =D28/F28 -> 32.146071 | J28: =I28/H28 -> 29.849923 | K28: 164.56 | L28: 45377 | M28: 18 | N28: 474.72 | O28: =K28/N28 -> 0.34664644 | P28: =N28/K28 -> 2.8847837 | Q28: =K28/D28 -> 0.18282616 | R28: =N28/D28 -> 0.52741393 | S28: =D28-N28 -> 425.37 | T28: =K28/M28 -> 9.1422222
A29: =iferror(if(B29>0,month(B29)&"-"&year(B29),B29),) -> 12-2024 | B29: 45647 | C29: AromaTru | D29: 9.8 | F29: 0 | G29: 1 | H29: =F29/G29 -> 0 | I29: =D29/F29 -> #DIV/0! | J29: =I29/H29 -> #DIV/0! | K29: 0 | L29: 12458 | M29: 0 | N29: 0 | O29: =K29/N29 -> #DIV/0! | P29: =N29/K29 -> #DIV/0! | Q29: =K29/D29 -> 0 | R29: =N29/D29 -> 0 | S29: =D29-N29 -> 9.8 | T29: =K29/M29 -> #DIV/0!
A30: =iferror(if(B30>0,month(B30)&"-"&year(B30),B30),) | B30: 2024 - Week 51 | D30: =SUM(D13:D29) -> 23343.57 | F30: =SUM(F13:F29) -> 150 | G30: =SUM(G13:G29) -> 158 | H30: =F30/G30 -> 0.94936709 | I30: =D30/F30 -> 155.6238 | J30: =I30/H30 -> 163.92374 | K30: =SUM(K13:K29) -> 1023.88 | L30: =SUM(L13:L29) -> 364632 | M30: =SUM(M13:M29) -> 48 | N30: =SUM(N13:N29) -> 5056.32 | O30: =K30/N30 -> 0.2024951 | P30: =N30/K30 -> 4.9383912 | Q30: =K30/D30 -> 0.043861329 | R30: =N30/D30 -> 0.2166044 | S30: =SUM(S13:S29) -> 18287.25 | T30: =K30/M30 -> 21.330833 | U30: =IFERROR((D30-#REF!)/D30,) | V30: =IFERROR((F30-#REF!)/F30,) | W30: =IFERROR((D30-monthly_reporting_2021!E49)/D30, ) | X30: =IFERROR((F30-monthly_reporting_2021!F49)/F30, )
B31: 45648 | C31: AirDoctor | D31: 12504.3 | F31: 32 | G31: 32 | H31: =F31/G31 -> 1 | I31: =D31/F31 -> 390.75937 | J31: =I31/H31 -> 390.75937 | K31: 106.38 | L31: 23406 | M31: 10 | N31: 4010.3 | O31: =K31/N31 -> 0.026526694 | P31: =N31/K31 -> 37.697876 | Q31: =K31/D31 -> 0.0085074734 | R31: =N31/D31 -> 0.32071367 | S31: =D31-N31 -> 8494 | T31: =K31/M31 -> 10.638
C32: AquaTru | D32: 5241.86 | F32: 31 | G32: 37 | H32: =F32/G32 -> 0.83783784 | I32: =D32/F32 -> 169.09226 | J32: =I32/H32 -> 201.81979 | K32: 104.84 | L32: 18706 | M32: 1 | N32: 79.95 | O32: =K32/N32 -> 1.3113196 | P32: =N32/K32 -> 0.76259061 | Q32: =K32/D32 -> 0.020000534 | R32: =N32/D32 -> 0.01525222 | S32: =D32-N32 -> 5161.91 | T32: =K32/M32 -> 104.84
C33: Beflexible | D33: 139.9 | F33: 2 | G33: 1 | H33: =F33/G33 -> 2 | I33: =D33/F33 -> 69.95 | J33: =I33/H33 -> 34.975 | K33: 0 | L33: 0 | M33: 0 | N33: 0 | O33: =K33/N33 -> #DIV/0! | P33: =N33/K33 -> #DIV/0! | Q33: =K33/D33 -> 0 | R33: =N33/D33 -> 0 | S33: =D33-N33 -> 139.9 | T33: =K33/M33 -> #DIV/0!
C34: Better Bladder | D34: 359.7 | F34: 6 | G34: 5 | H34: =F34/G34 -> 1.2 | I34: =D34/F34 -> 59.95 | J34: =I34/H34 -> 49.958333 | K34: 15.23 | L34: 1618 | M34: 0 | N34: 0 | O34: =K34/N34 -> #DIV/0! | P34: =N34/K34 -> 0 | Q34: =K34/D34 -> 0.04234084 | R34: =N34/D34 -> 0 | S34: =D34-N34 -> 359.7 | T34: =K34/M34 -> #DIV/0!
C35: Cebria | D35: 0 | F35: 0 | G35: 0 | H35: =F35/G35 -> #DIV/0! | I35: =D35/F35 -> #DIV/0! | J35: =I35/H35 -> #DIV/0! | K35: 0 | L35: 0 | M35: 0 | N35: 0 | O35: =K35/N35 -> #DIV/0! | P35: =N35/K35 -> #DIV/0! | Q35: =K35/D35 -> #DIV/0! | R35: =N35/D35 -> #DIV/0! | S35: =D35-N35 -> 0 | T35: =K35/M35 -> #DIV/0!
C36: GA Grown American | D36: 119.98 | F36: 2 | G36: 1 | H36: =F36/G36 -> 2 | I36: =D36/F36 -> 59.99 | J36: =I36/H36 -> 29.995 | K36: 41.55 | L36: 9951 | M36: 0 | N36: 0 | O36: =K36/N36 -> #DIV/0! | P36: =N36/K36 -> 0 | Q36: =K36/D36 -> 0.34630772 | R36: =N36/D36 -> 0 | S36: =D36-N36 -> 119.98 | T36: =K36/M36 -> #DIV/0!
C37: Ideal Prostate | D37: 849.35 | F37: 13 | G37: 8 | H37: =F37/G37 -> 1.625 | I37: =D37/F37 -> 65.334615 | J37: =I37/H37 -> 40.205917 | K37: 151.87 | L37: 3720 | M37: 1 | N37: 69.95 | O37: =K37/N37 -> 2.1711222 | P37: =N37/K37 -> 0.4605913 | Q37: =K37/D37 -> 0.17880732 | R37: =N37/D37 -> 0.082357097 | S37: =D37-N37 -> 779.4 | T37: =K37/M37 -> 151.87
B38: to | C38: Miracle Blade | D38: 765.75 | F38: 11 | G38: 14 | H38: =F38/G38 -> 0.78571429 | I38: =D38/F38 -> 69.613636 | J38: =I38/H38 -> 88.599174 | K38: 243.42 | L38: 28115 | M38: 4 | N38: 150.89 | O38: =K38/N38 -> 1.6132282 | P38: =N38/K38 -> 0.61987511 | Q38: =K38/D38 -> 0.31788443 | R38: =N38/D38 -> 0.19704865 | S38: =D38-N38 -> 614.86 | T38: =K38/M38 -> 60.855
C39: Paint Zoom | D39: 0 | F39: 0 | G39: 0 | H39: =F39/G39 -> #DIV/0! | I39: =D39/F39 -> #DIV/0! | J39: =I39/H39 -> #DIV/0! | K39: 53.92 | L39: 167085 | M39: 0 | N39: 0 | O39: =K39/N39 -> #DIV/0! | P39: =N39/K39 -> 0 | Q39: =K39/D39 -> #DIV/0! | R39: =N39/D39 -> #DIV/0! | S39: =D39-N39 -> 0 | T39: =K39/M39 -> #DIV/0!
C40: Profemin | D40: 0 | F40: 0 | G40: 1 | H40: =F40/G40 -> 0 | I40: =D40/F40 -> #DIV/0! | J40: =I40/H40 -> #DIV/0! | K40: 0 | L40: 0 | M40: 0 | N40: 0 | O40: =K40/N40 -> #DIV/0! | P40: =N40/K40 -> #DIV/0! | Q40: =K40/D40 -> #DIV/0! | R40: =N40/D40 -> #DIV/0! | S40: =D40-N40 -> 0 | T40: =K40/M40 -> #DIV/0!
C41: Prosvent | D41: 766.15 | F41: 15 | G41: 14 | H41: =F41/G41 -> 1.0714286 | I41: =D41/F41 -> 51.076667 | J41: =I41/H41 -> 47.671556 | K41: 56.99 | L41: 12059 | M41: 1 | N41: 67 | O41: =K41/N41 -> 0.85059701 | P41: =N41/K41 -> 1.1756449 | Q41: =K41/D41 -> 0.074384912 | R41: =N41/D41 -> 0.087450238 | S41: =D41-N41 -> 699.15 | T41: =K41/M41 -> 56.99
C42: SaniTru | D42: -10.91 | F42: 1 | G42: 1 | H42: =F42/G42 -> 1 | I42: =D42/F42 -> -10.91 | J42: =I42/H42 -> -10.91 | K42: 8.58 | L42: 10088 | M42: 1 | N42: 19.99 | O42: =K42/N42 -> 0.42921461 | P42: =N42/K42 -> 2.3298368 | Q42: =K42/D42 -> -0.78643446 | R42: =N42/D42 -> -1.832264 | S42: =D42-N42 -> -30.9 | T42: =K42/M42 -> 8.58
...

Sheet Sheet4
A1: WALMART - DATA SOURCES: https://seller.walmart.com/analytics/overview/item-sale; https://seller.walmart.com/analytics/reports; And Intentwise
C2: WEEKLY PERFORMANCE | X2: =(#REF!+#REF!+#REF!+#REF!)-(monthly_reporting_2021!D17+monthly_reporting_2021!D23+monthly_reporting_2021!D29+monthly_reporting_2021!D35) -> #REF! | Y2: =((#REF!+#REF!+#REF!+#REF!)-(monthly_reporting_2021!E17+monthly_reporting_2021!E23+monthly_reporting_2021!E29+monthly_reporting_2021!E35))/(#REF!+#REF!+#REF!+#REF!) -> #REF!
C3: Total Sales | F3: Total Orders | K3: Total Units Sold
C4: =VLOOKUP("Current Week",$B$11:$X$847,match("SALES",$B$11:$X$11,0),FALSE) -> 45850.88 | F4: =VLOOKUP("Current Week",$B$11:$X$847,match("Units Sold",$B$11:$X$11,0),FALSE) -> 342 | K4: =VLOOKUP("Current Week",$B$11:$X$847,match("Ordered Items",$B$11:$X$11,0),FALSE) -> 362
C5: =(C4-(VLOOKUP("Previous Week",$B$11:$X$852,match("SALES",$B$11:$X$11,0),FALSE)))/C4 -> 0.19141552 | F5: =(F4-(VLOOKUP("Previous Week",$B$11:$X$852,match("Units Sold",$B$11:$X$11,0),FALSE)))/F4 -> 0.28362573 | K5: =(K4-(VLOOKUP("Previous Week",$B$11:$X$852,match("Ordered Items",$B$11:$X$11,0),FALSE)))/K4 -> 0.26519337
C7: Advertising Sales | F7: Advertising Spend | K7: ACoS
C8: =VLOOKUP("Current Week",$B$11:$X$847,match("AD SALES",$B$11:$X$11,0),FALSE) -> 32577.4 | F8: =VLOOKUP("Current Week",$B$11:$X$847,match("SP AD SPEND",$B$11:$X$11,0),FALSE) -> 10686.6 | K8: =F8/C8 -> 0.32803723
C9: =(C8-(VLOOKUP("Previous Week",$B$11:$X$852,match("AD SALES",$B$11:$X$11,0),FALSE)))/C8 -> -0.058414115 | F9: =(F8-(VLOOKUP("Previous Week",$B$11:$X$852,match("SP AD SPEND",$B$11:$X$11,0),FALSE)))/F8 -> -0.099436678 | K9: =(K8-(VLOOKUP("Previous Week",$B$11:$X$852,match("ACOS",$B$11:$X$11,0),FALSE)))/K8 -> -0.038758518
D10: SALES METRICS | L10: ADVERTISING PERFORMANCE | V10: MoM | X10: YoY
A11: Month-Code | B11: DATE | C11: BRAND | D11: SALES | E11: UNITS SOLD | F11: ORDERED ITEMS | G11: UNITS PER ORDER | H11: SALES PER ORDER | I11: ASP | J11: SP AD SPEND | K11: IMPRESSIONS | L11: UNIT SALES | M11: AD SALES | N11: ACoS | O11: ROAS (return on ad send) | P11: TACoS (Total Advertsing Cost of Sales) | Q11: REVENUE PERCENTAGE OF AD SALES | R11: ORGANIC SALES | S11: CPO | T11: SALES | U11: UNITS | V11: SALES | W11: UNITS
B13: 45711 | C13: AirDoctor | D13: 1138.6 | E13: 9 | F13: 10 | G13: =E13/F13 -> 0.9 | H13: =D13/E13 -> 126.51111 | I13: =H13/G13 -> 140.5679 | J13: 652.84 | K13: 91286 | L13: 5 | M13: 289.8 | N13: =J13/M13 -> 2.252726 | O13: =M13/J13 -> 0.44390662 | P13: =J13/D13 -> 0.57337081 | Q13: =M13/D13 -> 0.2545231 | R13: =D13-M13 -> 848.8 | S13: =J13/L13 -> 130.568
C14: AquaTru | D14: 7251.12 | E14: 45 | F14: 47 | G14: =E14/F14 -> 0.95744681 | H14: =D14/E14 -> 161.136 | I14: =H14/G14 -> 168.2976 | J14: 325.06 | K14: 109626 | L14: 10 | M14: 1276.85 | N14: =J14/M14 -> 0.25457963 | O14: =M14/J14 -> 3.9280441 | P14: =J14/D14 -> 0.044828937 | Q14: =M14/D14 -> 0.17609004 | R14: =D14-M14 -> 5974.27 | S14: =J14/L14 -> 32.506
C15: Beflexible | D15: 0 | E15: 0 | F15: 0 | G15: =E15/F15 -> #DIV/0! | H15: =D15/E15 -> #DIV/0! | I15: =H15/G15 -> #DIV/0! | J15: 17.22 | K15: 128 | L15: 0 | M15: 0 | N15: =(J15/M15) -> #DIV/0! | O15: =M15/J15 -> 0 | P15: =J15/D15 -> #DIV/0! | Q15: =M15/D15 -> #DIV/0! | R15: =D15-M15 -> 0 | S15: =J15/L15 -> #DIV/0!
C16: Better Bladder | D16: 269.75 | E16: 5 | F16: 3 | G16: =E16/F16 -> 1.6666667 | H16: =D16/E16 -> 53.95 | I16: =H16/G16 -> 32.37 | J16: 163.92 | K16: 9083 | L16: 0 | M16: 0 | N16: =J16/M16 -> #DIV/0! | O16: =M16/J16 -> 0 | P16: =J16/D16 -> 0.60767377 | Q16: =M16/D16 -> 0 | R16: =D16-M16 -> 269.75 | S16: =J16/L16 -> #DIV/0!
C17: Cebria | D17: 0 | E17: 0 | F17: 0 | G17: =E17/F17 -> #DIV/0! | H17: =D17/E17 -> #DIV/0! | I17: =H17/G17 -> #DIV/0! | J17: 0 | K17: 0 | L17: 0 | M17: 0 | N17: =J17/M17 -> #DIV/0! | O17: =M17/J17 -> #DIV/0! | P17: =J17/D17 -> #DIV/0! | Q17: =M17/D17 -> #DIV/0! | R17: =D17-M17 -> 0 | S17: =J17/L17 -> #DIV/0!
C18: GA Grown American | D18: 455.81 | E18: 7 | F18: 6 | G18: =E18/F18 -> 1.1666667 | H18: =D18/E18 -> 65.115714 | I18: =H18/G18 -> 55.813469 | J18: 49.89 | K18: 6245 | L18: 2 | M18: 124.94 | N18: =J18/M18 -> 0.39931167 | O18: =M18/J18 -> 2.5043095 | P18: =J18/D18 -> 0.1094535 | Q18: =M18/D18 -> 0.27410544 | R18: =D18-M18 -> 330.87 | S18: =J18/L18 -> 24.945
C19: Ideal Prostate | D19: 500.16 | E19: 8 | F19: 8 | G19: =E19/F19 -> 1 | H19: =D19/E19 -> 62.52 | I19: =H19/G19 -> 62.52 | J19: 67.81 | K19: 6402 | L19: 1 | M19: 59.95 | N19: =J19/M19 -> 1.1311093 | O19: =M19/J19 -> 0.88408789 | P19: =J19/D19 -> 0.13557662 | Q19: =M19/D19 -> 0.11986164 | R19: =D19-M19 -> 440.21 | S19: =J19/L19 -> 67.81
B20: to | C20: Miracle Blade | D20: 614.92 | E20: 13 | F20: 12 | G20: =E20/F20 -> 1.0833333 | H20: =D20/E20 -> 47.301538 | I20: =H20/G20 -> 43.662959 | J20: 123.69 | K20: 14424 | L20: 5 | M20: 107.8 | N20: =J20/M20 -> 1.1474026 | O20: =M20/J20 -> 0.87153367 | P20: =J20/D20 -> 0.20114812 | Q20: =M20/D20 -> 0.17530736 | R20: =D20-M20 -> 507.12 | S20: =J20/L20 -> 24.738
C21: Paint Zoom | D21: 0 | E21: 0 | F21: 0 | G21: =E21/F21 -> #DIV/0! | H21: =D21/E21 -> #DIV/0! | I21: =H21/G21 -> #DIV/0! | J21: 61.54 | K21: 58340 | L21: 2 | M21: 199.9 | N21: =J21/M21 -> 0.30785393 | O21: =M21/J21 -> 3.2482938 | P21: =J21/D21 -> #DIV/0! | Q21: =M21/D21 -> #DIV/0! | R21: =D21-M21 -> -199.9 | S21: =J21/L21 -> 30.77
C22: Profemin | D22: 54.95 | E22: 1 | F22: 1 | G22: =E22/F22 -> 1 | H22: =D22/E22 -> 54.95 | I22: =H22/G22 -> 54.95 | J22: 0 | K22: 0 | L22: 0 | M22: 0 | N22: =J22/M22 -> #DIV/0! | O22: =M22/J22 -> #DIV/0! | P22: =J22/D22 -> 0 | Q22: =M22/D22 -> 0 | R22: =D22-M22 -> 54.95 | S22: =J22/L22 -> #DIV/0!
C23: Prosvent | D23: 201 | E23: 3 | F23: 3 | G23: =E23/F23 -> 1 | H23: =D23/E23 -> 67 | I23: =H23/G23 -> 67 | J23: 52.07 | K23: 7101 | L23: 1 | M23: 67 | N23: =J23/M23 -> 0.77716418 | O23: =M23/J23 -> 1.2867294 | P23: =J23/D23 -> 0.25905473 | Q23: =M23/D23 -> 0.33333333 | R23: =D23-M23 -> 134 | S23: =J23/L23 -> 52.07
C24: SaniTru | D24: 39.98 | E24: 2 | F24: 2 | G24: =E24/F24 -> 1 | H24: =D24/E24 -> 19.99 | I24: =H24/G24 -> 19.99 | J24: 7.73 | K24: 17629 | L24: 0 | M24: 0 | N24: =J24/M24 -> #DIV/0! | O24: =M24/J24 -> 0 | P24: =J24/D24 -> 0.19334667 | Q24: =M24/D24 -> 0 | R24: =D24-M24 -> 39.98 | S24: =J24/L24 -> #DIV/0!
C25: Rotorazer Saw | D25: -195 | E25: -1 | F25: 0 | G25: =E25/F25 -> #DIV/0! | H25: =D25/E25 -> 195 | I25: =H25/G25 -> #DIV/0! | J25: 27.44 | K25: 30342 | L25: 0 | M25: 0 | N25: =J25/M25 -> #DIV/0! | O25: =M25/J25 -> 0 | P25: =J25/D25 -> -0.14071795 | Q25: =M25/D25 -> 0 | R25: =D25-M25 -> -195 | S25: =J25/L25 -> #DIV/0!
C26: Superthotics | D26: 119.9 | E26: 2 | F26: 2 | G26: =E26/F26 -> 1 | H26: =D26/E26 -> 59.95 | I26: =H26/G26 -> 59.95 | J26: 46.2 | K26: 8233 | L26: 0 | M26: 0 | N26: =J26/M26 -> #DIV/0! | O26: =M26/J26 -> 0 | P26: =J26/D26 -> 0.3853211 | Q26: =M26/D26 -> 0 | R26: =D26-M26 -> 119.9 | S26: =J26/L26 -> #DIV/0!
C27: Therabotanics | D27: 620.91 | E27: 11 | F27: 10 | G27: =E27/F27 -> 1.1 | H27: =D27/E27 -> 56.446364 | I27: =H27/G27 -> 51.314876 | J27: 0 | K27: 0 | L27: 0 | M27: 0 | N27: =J27/M27 -> #DIV/0! | O27: =M27/J27 -> #DIV/0! | P27: =J27/D27 -> 0 | Q27: =M27/D27 -> 0 | R27: =D27-M27 -> 620.91 | S27: =J27/L27 -> #DIV/0!
C28: WALKFIT | D28: 834.27 | E28: 23 | F28: 23 | G28: =E28/F28 -> 1 | H28: =D28/E28 -> 36.272609 | I28: =H28/G28 -> 36.272609 | J28: 88.12 | K28: 33459 | L28: 11 | M28: 395.56 | N28: =J28/M28 -> 0.22277278 | O28: =M28/J28 -> 4.4888788 | P28: =J28/D28 -> 0.10562528 | Q28: =M28/D28 -> 0.47413907 | R28: =D28-M28 -> 438.71 | S28: =J28/L28 -> 8.0109091
C29: AromaTru | D29: 0 | E29: 0 | F29: 0 | G29: =E29/F29 -> #DIV/0! | H29: =D29/E29 -> #DIV/0! | I29: =H29/G29 -> #DIV/0! | J29: 3.31 | K29: 10850 | L29: 0 | M29: 0 | N29: =J29/M29 -> #DIV/0! | O29: =M29/J29 -> 0 | P29: =J29/D29 -> #DIV/0! | Q29: =M29/D29 -> #DIV/0! | R29: =D29-M29 -> 0 | S29: =J29/L29 -> #DIV/0!
A30: =iferror(if(B30>0,month(B30)&"-"&year(B30),B30),) -> 3-2025 | B30: 45717 | C30: SEM Campaigns | D30: 0 | E30: 0 | F30: 0 | G30: =E30/F30 -> #DIV/0! | H30: =D30/E30 -> #DIV/0! | I30: =H30/G30 -> #DIV/0! | J30: 22.48 | K30: 3411 | L30: 0 | M30: 0 | N30: =J30/M30 -> #DIV/0! | O30: =M30/J30 -> 0 | P30: =J30/D30 -> #DIV/0! | Q30: =M30/D30 -> #DIV/0! | R30: =D30-M30 -> 0 | S30: =J30/L30 -> #DIV/0!
