Workbook

Sheet ALL - 2025
A1: Home Depot RPD - Orange Access - DATA SOURCES: https://us.orangeapronmedia.com/r/organizations
C2: WEEKLY PERFORMANCE | X2: =(#REF!+#REF!+#REF!+#REF!)-(monthly_reporting_2021!D17+monthly_reporting_2021!D23+monthly_reporting_2021!D29+monthly_reporting_2021!D35) -> #REF! | Y2: =((#REF!+#REF!+#REF!+#REF!)-(monthly_reporting_2021!E17+monthly_reporting_2021!E23+monthly_reporting_2021!E29+monthly_reporting_2021!E35))/(#REF!+#REF!+#REF!+#REF!) -> #REF!
K3: Total Sales | N3: Total Orders | S3: Total Units Sold
K4: =VLOOKUP("Current Week",$B$11:$X$105,match("SALES",$B$11:$X$11,0),FALSE) -> 0 | N4: =VLOOKUP("Current Week",$B$11:$X$105,match("Units Sold",$B$11:$X$11,0),FALSE) -> 0 | S4: =VLOOKUP("Current Week",$B$11:$X$105,match("Ordered Items",$B$11:$X$11,0),FALSE) -> 0
K5: =(K4-(VLOOKUP("Previous Week",$B$11:$X$110,match("SALES",$B$11:$X$11,0),FALSE)))/K4 -> #DIV/0! | N5: =(N4-(VLOOKUP("Previous Week",$B$11:$X$110,match("Units Sold",$B$11:$X$11,0),FALSE)))/N4 -> #DIV/0! | S5: =(S4-(VLOOKUP("Previous Week",$B$11:$X$110,match("Ordered Items",$B$11:$X$11,0),FALSE)))/S4 -> #DIV/0!
K7: Advertising Sales | N7: Advertising Spend | S7: ACoS
K8: =VLOOKUP("Current Week",$B$11:$X$105,match("AD SALES",$B$11:$X$11,0),FALSE) -> 571 | N8: =VLOOKUP("Current Week",$B$11:$X$105,match("SP AD SPEND",$B$11:$X$11,0),FALSE) -> 593.32 | S8: =N8/K8 -> 1.0390893
K9: =(K8-(VLOOKUP("Previous Week",$B$11:$X$110,match("AD SALES",$B$11:$X$11,0),FALSE)))/K8 -> -0.7793345 | N9: =(N8-(VLOOKUP("Previous Week",$B$11:$X$110,match("SP AD SPEND",$B$11:$X$11,0),FALSE)))/N8 -> 0.12256455 | S9: =(S8-(VLOOKUP("Previous Week",$B$11:$X$110,match("ACOS",$B$11:$X$11,0),FALSE)))/S8 -> 0.50687437
D10: SALES METRICS | L10: ADVERTISING PERFORMANCE | V10: MoM | X10: YoY
A11: Month-Code | B11: DATE | C11: Campaign Group per Brand | D11: SALES | E11: UNITS SOLD | F11: ORDERED ITEMS | G11: UNITS PER ORDER | H11: SALES PER ORDER | I11: ASP | J11: SP AD SPEND | K11: IMPRESSIONS | L11: UNIT SALES | M11: AD SALES | N11: ACoS | O11: ROAS (return on ad send) | P11: TACoS (Total Advertsing Cost of Sales) | Q11: REVENUE PERCENTAGE OF AD SALES | R11: ORGANIC SALES | S11: CPO | T11: SALES | U11: UNITS | V11: SALES | W11: UNITS
B13: 45921 | C13: AIRDOCTOR - Home Depot US | G13: =E13/F13 -> #DIV/0! | H13: =D13/E13 -> #DIV/0! | I13: =H13/G13 -> #DIV/0! | J13: 0 | K13: 0 | L13: 0 | M13: 0 | N13: =J13/M13 -> #DIV/0! | O13: =M13/J13 -> #DIV/0! | P13: =J13/D13 -> #DIV/0! | Q13: =M13/D13 -> #DIV/0! | R13: =D13-M13 -> 0 | S13: =J13/L13 -> #DIV/0!
C14: AQUA TRU - Home Depot US | G14: =E14/F14 -> #DIV/0! | H14: =D14/E14 -> #DIV/0! | I14: =H14/G14 -> #DIV/0! | J14: 0 | K14: 0 | L14: 0 | M14: 0 | N14: =J14/M14 -> #DIV/0! | O14: =M14/J14 -> #DIV/0! | P14: =J14/D14 -> #DIV/0! | Q14: =M14/D14 -> #DIV/0! | R14: =D14-M14 -> 0 | S14: =J14/L14 -> #DIV/0!
B15: to | C15: PAINT ZOOM - Home Depot US | G15: =E15/F15 -> #DIV/0! | H15: =D15/E15 -> #DIV/0! | I15: =H15/G15 -> #DIV/0! | J15: 0 | K15: 0 | L15: 0 | M15: 0 | N15: =(J15/M15) -> #DIV/0! | O15: =M15/J15 -> #DIV/0! | P15: =J15/D15 -> #DIV/0! | Q15: =M15/D15 -> #DIV/0! | R15: =D15-M15 -> 0 | S15: =J15/L15 -> #DIV/0!
A16: =iferror(if(B16>0,month(B16)&"-"&year(B16),B16),) -> 9-2025 | B16: 45927 | C16: ROTORAZER SAW - Home Depot US / ROTORAZERSAW - Home Depot US | G16: =E16/F16 -> #DIV/0! | H16: =D16/E16 -> #DIV/0! | I16: =H16/G16 -> #DIV/0! | J16: 0 | K16: 0 | L16: 0 | M16: 0 | N16: =J16/M16 -> #DIV/0! | O16: =M16/J16 -> #DIV/0! | P16: =J16/D16 -> #DIV/0! | Q16: =M16/D16 -> #DIV/0! | R16: =D16-M16 -> 0 | S16: =J16/L16 -> #DIV/0!
A17: =iferror(if(B17>0,month(B17)&"-"&year(B17),B17),) | B17: Week 39 | D17: =SUM(D13:D16) -> 0 | E17: =SUM(E13:E16) -> 0 | F17: =SUM(F13:F16) -> 0 | G17: =E17/F17 -> #DIV/0! | H17: =D17/E17 -> #DIV/0! | I17: =H17/G17 -> #DIV/0! | J17: =SUM(J13:J16) -> 0 | K17: =SUM(K13:K16) -> 0 | L17: =SUM(L13:L16) -> 0 | M17: =SUM(M13:M16) -> 0 | N17: =J17/M17 -> #DIV/0! | O17: =M17/J17 -> #DIV/0! | P17: =J17/D17 -> #DIV/0! | Q17: =M17/D17 -> #DIV/0! | R17: =SUM(R13:R16) -> 0 | S17: =J17/L17 -> #DIV/0! | T17: =IFERROR((D17-#REF!)/D17,) | U17: =IFERROR((E17-#REF!)/E17,) | V17: =IFERROR((D17-#REF!)/D17, ) | W17: =IFERROR((E17-#REF!)/E17, )
B18: 45928 | C18: AIRDOCTOR - Home Depot US | G18: =E18/F18 -> #DIV/0! | H18: =D18/E18 -> #DIV/0! | I18: =H18/G18 -> #DIV/0! | J18: 0 | K18: 0 | L18: 0 | M18: 0 | N18: =J18/M18 -> #DIV/0! | O18: =M18/J18 -> #DIV/0! | P18: =J18/D18 -> #DIV/0! | Q18: =M18/D18 -> #DIV/0! | R18: =D18-M18 -> 0 | S18: =J18/L18 -> #DIV/0!
C19: AQUA TRU - Home Depot US | G19: =E19/F19 -> #DIV/0! | H19: =D19/E19 -> #DIV/0! | I19: =H19/G19 -> #DIV/0! | J19: 0 | K19: 0 | L19: 0 | M19: 0 | N19: =J19/M19 -> #DIV/0! | O19: =M19/J19 -> #DIV/0! | P19: =J19/D19 -> #DIV/0! | Q19: =M19/D19 -> #DIV/0! | R19: =D19-M19 -> 0 | S19: =J19/L19 -> #DIV/0!
B20: to | C20: PAINT ZOOM - Home Depot US | G20: =E20/F20 -> #DIV/0! | H20: =D20/E20 -> #DIV/0! | I20: =H20/G20 -> #DIV/0! | J20: 0 | K20: 0 | L20: 0 | M20: 0 | N20: =(J20/M20) -> #DIV/0! | O20: =M20/J20 -> #DIV/0! | P20: =J20/D20 -> #DIV/0! | Q20: =M20/D20 -> #DIV/0! | R20: =D20-M20 -> 0 | S20: =J20/L20 -> #DIV/0!
A21: =iferror(if(B21>0,month(B21)&"-"&year(B21),B21),) -> 10-2025 | B21: 45934 | C21: ROTORAZER SAW - Home Depot US / ROTORAZERSAW - Home Depot US | G21: =E21/F21 -> #DIV/0! | H21: =D21/E21 -> #DIV/0! | I21: =H21/G21 -> #DIV/0! | J21: 0 | K21: 0 | L21: 0 | M21: 0 | N21: =J21/M21 -> #DIV/0! | O21: =M21/J21 -> #DIV/0! | P21: =J21/D21 -> #DIV/0! | Q21: =M21/D21 -> #DIV/0! | R21: =D21-M21 -> 0 | S21: =J21/L21 -> #DIV/0!
A22: =iferror(if(B22>0,month(B22)&"-"&year(B22),B22),) | B22: Week 40 | D22: =SUM(D18:D21) -> 0 | E22: =SUM(E18:E21) -> 0 | F22: =SUM(F18:F21) -> 0 | G22: =E22/F22 -> #DIV/0! | H22: =D22/E22 -> #DIV/0! | I22: =H22/G22 -> #DIV/0! | J22: =SUM(J18:J21) -> 0 | K22: =SUM(K18:K21) -> 0 | L22: =SUM(L18:L21) -> 0 | M22: =SUM(M18:M21) -> 0 | N22: =J22/M22 -> #DIV/0! | O22: =M22/J22 -> #DIV/0! | P22: =J22/D22 -> #DIV/0! | Q22: =M22/D22 -> #DIV/0! | R22: =SUM(R18:R21) -> 0 | S22: =J22/L22 -> #DIV/0! | T22: =IFERROR((D22-#REF!)/D22,) | U22: =IFERROR((E22-#REF!)/E22,) | V22: =IFERROR((D22-#REF!)/D22, ) | W22: =IFERROR((E22-#REF!)/E22, )
B23: 45935 | C23: AIRDOCTOR - Home Depot US | G23: =E23/F23 -> #DIV/0! | H23: =D23/E23 -> #DIV/0! | I23: =H23/G23 -> #DIV/0! | J23: 0 | K23: 0 | L23: 0 | M23: 0 | N23: =J23/M23 -> #DIV/0! | O23: =M23/J23 -> #DIV/0! | P23: =J23/D23 -> #DIV/0! | Q23: =M23/D23 -> #DIV/0! | R23: =D23-M23 -> 0 | S23: =J23/L23 -> #DIV/0!
C24: AQUA TRU - Home Depot US | G24: =E24/F24 -> #DIV/0! | H24: =D24/E24 -> #DIV/0! | I24: =H24/G24 -> #DIV/0! | J24: 0 | K24: 0 | L24: 0 | M24: 0 | N24: =J24/M24 -> #DIV/0! | O24: =M24/J24 -> #DIV/0! | P24: =J24/D24 -> #DIV/0! | Q24: =M24/D24 -> #DIV/0! | R24: =D24-M24 -> 0 | S24: =J24/L24 -> #DIV/0!
B25: to | C25: PAINT ZOOM - Home Depot US | G25: =E25/F25 -> #DIV/0! | H25: =D25/E25 -> #DIV/0! | I25: =H25/G25 -> #DIV/0! | J25: 0 | K25: 0 | L25: 0 | M25: 0 | N25: =(J25/M25) -> #DIV/0! | O25: =M25/J25 -> #DIV/0! | P25: =J25/D25 -> #DIV/0! | Q25: =M25/D25 -> #DIV/0! | R25: =D25-M25 -> 0 | S25: =J25/L25 -> #DIV/0!
A26: =iferror(if(B26>0,month(B26)&"-"&year(B26),B26),) -> 10-2025 | B26: 45941 | C26: ROTORAZER SAW - Home Depot US / ROTORAZERSAW - Home Depot US | G26: =E26/F26 -> #DIV/0! | H26: =D26/E26 -> #DIV/0! | I26: =H26/G26 -> #DIV/0! | J26: 0 | K26: 0 | L26: 0 | M26: 0 | N26: =J26/M26 -> #DIV/0! | O26: =M26/J26 -> #DIV/0! | P26: =J26/D26 -> #DIV/0! | Q26: =M26/D26 -> #DIV/0! | R26: =D26-M26 -> 0 | S26: =J26/L26 -> #DIV/0!
A27: =iferror(if(B27>0,month(B27)&"-"&year(B27),B27),) | B27: Week 41 | D27: =SUM(D23:D26) -> 0 | E27: =SUM(E23:E26) -> 0 | F27: =SUM(F23:F26) -> 0 | G27: =E27/F27 -> #DIV/0! | H27: =D27/E27 -> #DIV/0! | I27: =H27/G27 -> #DIV/0! | J27: =SUM(J23:J26) -> 0 | K27: =SUM(K23:K26) -> 0 | L27: =SUM(L23:L26) -> 0 | M27: =SUM(M23:M26) -> 0 | N27: =J27/M27 -> #DIV/0! | O27: =M27/J27 -> #DIV/0! | P27: =J27/D27 -> #DIV/0! | Q27: =M27/D27 -> #DIV/0! | R27: =SUM(R23:R26) -> 0 | S27: =J27/L27 -> #DIV/0! | T27: =IFERROR((D27-#REF!)/D27,) | U27: =IFERROR((E27-#REF!)/E27,) | V27: =IFERROR((D27-#REF!)/D27, ) | W27: =IFERROR((E27-#REF!)/E27, )
B28: 45942 | C28: AIRDOCTOR - Home Depot US | G28: =E28/F28 -> #DIV/0! | H28: =D28/E28 -> #DIV/0! | I28: =H28/G28 -> #DIV/0! | J28: 0 | K28: 0 | L28: 0 | M28: 0 | N28: =J28/M28 -> #DIV/0! | O28: =M28/J28 -> #DIV/0! | P28: =J28/D28 -> #DIV/0! | Q28: =M28/D28 -> #DIV/0! | R28: =D28-M28 -> 0 | S28: =J28/L28 -> #DIV/0!
C29: AQUA TRU - Home Depot US | G29: =E29/F29 -> #DIV/0! | H29: =D29/E29 -> #DIV/0! | I29: =H29/G29 -> #DIV/0! | J29: 0 | K29: 0 | L29: 0 | M29: 0 | N29: =J29/M29 -> #DIV/0! | O29: =M29/J29 -> #DIV/0! | P29: =J29/D29 -> #DIV/0! | Q29: =M29/D29 -> #DIV/0! | R29: =D29-M29 -> 0 | S29: =J29/L29 -> #DIV/0!
B30: to | C30: PAINT ZOOM - Home Depot US | G30: =E30/F30 -> #DIV/0! | H30: =D30/E30 -> #DIV/0! | I30: =H30/G30 -> #DIV/0! | J30: 0 | K30: 0 | L30: 0 | M30: 0 | N30: =(J30/M30) -> #DIV/0! | O30: =M30/J30 -> #DIV/0! | P30: =J30/D30 -> #DIV/0! | Q30: =M30/D30 -> #DIV/0! | R30: =D30-M30 -> 0 | S30: =J30/L30 -> #DIV/0!
A31: =iferror(if(B31>0,month(B31)&"-"&year(B31),B31),) -> 10-2025 | B31: 45948 | C31: ROTORAZER SAW - Home Depot US / ROTORAZERSAW - Home Depot US | G31: =E31/F31 -> #DIV/0! | H31: =D31/E31 -> #DIV/0! | I31: =H31/G31 -> #DIV/0! | J31: 0 | K31: 0 | L31: 0 | M31: 0 | N31: =J31/M31 -> #DIV/0! | O31: =M31/J31 -> #DIV/0! | P31: =J31/D31 -> #DIV/0! | Q31: =M31/D31 -> #DIV/0! | R31: =D31-M31 -> 0 | S31: =J31/L31 -> #DIV/0!
A32: =iferror(if(B32>0,month(B32)&"-"&year(B32),B32),) | B32: Week 42 | D32: =SUM(D28:D31) -> 0 | E32: =SUM(E28:E31) -> 0 | F32: =SUM(F28:F31) -> 0 | G32: =E32/F32 -> #DIV/0! | H32: =D32/E32 -> #DIV/0! | I32: =H32/G32 -> #DIV/0! | J32: =SUM(J28:J31) -> 0 | K32: =SUM(K28:K31) -> 0 | L32: =SUM(L28:L31) -> 0 | M32: =SUM(M28:M31) -> 0 | N32: =J32/M32 -> #DIV/0! | O32: =M32/J32 -> #DIV/0! | P32: =J32/D32 -> #DIV/0! | Q32: =M32/D32 -> #DIV/0! | R32: =SUM(R28:R31) -> 0 | S32: =J32/L32 -> #DIV/0! | T32: =IFERROR((D32-#REF!)/D32,) | U32: =IFERROR((E32-#REF!)/E32,) | V32: =IFERROR((D32-#REF!)/D32, ) | W32: =IFERROR((E32-#REF!)/E32, )
B33: 45949 | C33: AIRDOCTOR - Home Depot US | G33: =E33/F33 -> #DIV/0! | H33: =D33/E33 -> #DIV/0! | I33: =H33/G33 -> #DIV/0! | J33: 107.11 | K33: 4721 | L33: 0 | M33: 0 | N33: =J33/M33 -> #DIV/0! | O33: =M33/J33 -> 0 | P33: =J33/D33 -> #DIV/0! | Q33: =M33/D33 -> #DIV/0! | R33: =D33-M33 -> 0 | S33: =J33/L33 -> #DIV/0!
C34: AQUA TRU - Home Depot US | G34: =E34/F34 -> #DIV/0! | H34: =D34/E34 -> #DIV/0! | I34: =H34/G34 -> #DIV/0! | J34: 122.23 | K34: 19317 | L34: 0 | M34: 0 | N34: =J34/M34 -> #DIV/0! | O34: =M34/J34 -> 0 | P34: =J34/D34 -> #DIV/0! | Q34: =M34/D34 -> #DIV/0! | R34: =D34-M34 -> 0 | S34: =J34/L34 -> #DIV/0!
B35: to | C35: PAINT ZOOM - Home Depot US | G35: =E35/F35 -> #DIV/0! | H35: =D35/E35 -> #DIV/0! | I35: =H35/G35 -> #DIV/0! | J35: 0 | K35: 0 | L35: 0 | M35: 0 | N35: =(J35/M35) -> #DIV/0! | O35: =M35/J35 -> #DIV/0! | P35: =J35/D35 -> #DIV/0! | Q35: =M35/D35 -> #DIV/0! | R35: =D35-M35 -> 0 | S35: =J35/L35 -> #DIV/0!
A36: =iferror(if(B36>0,month(B36)&"-"&year(B36),B36),) -> 10-2025 | B36: 45955 | C36: ROTORAZER SAW - Home Depot US / ROTORAZERSAW - Home Depot US | G36: =E36/F36 -> #DIV/0! | H36: =D36/E36 -> #DIV/0! | I36: =H36/G36 -> #DIV/0! | N36: =J36/M36 -> #DIV/0! | O36: =M36/J36 -> #DIV/0! | P36: =J36/D36 -> #DIV/0! | Q36: =M36/D36 -> #DIV/0! | R36: =D36-M36 -> 0 | S36: =J36/L36 -> #DIV/0!
A37: =iferror(if(B37>0,month(B37)&"-"&year(B37),B37),) | B37: Week 43 | D37: =SUM(D33:D36) -> 0 | E37: =SUM(E33:E36) -> 0 | F37: =SUM(F33:F36) -> 0 | G37: =E37/F37 -> #DIV/0! | H37: =D37/E37 -> #DIV/0! | I37: =H37/G37 -> #DIV/0! | J37: =SUM(J33:J36) -> 229.34 | K37: =SUM(K33:K36) -> 24038 | L37: =SUM(L33:L36) -> 0 | M37: =SUM(M33:M36) -> 0 | N37: =J37/M37 -> #DIV/0! | O37: =M37/J37 -> 0 | P37: =J37/D37 -> #DIV/0! | Q37: =M37/D37 -> #DIV/0! | R37: =SUM(R33:R36) -> 0 | S37: =J37/L37 -> #DIV/0! | T37: =IFERROR((D37-#REF!)/D37,) | U37: =IFERROR((E37-#REF!)/E37,) | V37: =IFERROR((D37-#REF!)/D37, ) | W37: =IFERROR((E37-#REF!)/E37, )
B38: 45956 | C38: AIRDOCTOR - Home Depot US | G38: =E38/F38 -> #DIV/0! | H38: =D38/E38 -> #DIV/0! | I38: =H38/G38 -> #DIV/0! | J38: 186.03 | K38: 8308 | L38: 0 | M38: 0 | N38: =J38/M38 -> #DIV/0! | O38: =M38/J38 -> 0 | P38: =J38/D38 -> #DIV/0! | Q38: =M38/D38 -> #DIV/0! | R38: =D38-M38 -> 0 | S38: =J38/L38 -> #DIV/0!
C39: AQUA TRU - Home Depot US | G39: =E39/F39 -> #DIV/0! | H39: =D39/E39 -> #DIV/0! | I39: =H39/G39 -> #DIV/0! | J39: 306.48 | K39: 36970 | L39: 0 | M39: 0 | N39: =J39/M39 -> #DIV/0! | O39: =M39/J39 -> 0 | P39: =J39/D39 -> #DIV/0! | Q39: =M39/D39 -> #DIV/0! | R39: =D39-M39 -> 0 | S39: =J39/L39 -> #DIV/0!
B40: to | C40: PAINT ZOOM - Home Depot US | G40: =E40/F40 -> #DIV/0! | H40: =D40/E40 -> #DIV/0! | I40: =H40/G40 -> #DIV/0! | J40: 0 | K40: 0 | L40: 0 | M40: 0 | N40: =(J40/M40) -> #DIV/0! | O40: =M40/J40 -> #DIV/0! | P40: =J40/D40 -> #DIV/0! | Q40: =M40/D40 -> #DIV/0! | R40: =D40-M40 -> 0 | S40: =J40/L40 -> #DIV/0!
A41: =iferror(if(B41>0,month(B41)&"-"&year(B41),B41),) -> 11-2025 | B41: 45962 | C41: ROTORAZER SAW - Home Depot US / ROTORAZERSAW - Home Depot US | G41: =E41/F41 -> #DIV/0! | H41: =D41/E41 -> #DIV/0! | I41: =H41/G41 -> #DIV/0! | J41: 109.38 | K41: 15992 | L41: 0 | M41: 0 | N41: =J41/M41 -> #DIV/0! | O41: =M41/J41 -> 0 | P41: =J41/D41 -> #DIV/0! | Q41: =M41/D41 -> #DIV/0! | R41: =D41-M41 -> 0 | S41: =J41/L41 -> #DIV/0!
A42: =iferror(if(B42>0,month(B42)&"-"&year(B42),B42),) | B42: Week 44 | D42: =SUM(D38:D41) -> 0 | E42: =SUM(E38:E41) -> 0 | F42: =SUM(F38:F41) -> 0 | G42: =E42/F42 -> #DIV/0! | H42: =D42/E42 -> #DIV/0! | I42: =H42/G42 -> #DIV/0! | J42: =SUM(J38:J41) -> 601.89 | K42: =SUM(K38:K41) -> 61270 | L42: =SUM(L38:L41) -> 0 | M42: =SUM(M38:M41) -> 0 | N42: =J42/M42 -> #DIV/0! | O42: =M42/J42 -> 0 | P42: =J42/D42 -> #DIV/0! | Q42: =M42/D42 -> #DIV/0! | R42: =SUM(R38:R41) -> 0 | S42: =J42/L42 -> #DIV/0! | T42: =IFERROR((D42-#REF!)/D42,) | U42: =IFERROR((E42-#REF!)/E42,) | V42: =IFERROR((D42-#REF!)/D42, ) | W42: =IFERROR((E42-#REF!)/E42, )
...

Sheet ALL - 2026 - Orange Access
A1: Home Depot RPD - Orange Access - DATA SOURCES: https://us.orangeapronmedia.com/r/organizations
C2: WEEKLY PERFORMANCE | X2: =(#REF!+#REF!+#REF!+#REF!)-(monthly_reporting_2021!D17+monthly_reporting_2021!D23+monthly_reporting_2021!D29+monthly_reporting_2021!D35) -> #REF! | Y2: =((#REF!+#REF!+#REF!+#REF!)-(monthly_reporting_2021!E17+monthly_reporting_2021!E23+monthly_reporting_2021!E29+monthly_reporting_2021!E35))/(#REF!+#REF!+#REF!+#REF!) -> #REF!
K3: Total Sales | N3: Total Orders | S3: Total Units Sold
K4: =VLOOKUP("Current Week",$B$11:$X$95,match("SALES",$B$11:$X$11,0),FALSE) -> 0 | N4: =VLOOKUP("Current Week",$B$11:$X$95,match("Units Sold",$B$11:$X$11,0),FALSE) -> 0 | S4: =VLOOKUP("Current Week",$B$11:$X$95,match("Ordered Items",$B$11:$X$11,0),FALSE) -> 0
K5: =(K4-(VLOOKUP("Previous Week",$B$11:$X$100,match("SALES",$B$11:$X$11,0),FALSE)))/K4 -> #DIV/0! | N5: =(N4-(VLOOKUP("Previous Week",$B$11:$X$100,match("Units Sold",$B$11:$X$11,0),FALSE)))/N4 -> #DIV/0! | S5: =(S4-(VLOOKUP("Previous Week",$B$11:$X$100,match("Ordered Items",$B$11:$X$11,0),FALSE)))/S4 -> #DIV/0!
K7: Advertising Sales | N7: Advertising Spend | S7: ACoS
K8: =VLOOKUP("Current Week",$B$11:$X$95,match("AD SALES",$B$11:$X$11,0),FALSE) -> 1710.34 | N8: =VLOOKUP("Current Week",$B$11:$X$95,match("SP AD SPEND",$B$11:$X$11,0),FALSE) -> 907.14 | S8: =N8/K8 -> 0.53038577
K9: =(K8-(VLOOKUP("Previous Week",$B$11:$X$100,match("AD SALES",$B$11:$X$11,0),FALSE)))/K8 -> -0.35237438 | N9: =(N8-(VLOOKUP("Previous Week",$B$11:$X$100,match("SP AD SPEND",$B$11:$X$11,0),FALSE)))/N8 -> 0.028540247 | S9: =(S8-(VLOOKUP("Previous Week",$B$11:$X$100,match("ACOS",$B$11:$X$11,0),FALSE)))/S8 -> 0.28166359
D10: SALES METRICS | L10: ADVERTISING PERFORMANCE | V10: MoM | X10: YoY
A11: Month-Code | B11: DATE | C11: Campaign Group per Brand | D11: SALES | E11: UNITS SOLD | F11: ORDERED ITEMS | G11: UNITS PER ORDER | H11: SALES PER ORDER | I11: ASP | J11: SP AD SPEND | K11: IMPRESSIONS | L11: UNIT SALES | M11: AD SALES | N11: ACoS | O11: ROAS (return on ad send) | P11: TACoS (Total Advertsing Cost of Sales) | Q11: REVENUE PERCENTAGE OF AD SALES | R11: ORGANIC SALES | S11: CPO | T11: SALES | U11: UNITS | V11: SALES | W11: UNITS
B13: 45921 | C13: AIRDOCTOR - Home Depot US | G13: =E13/F13 -> #DIV/0! | H13: =D13/E13 -> #DIV/0! | I13: =H13/G13 -> #DIV/0! | J13: 0 | K13: 0 | L13: 0 | M13: 0 | N13: =J13/M13 -> #DIV/0! | O13: =M13/J13 -> #DIV/0! | P13: =J13/D13 -> #DIV/0! | Q13: =M13/D13 -> #DIV/0! | R13: =D13-M13 -> 0 | S13: =J13/L13 -> #DIV/0!
C14: AQUA TRU - Home Depot US | G14: =E14/F14 -> #DIV/0! | H14: =D14/E14 -> #DIV/0! | I14: =H14/G14 -> #DIV/0! | J14: 0 | K14: 0 | L14: 0 | M14: 0 | N14: =J14/M14 -> #DIV/0! | O14: =M14/J14 -> #DIV/0! | P14: =J14/D14 -> #DIV/0! | Q14: =M14/D14 -> #DIV/0! | R14: =D14-M14 -> 0 | S14: =J14/L14 -> #DIV/0!
B15: to | C15: PAINT ZOOM - Home Depot US | G15: =E15/F15 -> #DIV/0! | H15: =D15/E15 -> #DIV/0! | I15: =H15/G15 -> #DIV/0! | J15: 0 | K15: 0 | L15: 0 | M15: 0 | N15: =(J15/M15) -> #DIV/0! | O15: =M15/J15 -> #DIV/0! | P15: =J15/D15 -> #DIV/0! | Q15: =M15/D15 -> #DIV/0! | R15: =D15-M15 -> 0 | S15: =J15/L15 -> #DIV/0!
A16: =iferror(if(B16>0,month(B16)&"-"&year(B16),B16),) -> 9-2025 | B16: 45927 | C16: ROTORAZER SAW - Home Depot US / ROTORAZERSAW - Home Depot US | G16: =E16/F16 -> #DIV/0! | H16: =D16/E16 -> #DIV/0! | I16: =H16/G16 -> #DIV/0! | J16: 0 | K16: 0 | L16: 0 | M16: 0 | N16: =J16/M16 -> #DIV/0! | O16: =M16/J16 -> #DIV/0! | P16: =J16/D16 -> #DIV/0! | Q16: =M16/D16 -> #DIV/0! | R16: =D16-M16 -> 0 | S16: =J16/L16 -> #DIV/0!
B17: 46012 | C17: AIRDOCTOR - Home Depot US | G17: =E17/F17 -> #DIV/0! | H17: =D17/E17 -> #DIV/0! | I17: =H17/G17 -> #DIV/0! | J17: 176.83 | K17: 10330 | M17: 839 | N17: =J17/M17 -> 0.21076281 | O17: =M17/J17 -> 4.74467 | P17: =J17/D17 -> #DIV/0! | Q17: =M17/D17 -> #DIV/0! | R17: =D17-M17 -> -839 | S17: =J17/L17 -> #DIV/0!
C18: AirDoctor - Home Depot CA | G18: =E18/F18 -> #DIV/0! | H18: =D18/E18 -> #DIV/0! | I18: =H18/G18 -> #DIV/0! | J18: 0 | K18: 0 | M18: 0 | N18: =J18/M18 -> #DIV/0! | O18: =M18/J18 -> #DIV/0! | P18: =J18/D18 -> #DIV/0! | Q18: =M18/D18 -> #DIV/0! | R18: =D18-M18 -> 0 | S18: =J18/L18 -> #DIV/0!
C19: AQUA TRU - Home Depot US | G19: =E19/F19 -> #DIV/0! | H19: =D19/E19 -> #DIV/0! | I19: =H19/G19 -> #DIV/0! | J19: 169.03 | K19: 10693 | M19: 177 | N19: =J19/M19 -> 0.95497175 | O19: =M19/J19 -> 1.0471514 | P19: =J19/D19 -> #DIV/0! | Q19: =M19/D19 -> #DIV/0! | R19: =D19-M19 -> -177 | S19: =J19/L19 -> #DIV/0!
C20: AquaTru - Home Depot CA | G20: =E20/F20 -> #DIV/0! | H20: =D20/E20 -> #DIV/0! | I20: =H20/G20 -> #DIV/0! | J20: 0 | K20: 0 | M20: 0 | N20: =J20/M20 -> #DIV/0! | O20: =M20/J20 -> #DIV/0! | P20: =J20/D20 -> #DIV/0! | Q20: =M20/D20 -> #DIV/0! | R20: =D20-M20 -> 0 | S20: =J20/L20 -> #DIV/0!
B21: to | C21: PAINT ZOOM - Home Depot US | G21: =E21/F21 -> #DIV/0! | H21: =D21/E21 -> #DIV/0! | I21: =H21/G21 -> #DIV/0! | J21: 0 | K21: 0 | M21: 0 | N21: =(J21/M21) -> #DIV/0! | O21: =M21/J21 -> #DIV/0! | P21: =J21/D21 -> #DIV/0! | Q21: =M21/D21 -> #DIV/0! | R21: =D21-M21 -> 0 | S21: =J21/L21 -> #DIV/0!
A22: =iferror(if(B22>0,month(B22)&"-"&year(B22),B22),) -> 12-2025 | B22: 46018 | C22: ROTORAZER SAW - Home Depot US / ROTORAZERSAW - Home Depot US | G22: =E22/F22 -> #DIV/0! | H22: =D22/E22 -> #DIV/0! | I22: =H22/G22 -> #DIV/0! | J22: 174.74 | K22: 5497 | M22: 0 | N22: =J22/M22 -> #DIV/0! | O22: =M22/J22 -> 0 | P22: =J22/D22 -> #DIV/0! | Q22: =M22/D22 -> #DIV/0! | R22: =D22-M22 -> 0 | S22: =J22/L22 -> #DIV/0!
A23: =iferror(if(B23>0,month(B23)&"-"&year(B23),B23),) | B23: Week 52 | D23: =SUM(D17:D22) -> 0 | E23: =SUM(E17:E22) -> 0 | F23: =SUM(F17:F22) -> 0 | G23: =E23/F23 -> #DIV/0! | H23: =D23/E23 -> #DIV/0! | I23: =H23/G23 -> #DIV/0! | J23: =SUM(J17:J22) -> 520.6 | K23: =SUM(K17:K22) -> 26520 | L23: =SUM(L17:L22) -> 0 | M23: =SUM(M17:M22) -> 1016 | N23: =J23/M23 -> 0.51240157 | O23: =M23/J23 -> 1.9515943 | P23: =J23/D23 -> #DIV/0! | Q23: =M23/D23 -> #DIV/0! | R23: =SUM(R17:R22) -> -1016 | S23: =J23/L23 -> #DIV/0! | T23: =IFERROR((D23-#REF!)/D23,) | U23: =IFERROR((E23-#REF!)/E23,) | V23: =IFERROR((D23-#REF!)/D23, ) | W23: =IFERROR((E23-#REF!)/E23, )
B24: 46019 | C24: AIRDOCTOR - Home Depot US | G24: =E24/F24 -> #DIV/0! | H24: =D24/E24 -> #DIV/0! | I24: =H24/G24 -> #DIV/0! | J24: 163.31 | K24: 11820 | M24: 58 | N24: =J24/M24 -> 2.8156897 | O24: =M24/J24 -> 0.35515278 | P24: =J24/D24 -> #DIV/0! | Q24: =M24/D24 -> #DIV/0! | R24: =D24-M24 -> -58 | S24: =J24/L24 -> #DIV/0!
C25: AirDoctor - Home Depot CA | G25: =E25/F25 -> #DIV/0! | H25: =D25/E25 -> #DIV/0! | I25: =H25/G25 -> #DIV/0! | J25: 106.4 | K25: 6630 | M25: 0 | N25: =J25/M25 -> #DIV/0! | O25: =M25/J25 -> 0 | P25: =J25/D25 -> #DIV/0! | Q25: =M25/D25 -> #DIV/0! | R25: =D25-M25 -> 0 | S25: =J25/L25 -> #DIV/0!
C26: AQUA TRU - Home Depot US | G26: =E26/F26 -> #DIV/0! | H26: =D26/E26 -> #DIV/0! | I26: =H26/G26 -> #DIV/0! | J26: 157.13 | K26: 10589 | M26: 359 | N26: =J26/M26 -> 0.43768802 | O26: =M26/J26 -> 2.2847324 | P26: =J26/D26 -> #DIV/0! | Q26: =M26/D26 -> #DIV/0! | R26: =D26-M26 -> -359 | S26: =J26/L26 -> #DIV/0!
C27: AquaTru - Home Depot CA | G27: =E27/F27 -> #DIV/0! | H27: =D27/E27 -> #DIV/0! | I27: =H27/G27 -> #DIV/0! | J27: 0 | K27: 0 | M27: 0 | N27: =J27/M27 -> #DIV/0! | O27: =M27/J27 -> #DIV/0! | P27: =J27/D27 -> #DIV/0! | Q27: =M27/D27 -> #DIV/0! | R27: =D27-M27 -> 0 | S27: =J27/L27 -> #DIV/0!
B28: to | C28: PAINT ZOOM - Home Depot US | G28: =E28/F28 -> #DIV/0! | H28: =D28/E28 -> #DIV/0! | I28: =H28/G28 -> #DIV/0! | J28: 0 | K28: 0 | M28: 0 | N28: =(J28/M28) -> #DIV/0! | O28: =M28/J28 -> #DIV/0! | P28: =J28/D28 -> #DIV/0! | Q28: =M28/D28 -> #DIV/0! | R28: =D28-M28 -> 0 | S28: =J28/L28 -> #DIV/0!
A29: =iferror(if(B29>0,month(B29)&"-"&year(B29),B29),) -> 1-2026 | B29: 46025 | C29: ROTORAZER SAW - Home Depot US / ROTORAZERSAW - Home Depot US | G29: =E29/F29 -> #DIV/0! | H29: =D29/E29 -> #DIV/0! | I29: =H29/G29 -> #DIV/0! | J29: 166.48 | K29: 5772 | M29: 154 | N29: =J29/M29 -> 1.081039 | O29: =M29/J29 -> 0.92503604 | P29: =J29/D29 -> #DIV/0! | Q29: =M29/D29 -> #DIV/0! | R29: =D29-M29 -> -154 | S29: =J29/L29 -> #DIV/0!
A30: =iferror(if(B30>0,month(B30)&"-"&year(B30),B30),) | B30: 2026 - Week 1 | D30: =SUM(D24:D29) -> 0 | E30: =SUM(E24:E29) -> 0 | F30: =SUM(F24:F29) -> 0 | G30: =E30/F30 -> #DIV/0! | H30: =D30/E30 -> #DIV/0! | I30: =H30/G30 -> #DIV/0! | J30: =SUM(J24:J29) -> 593.32 | K30: =SUM(K24:K29) -> 34811 | L30: =SUM(L24:L29) -> 0 | M30: =SUM(M24:M29) -> 571 | N30: =J30/M30 -> 1.0390893 | O30: =M30/J30 -> 0.96238118 | P30: =J30/D30 -> #DIV/0! | Q30: =M30/D30 -> #DIV/0! | R30: =SUM(R24:R29) -> -571 | S30: =J30/L30 -> #DIV/0! | T30: =IFERROR((D30-#REF!)/D30,) | U30: =IFERROR((E30-#REF!)/E30,) | V30: =IFERROR((D30-#REF!)/D30, ) | W30: =IFERROR((E30-#REF!)/E30, )
B31: 46026 | C31: AIRDOCTOR - Home Depot US | G31: =E31/F31 -> #DIV/0! | H31: =D31/E31 -> #DIV/0! | I31: =H31/G31 -> #DIV/0! | J31: 158.91 | K31: 13235 | M31: 609 | N31: =J31/M31 -> 0.26093596 | O31: =M31/J31 -> 3.8323579 | P31: =J31/D31 -> #DIV/0! | Q31: =M31/D31 -> #DIV/0! | R31: =D31-M31 -> -609 | S31: =J31/L31 -> #DIV/0!
C32: AirDoctor - Home Depot CA | G32: =E32/F32 -> #DIV/0! | H32: =D32/E32 -> #DIV/0! | I32: =H32/G32 -> #DIV/0! | J32: 295.15 | K32: 25738 | M32: 0 | N32: =J32/M32 -> #DIV/0! | O32: =M32/J32 -> 0 | P32: =J32/D32 -> #DIV/0! | Q32: =M32/D32 -> #DIV/0! | R32: =D32-M32 -> 0 | S32: =J32/L32 -> #DIV/0!
C33: AQUA TRU - Home Depot US | G33: =E33/F33 -> #DIV/0! | H33: =D33/E33 -> #DIV/0! | I33: =H33/G33 -> #DIV/0! | J33: 156.35 | K33: 23049 | M33: 0 | N33: =J33/M33 -> #DIV/0! | O33: =M33/J33 -> 0 | P33: =J33/D33 -> #DIV/0! | Q33: =M33/D33 -> #DIV/0! | R33: =D33-M33 -> 0 | S33: =J33/L33 -> #DIV/0!
C34: AquaTru - Home Depot CA | G34: =E34/F34 -> #DIV/0! | H34: =D34/E34 -> #DIV/0! | I34: =H34/G34 -> #DIV/0! | J34: 56.72 | K34: 6838 | M34: 0 | N34: =J34/M34 -> #DIV/0! | O34: =M34/J34 -> 0 | P34: =J34/D34 -> #DIV/0! | Q34: =M34/D34 -> #DIV/0! | R34: =D34-M34 -> 0 | S34: =J34/L34 -> #DIV/0!
B35: to | C35: PAINT ZOOM - Home Depot US | G35: =E35/F35 -> #DIV/0! | H35: =D35/E35 -> #DIV/0! | I35: =H35/G35 -> #DIV/0! | J35: 0 | K35: 0 | M35: 0 | N35: =(J35/M35) -> #DIV/0! | O35: =M35/J35 -> #DIV/0! | P35: =J35/D35 -> #DIV/0! | Q35: =M35/D35 -> #DIV/0! | R35: =D35-M35 -> 0 | S35: =J35/L35 -> #DIV/0!
A36: =iferror(if(B36>0,month(B36)&"-"&year(B36),B36),) -> 1-2026 | B36: 46032 | C36: ROTORAZER SAW - Home Depot US / ROTORAZERSAW - Home Depot US | G36: =E36/F36 -> #DIV/0! | H36: =D36/E36 -> #DIV/0! | I36: =H36/G36 -> #DIV/0! | J36: 139.38 | K36: 12458 | M36: 0 | N36: =J36/M36 -> #DIV/0! | O36: =M36/J36 -> 0 | P36: =J36/D36 -> #DIV/0! | Q36: =M36/D36 -> #DIV/0! | R36: =D36-M36 -> 0 | S36: =J36/L36 -> #DIV/0!
A37: =iferror(if(B37>0,month(B37)&"-"&year(B37),B37),) | B37: 2026 - Week 2 | D37: =SUM(D31:D36) -> 0 | E37: =SUM(E31:E36) -> 0 | F37: =SUM(F31:F36) -> 0 | G37: =E37/F37 -> #DIV/0! | H37: =D37/E37 -> #DIV/0! | I37: =H37/G37 -> #DIV/0! | J37: =SUM(J31:J36) -> 806.51 | K37: =SUM(K31:K36) -> 81318 | L37: =SUM(L31:L36) -> 0 | M37: =SUM(M31:M36) -> 609 | N37: =J37/M37 -> 1.3243186 | O37: =M37/J37 -> 0.75510533 | P37: =J37/D37 -> #DIV/0! | Q37: =M37/D37 -> #DIV/0! | R37: =SUM(R31:R36) -> -609 | S37: =J37/L37 -> #DIV/0! | T37: =IFERROR((D37-#REF!)/D37,) | U37: =IFERROR((E37-#REF!)/E37,) | V37: =IFERROR((D37-#REF!)/D37, ) | W37: =IFERROR((E37-#REF!)/E37, )
B38: 46033 | C38: AIRDOCTOR - Home Depot US | G38: =E38/F38 -> #DIV/0! | H38: =D38/E38 -> #DIV/0! | I38: =H38/G38 -> #DIV/0! | J38: 160.36 | K38: 7685 | M38: 0 | N38: =J38/M38 -> #DIV/0! | O38: =M38/J38 -> 0 | P38: =J38/D38 -> #DIV/0! | Q38: =M38/D38 -> #DIV/0! | R38: =D38-M38 -> 0 | S38: =J38/L38 -> #DIV/0!
C39: AirDoctor - Home Depot CA | G39: =E39/F39 -> #DIV/0! | H39: =D39/E39 -> #DIV/0! | I39: =H39/G39 -> #DIV/0! | J39: 277.4 | K39: 25369 | M39: 0 | N39: =J39/M39 -> #DIV/0! | O39: =M39/J39 -> 0 | P39: =J39/D39 -> #DIV/0! | Q39: =M39/D39 -> #DIV/0! | R39: =D39-M39 -> 0 | S39: =J39/L39 -> #DIV/0!
C40: AQUA TRU - Home Depot US | G40: =E40/F40 -> #DIV/0! | H40: =D40/E40 -> #DIV/0! | I40: =H40/G40 -> #DIV/0! | J40: 156.06 | K40: 20546 | M40: 0 | N40: =J40/M40 -> #DIV/0! | O40: =M40/J40 -> 0 | P40: =J40/D40 -> #DIV/0! | Q40: =M40/D40 -> #DIV/0! | R40: =D40-M40 -> 0 | S40: =J40/L40 -> #DIV/0!
C41: AquaTru - Home Depot CA | G41: =E41/F41 -> #DIV/0! | H41: =D41/E41 -> #DIV/0! | I41: =H41/G41 -> #DIV/0! | J41: 284.2 | K41: 18011 | M41: 0 | N41: =J41/M41 -> #DIV/0! | O41: =M41/J41 -> 0 | P41: =J41/D41 -> #DIV/0! | Q41: =M41/D41 -> #DIV/0! | R41: =D41-M41 -> 0 | S41: =J41/L41 -> #DIV/0!
B42: to | C42: PAINT ZOOM - Home Depot US | G42: =E42/F42 -> #DIV/0! | H42: =D42/E42 -> #DIV/0! | I42: =H42/G42 -> #DIV/0! | J42: 0 | K42: 0 | M42: 0 | N42: =(J42/M42) -> #DIV/0! | O42: =M42/J42 -> #DIV/0! | P42: =J42/D42 -> #DIV/0! | Q42: =M42/D42 -> #DIV/0! | R42: =D42-M42 -> 0 | S42: =J42/L42 -> #DIV/0!
...

Sheet Home Depot - 2026
A1: DATA SOURCE: https://app.dsco.io/insights/sales-insights
C2: WEEKLY PERFORMANCE | X2: =(#REF!+#REF!+#REF!+#REF!)-(monthly_reporting_2021!D17+monthly_reporting_2021!D23+monthly_reporting_2021!D29+monthly_reporting_2021!D35) -> #REF! | Y2: =((#REF!+#REF!+#REF!+#REF!)-(monthly_reporting_2021!E17+monthly_reporting_2021!E23+monthly_reporting_2021!E29+monthly_reporting_2021!E35))/(#REF!+#REF!+#REF!+#REF!) -> #REF!
C3: Total Sales | F3: Total Orders | J3: Total Units Sold
C4: =VLOOKUP("Current Week",$B$11:$Z$57,match("SALES",$B$11:$Z$11,0),FALSE) -> 0.4882394 | F4: =VLOOKUP("Current Week",$B$11:$Z$57,match("Units Sold",$B$11:$Z$11,0),FALSE) -> 137 | J4: =VLOOKUP("Current Week",$B$11:$Z$57,match("Ordered Items",$B$11:$Z$11,0),FALSE) -> 84
C5: =(C4-(VLOOKUP("Previous Week",$B$11:$Z$61,match("SALES",$B$11:$Z$11,0),FALSE)))/C4 -> 1 | F5: =(F4-(VLOOKUP("Previous Week",$B$11:$Z$71,match("Units Sold",$B$11:$Z$11,0),FALSE)))/F4 -> 0.45985401 | J5: =(J4-(VLOOKUP("Previous Week",$B$11:$Z$71,match("Ordered Items",$B$11:$Z$11,0),FALSE)))/J4 -> 0.44047619
C7: Advertising Sales | F7: Advertising Spend | J7: ACoS
C8: =VLOOKUP("Current Week",$B$11:$Z$57,match("AD SALES",$B$11:$Z$11,0),FALSE) -> #N/A | F8: =VLOOKUP("Current Week",$B$11:$Z$57,match("SP AD SPEND",$B$11:$Z$11,0),FALSE) -> #N/A | J8: =F8/C8 -> #N/A
C9: =(C8-(VLOOKUP("Previous Week",$B$11:$Z$71,match("AD SALES",$B$11:$Z$11,0),FALSE)))/C8 -> #N/A | F9: =(F8-(VLOOKUP("Previous Week",$B$11:$Z$71,match("SP AD SPEND",$B$11:$Z$11,0),FALSE)))/F8 -> #N/A | J9: =(J8-(VLOOKUP("Previous Week",$B$11:$Z$71,match("ACOS",$B$11:$Z$11,0),FALSE)))/J8 -> #N/A
D10: SALES METRICS | V10: MoM | X10: YoY
A11: Month-Code | B11: DATE | C11: BRAND | D11: GWV | E11: UNITS SOLD | F11: ORDERED ITEMS | G11: UNITS PER ORDER | H11: SALES PER ORDER | I11: ASP | V11: SALES | W11: UNITS | X11: SALES | Y11: UNITS
A13: =iferror(if(B13>0,month(B13)&"-"&year(B13),B13),) -> 12-2025 | B13: 46019 | C13: AquaTru | D13: 2772.16 | E13: 40 | F13: 37 | G13: =E13/F13 -> 1.0810811 | H13: =D13/E13 -> 69.304 | I13: =H13/G13 -> 64.1062
C14: AirDoctor | D14: 5527.38 | E14: 36 | F14: 30 | G14: =E14/F14 -> 1.2 | H14: =D14/E14 -> 153.53833 | I14: =H14/G14 -> 127.94861
A15: =iferror(if(B15>0,month(B15)&"-"&year(B15),B15),) | C15: Rotorazer | D15: 382.5 | E15: 5 | F15: 5 | G15: =E15/F15 -> 1 | H15: =D15/E15 -> 76.5 | I15: =H15/G15 -> 76.5
A16: =iferror(if(B16>0,month(B16)&"-"&year(B16),B16),) -> 1-2026 | B16: 46025 | C16: Ionic Pro | D16: 0 | E16: 0 | F16: 0 | G16: =E16/F16 -> #DIV/0! | H16: =D16/E16 -> #DIV/0! | I16: =H16/G16 -> #DIV/0!
A17: =iferror(if(B17>0,month(B17)&"-"&year(B17),B17),) | B17: 2026 - Week 1 | D17: =SUM(D13:D16) -> 8682.04 | E17: =SUM(E13:E16) -> 81 | F17: =SUM(F13:F16) -> 72 | G17: =E17/F17 -> 1.125 | H17: =D17/E17 -> 107.18568 | I17: =H17/G17 -> 95.276159 | V17: =IFERROR((D17-#REF!)/D17,) | W17: =IFERROR((E17-#REF!)/E17,) | X17: =IFERROR((D17-#REF!)/D17,) | Y17: =IFERROR((E17-#REF!)/E17,)
A18: =iferror(if(B18>0,month(B18)&"-"&year(B18),B18),) -> 1-2026 | B18: 46026 | C18: AquaTru | D18: 5422.63 | E18: 55 | F18: 53 | G18: =E18/F18 -> 1.0377358 | H18: =D18/E18 -> 98.593273 | I18: =H18/G18 -> 95.008063
C19: AirDoctor | D19: 2828.19 | E19: 29 | F19: 25 | G19: =E19/F19 -> 1.16 | H19: =D19/E19 -> 97.523793 | I19: =H19/G19 -> 84.072235
A20: =iferror(if(B20>0,month(B20)&"-"&year(B20),B20),) | C20: Rotorazer | D20: 2066.1 | E20: 13 | F20: 12 | G20: =E20/F20 -> 1.0833333 | H20: =D20/E20 -> 158.93077 | I20: =H20/G20 -> 146.70533
A21: =iferror(if(B21>0,month(B21)&"-"&year(B21),B21),) -> 1-2026 | B21: 46032 | C21: Ionic Pro | D21: 0 | E21: 0 | F21: 0 | G21: =E21/F21 -> #DIV/0! | H21: =D21/E21 -> #DIV/0! | I21: =H21/G21 -> #DIV/0!
A22: =iferror(if(B22>0,month(B22)&"-"&year(B22),B22),) | B22: 2026 - Week 2 | D22: =SUM(D18:D21) -> 10316.92 | E22: =SUM(E18:E21) -> 97 | F22: =SUM(F18:F21) -> 90 | G22: =E22/F22 -> 1.0777778 | H22: =D22/E22 -> 106.36 | I22: =H22/G22 -> 98.684536 | V22: =IFERROR((D22-#REF!)/D22,) | W22: =IFERROR((E22-#REF!)/E22,) | X22: =IFERROR((D22-#REF!)/D22,) | Y22: =IFERROR((E22-#REF!)/E22,)
A23: =iferror(if(B23>0,month(B23)&"-"&year(B23),B23),) -> 1-2026 | B23: 46033 | C23: AquaTru | D23: 6614.61 | E23: 73 | F23: 71 | G23: =E23/F23 -> 1.028169 | H23: =D23/E23 -> 90.611096 | I23: =H23/G23 -> 88.1286
C24: AirDoctor | D24: 3820.15 | E24: 37 | F24: 29 | G24: =E24/F24 -> 1.2758621 | H24: =D24/E24 -> 103.2473 | I24: =H24/G24 -> 80.923557
A25: =iferror(if(B25>0,month(B25)&"-"&year(B25),B25),) | C25: Rotorazer | D25: 884.7 | E25: 8 | F25: 8 | G25: =E25/F25 -> 1 | H25: =D25/E25 -> 110.5875 | I25: =H25/G25 -> 110.5875
A26: =iferror(if(B26>0,month(B26)&"-"&year(B26),B26),) -> 1-2026 | B26: 46039 | C26: Ionic Pro | D26: 0 | E26: 0 | F26: 0 | G26: =E26/F26 -> #DIV/0! | H26: =D26/E26 -> #DIV/0! | I26: =H26/G26 -> #DIV/0!
A27: =iferror(if(B27>0,month(B27)&"-"&year(B27),B27),) | B27: 2026 - Week 3 | D27: =SUM(D23:D26) -> 11319.46 | E27: =SUM(E23:E26) -> 118 | F27: =SUM(F23:F26) -> 108 | G27: =E27/F27 -> 1.0925926 | H27: =D27/E27 -> 95.927627 | I27: =H27/G27 -> 87.798167 | V27: =IFERROR((D27-#REF!)/D27,) | W27: =IFERROR((E27-#REF!)/E27,) | X27: =IFERROR((D27-#REF!)/D27,) | Y27: =IFERROR((E27-#REF!)/E27,)
A28: =iferror(if(B28>0,month(B28)&"-"&year(B28),B28),) -> 1-2026 | B28: 46040 | C28: AquaTru | D28: 5624.24 | E28: 68 | F28: 67 | G28: =E28/F28 -> 1.0149254 | H28: =D28/E28 -> 82.709412 | I28: =H28/G28 -> 81.493097
A29: =iferror(if(B29>0,month(B29)&"-"&year(B29),B29),) | C29: AirDoctor | D29: 3529.11 | E29: 40 | F29: 27 | G29: =E29/F29 -> 1.4814815 | H29: =D29/E29 -> 88.22775 | I29: =H29/G29 -> 59.553731
C30: Rotorazer | D30: 364.5 | E30: 4 | F30: 4 | G30: =E30/F30 -> 1 | H30: =D30/E30 -> 91.125 | I30: =H30/G30 -> 91.125
A31: =iferror(if(B31>0,month(B31)&"-"&year(B31),B31),) -> 1-2026 | B31: 46046 | C31: Ionic Pro | D31: 0 | E31: 0 | F31: 0 | G31: =E31/F31 -> #DIV/0! | H31: =D31/E31 -> #DIV/0! | I31: =H31/G31 -> #DIV/0!
A32: =iferror(if(B32>0,month(B32)&"-"&year(B32),B32),) | B32: 2026 - Week 4 | D32: =SUM(D28:D31) -> 9517.85 | E32: =SUM(E28:E31) -> 112 | F32: =SUM(F28:F31) -> 98 | G32: =E32/F32 -> 1.1428571 | H32: =D32/E32 -> 84.980804 | I32: =H32/G32 -> 74.358203 | V32: =IFERROR((D32-#REF!)/D32,) | W32: =IFERROR((E32-#REF!)/E32,) | X32: =IFERROR((D32-#REF!)/D32,) | Y32: =IFERROR((E32-#REF!)/E32,)
A33: =iferror(if(B33>0,month(B33)&"-"&year(B33),B33),) -> 1-2026 | B33: 46047 | C33: AquaTru | D33: 4284.19 | E33: 42 | F33: 41 | G33: =E33/F33 -> 1.0243902 | H33: =D33/E33 -> 102.00452 | I33: =H33/G33 -> 99.575845
C34: AirDoctor | D34: 2972.6 | E34: 21 | F34: 20 | G34: =E34/F34 -> 1.05 | H34: =D34/E34 -> 141.55238 | I34: =H34/G34 -> 134.81179
A35: =iferror(if(B35>0,month(B35)&"-"&year(B35),B35),) | C35: Rotorazer | D35: 241.5 | E35: 8 | F35: 4 | G35: =E35/F35 -> 2 | H35: =D35/E35 -> 30.1875 | I35: =H35/G35 -> 15.09375
A36: =iferror(if(B36>0,month(B36)&"-"&year(B36),B36),) -> 1-2026 | B36: 46053 | C36: Ionic Pro | D36: 195.97 | E36: 1 | F36: 1 | G36: =E36/F36 -> 1 | H36: =D36/E36 -> 195.97 | I36: =H36/G36 -> 195.97
A37: =iferror(if(B37>0,month(B37)&"-"&year(B37),B37),) | B37: 2026 - Week 5 | D37: =SUM(D33:D36) -> 7694.26 | E37: =SUM(E33:E36) -> 72 | F37: =SUM(F33:F36) -> 66 | G37: =E37/F37 -> 1.0909091 | H37: =D37/E37 -> 106.86472 | I37: =H37/G37 -> 97.959329 | V37: =IFERROR((D37-#REF!)/D37,) | W37: =IFERROR((E37-#REF!)/E37,) | X37: =IFERROR((D37-#REF!)/D37,) | Y37: =IFERROR((E37-#REF!)/E37,)
A38: =iferror(if(B38>0,month(B38)&"-"&year(B38),B38),) -> 2-2026 | B38: 46054 | C38: AquaTru | D38: 3583.17 | E38: 42 | F38: 39 | G38: =E38/F38 -> 1.0769231 | H38: =D38/E38 -> 85.313571 | I38: =H38/G38 -> 79.219745
C39: AirDoctor | D39: 3644.44 | E39: 50 | F39: 26 | G39: =E39/F39 -> 1.9230769 | H39: =D39/E39 -> 72.8888 | I39: =H39/G39 -> 37.902176
A40: =iferror(if(B40>0,month(B40)&"-"&year(B40),B40),) | C40: Rotorazer | D40: 848.7 | E40: 6 | F40: 6 | G40: =E40/F40 -> 1 | H40: =D40/E40 -> 141.45 | I40: =H40/G40 -> 141.45
A41: =iferror(if(B41>0,month(B41)&"-"&year(B41),B41),) -> 2-2026 | B41: 46060 | C41: Ionic Pro | D41: 0 | E41: 0 | F41: 0 | G41: =E41/F41 -> #DIV/0! | H41: =D41/E41 -> #DIV/0! | I41: =H41/G41 -> #DIV/0!
A42: =iferror(if(B42>0,month(B42)&"-"&year(B42),B42),) | B42: 2026 - Week 6 | D42: =SUM(D38:D41) -> 8076.31 | E42: =SUM(E38:E41) -> 98 | F42: =SUM(F38:F41) -> 71 | G42: =E42/F42 -> 1.3802817 | H42: =D42/E42 -> 82.411327 | I42: =H42/G42 -> 59.706165 | V42: =IFERROR((D42-#REF!)/D42,) | W42: =IFERROR((E42-#REF!)/E42,) | X42: =IFERROR((D42-#REF!)/D42,) | Y42: =IFERROR((E42-#REF!)/E42,)
...

Sheet Home Depot Canada - 2026
A1: DATA SOURCE: https://app.dsco.io/insights/sales-insights
C2: WEEKLY PERFORMANCE | X2: =(#REF!+#REF!+#REF!+#REF!)-(monthly_reporting_2021!D17+monthly_reporting_2021!D23+monthly_reporting_2021!D29+monthly_reporting_2021!D35) -> #REF! | Y2: =((#REF!+#REF!+#REF!+#REF!)-(monthly_reporting_2021!E17+monthly_reporting_2021!E23+monthly_reporting_2021!E29+monthly_reporting_2021!E35))/(#REF!+#REF!+#REF!+#REF!) -> #REF!
C3: Total Sales | F3: Total Orders | J3: Total Units Sold
C4: =VLOOKUP("Current Week",$B$11:$Z$57,match("SALES",$B$11:$Z$11,0),FALSE) -> -1.1791388 | F4: =VLOOKUP("Current Week",$B$11:$Z$57,match("Units Sold",$B$11:$Z$11,0),FALSE) -> 24 | J4: =VLOOKUP("Current Week",$B$11:$Z$57,match("Ordered Items",$B$11:$Z$11,0),FALSE) -> 24
C5: =(C4-(VLOOKUP("Previous Week",$B$11:$Z$61,match("SALES",$B$11:$Z$11,0),FALSE)))/C4 -> 1 | F5: =(F4-(VLOOKUP("Previous Week",$B$11:$Z$71,match("Units Sold",$B$11:$Z$11,0),FALSE)))/F4 -> -0.33333333 | J5: =(J4-(VLOOKUP("Previous Week",$B$11:$Z$71,match("Ordered Items",$B$11:$Z$11,0),FALSE)))/J4 -> -0.041666667
C7: Advertising Sales | F7: Advertising Spend | J7: ACoS
C8: =VLOOKUP("Current Week",$B$11:$Z$57,match("AD SALES",$B$11:$Z$11,0),FALSE) -> #N/A | F8: =VLOOKUP("Current Week",$B$11:$Z$57,match("SP AD SPEND",$B$11:$Z$11,0),FALSE) -> #N/A | J8: =F8/C8 -> #N/A
C9: =(C8-(VLOOKUP("Previous Week",$B$11:$Z$71,match("AD SALES",$B$11:$Z$11,0),FALSE)))/C8 -> #N/A | F9: =(F8-(VLOOKUP("Previous Week",$B$11:$Z$71,match("SP AD SPEND",$B$11:$Z$11,0),FALSE)))/F8 -> #N/A | J9: =(J8-(VLOOKUP("Previous Week",$B$11:$Z$71,match("ACOS",$B$11:$Z$11,0),FALSE)))/J8 -> #N/A
D10: SALES METRICS | V10: MoM | X10: YoY
A11: Month-Code | B11: DATE | C11: BRAND | D11: GWV | E11: UNITS SOLD | F11: ORDERED ITEMS | G11: UNITS PER ORDER | H11: SALES PER ORDER | I11: ASP | V11: SALES | W11: UNITS | X11: SALES | Y11: UNITS
A13: =iferror(if(B13>0,month(B13)&"-"&year(B13),B13),) -> 12-2025 | B13: 46019 | C13: AquaTru | D13: 6000.27 | E13: 42 | F13: 40 | G13: =E13/F13 -> 1.05 | H13: =D13/E13 -> 142.86357 | I13: =H13/G13 -> 136.06054
C14: AirDoctor | D14: 1008 | E14: 3 | F14: 3 | G14: =E14/F14 -> 1 | H14: =D14/E14 -> 336 | I14: =H14/G14 -> 336
A15: =iferror(if(B15>0,month(B15)&"-"&year(B15),B15),) | C15: Rotorazer | D15: 0 | E15: 0 | F15: 0 | G15: =E15/F15 -> #DIV/0! | H15: =D15/E15 -> #DIV/0! | I15: =H15/G15 -> #DIV/0!
A16: =iferror(if(B16>0,month(B16)&"-"&year(B16),B16),) -> 1-2026 | B16: 46025 | C16: Ionic Pro | D16: 0 | E16: 0 | F16: 0 | G16: =E16/F16 -> #DIV/0! | H16: =D16/E16 -> #DIV/0! | I16: =H16/G16 -> #DIV/0!
A17: =iferror(if(B17>0,month(B17)&"-"&year(B17),B17),) | B17: 2026 - Week 1 | D17: =SUM(D13:D16) -> 7008.27 | E17: =SUM(E13:E16) -> 45 | F17: =SUM(F13:F16) -> 43 | G17: =E17/F17 -> 1.0465116 | H17: =D17/E17 -> 155.73933 | I17: =H17/G17 -> 148.81759 | V17: =IFERROR((D17-#REF!)/D17,) | W17: =IFERROR((E17-#REF!)/E17,) | X17: =IFERROR((D17-#REF!)/D17,) | Y17: =IFERROR((E17-#REF!)/E17,)
A18: =iferror(if(B18>0,month(B18)&"-"&year(B18),B18),) -> 1-2026 | B18: 46026 | C18: AquaTru | D18: 6139.58 | E18: 44 | F18: 44 | G18: =E18/F18 -> 1 | H18: =D18/E18 -> 139.53591 | I18: =H18/G18 -> 139.53591
C19: AirDoctor | D19: 385 | E19: 1 | F19: 1 | G19: =E19/F19 -> 1 | H19: =D19/E19 -> 385 | I19: =H19/G19 -> 385
A20: =iferror(if(B20>0,month(B20)&"-"&year(B20),B20),) | C20: Rotorazer | D20: 0 | E20: 0 | F20: 0 | G20: =E20/F20 -> #DIV/0! | H20: =D20/E20 -> #DIV/0! | I20: =H20/G20 -> #DIV/0!
A21: =iferror(if(B21>0,month(B21)&"-"&year(B21),B21),) -> 1-2026 | B21: 46032 | C21: Ionic Pro | D21: 0 | E21: 0 | F21: 0 | G21: =E21/F21 -> #DIV/0! | H21: =D21/E21 -> #DIV/0! | I21: =H21/G21 -> #DIV/0!
A22: =iferror(if(B22>0,month(B22)&"-"&year(B22),B22),) | B22: 2026 - Week 2 | D22: =SUM(D18:D21) -> 6524.58 | E22: =SUM(E18:E21) -> 45 | F22: =SUM(F18:F21) -> 45 | G22: =E22/F22 -> 1 | H22: =D22/E22 -> 144.99067 | I22: =H22/G22 -> 144.99067 | V22: =IFERROR((D22-#REF!)/D22,) | W22: =IFERROR((E22-#REF!)/E22,) | X22: =IFERROR((D22-#REF!)/D22,) | Y22: =IFERROR((E22-#REF!)/E22,)
A23: =iferror(if(B23>0,month(B23)&"-"&year(B23),B23),) -> 1-2026 | B23: 46033 | C23: AquaTru | D23: 5022.11 | E23: 40 | F23: 40 | G23: =E23/F23 -> 1 | H23: =D23/E23 -> 125.55275 | I23: =H23/G23 -> 125.55275
C24: AirDoctor | D24: 0 | E24: 0 | F24: 0 | G24: =E24/F24 -> #DIV/0! | H24: =D24/E24 -> #DIV/0! | I24: =H24/G24 -> #DIV/0!
A25: =iferror(if(B25>0,month(B25)&"-"&year(B25),B25),) | C25: Rotorazer | D25: 0 | E25: 0 | F25: 0 | G25: =E25/F25 -> #DIV/0! | H25: =D25/E25 -> #DIV/0! | I25: =H25/G25 -> #DIV/0!
A26: =iferror(if(B26>0,month(B26)&"-"&year(B26),B26),) -> 1-2026 | B26: 46039 | C26: Ionic Pro | D26: 0 | E26: 0 | F26: 0 | G26: =E26/F26 -> #DIV/0! | H26: =D26/E26 -> #DIV/0! | I26: =H26/G26 -> #DIV/0!
A27: =iferror(if(B27>0,month(B27)&"-"&year(B27),B27),) | B27: 2026 - Week 3 | D27: =SUM(D23:D26) -> 5022.11 | E27: =SUM(E23:E26) -> 40 | F27: =SUM(F23:F26) -> 40 | G27: =E27/F27 -> 1 | H27: =D27/E27 -> 125.55275 | I27: =H27/G27 -> 125.55275 | V27: =IFERROR((D27-#REF!)/D27,) | W27: =IFERROR((E27-#REF!)/E27,) | X27: =IFERROR((D27-#REF!)/D27,) | Y27: =IFERROR((E27-#REF!)/E27,)
A28: =iferror(if(B28>0,month(B28)&"-"&year(B28),B28),) -> 1-2026 | B28: 46040 | C28: AquaTru | D28: 4058.89 | E28: 34 | F28: 34 | G28: =E28/F28 -> 1 | H28: =D28/E28 -> 119.37912 | I28: =H28/G28 -> 119.37912
A29: =iferror(if(B29>0,month(B29)&"-"&year(B29),B29),) | C29: AirDoctor | D29: 3292.3 | E29: 7 | F29: 6 | G29: =E29/F29 -> 1.1666667 | H29: =D29/E29 -> 470.32857 | I29: =H29/G29 -> 403.13878
C30: Rotorazer | D30: 0 | E30: 0 | F30: 0 | G30: =E30/F30 -> #DIV/0! | H30: =D30/E30 -> #DIV/0! | I30: =H30/G30 -> #DIV/0!
A31: =iferror(if(B31>0,month(B31)&"-"&year(B31),B31),) -> 1-2026 | B31: 46046 | C31: Ionic Pro | D31: 0 | E31: 0 | F31: 0 | G31: =E31/F31 -> #DIV/0! | H31: =D31/E31 -> #DIV/0! | I31: =H31/G31 -> #DIV/0!
A32: =iferror(if(B32>0,month(B32)&"-"&year(B32),B32),) | B32: 2026 - Week 4 | D32: =SUM(D28:D31) -> 7351.19 | E32: =SUM(E28:E31) -> 41 | F32: =SUM(F28:F31) -> 40 | G32: =E32/F32 -> 1.025 | H32: =D32/E32 -> 179.29732 | I32: =H32/G32 -> 174.92421 | V32: =IFERROR((D32-#REF!)/D32,) | W32: =IFERROR((E32-#REF!)/E32,) | X32: =IFERROR((D32-#REF!)/D32,) | Y32: =IFERROR((E32-#REF!)/E32,)
A33: =iferror(if(B33>0,month(B33)&"-"&year(B33),B33),) -> 1-2026 | B33: 46047 | C33: AquaTru | D33: 3447.61 | E33: 31 | F33: 29 | G33: =E33/F33 -> 1.0689655 | H33: =D33/E33 -> 111.21323 | I33: =H33/G33 -> 104.03818
C34: AirDoctor | D34: 272.3 | E34: 1 | F34: 1 | G34: =E34/F34 -> 1 | H34: =D34/E34 -> 272.3 | I34: =H34/G34 -> 272.3
A35: =iferror(if(B35>0,month(B35)&"-"&year(B35),B35),) | C35: Rotorazer | D35: 0 | E35: 0 | F35: 0 | G35: =E35/F35 -> #DIV/0! | H35: =D35/E35 -> #DIV/0! | I35: =H35/G35 -> #DIV/0!
A36: =iferror(if(B36>0,month(B36)&"-"&year(B36),B36),) -> 1-2026 | B36: 46053 | C36: Ionic Pro | D36: 0 | E36: 0 | F36: 0 | G36: =E36/F36 -> #DIV/0! | H36: =D36/E36 -> #DIV/0! | I36: =H36/G36 -> #DIV/0!
A37: =iferror(if(B37>0,month(B37)&"-"&year(B37),B37),) | B37: 2026 - Week 5 | D37: =SUM(D33:D36) -> 3719.91 | E37: =SUM(E33:E36) -> 32 | F37: =SUM(F33:F36) -> 30 | G37: =E37/F37 -> 1.0666667 | H37: =D37/E37 -> 116.24719 | I37: =H37/G37 -> 108.98174 | V37: =IFERROR((D37-#REF!)/D37,) | W37: =IFERROR((E37-#REF!)/E37,) | X37: =IFERROR((D37-#REF!)/D37,) | Y37: =IFERROR((E37-#REF!)/E37,)
A38: =iferror(if(B38>0,month(B38)&"-"&year(B38),B38),) -> 2-2026 | B38: 46054 | C38: AquaTru | D38: 2486.85 | E38: 25 | F38: 19 | G38: =E38/F38 -> 1.3157895 | H38: =D38/E38 -> 99.474 | I38: =H38/G38 -> 75.60024
C39: AirDoctor | D39: 1294.6 | E39: 4 | F39: 4 | G39: =E39/F39 -> 1 | H39: =D39/E39 -> 323.65 | I39: =H39/G39 -> 323.65
A40: =iferror(if(B40>0,month(B40)&"-"&year(B40),B40),) | C40: Rotorazer | D40: 0 | E40: 0 | F40: 0 | G40: =E40/F40 -> #DIV/0! | H40: =D40/E40 -> #DIV/0! | I40: =H40/G40 -> #DIV/0!
A41: =iferror(if(B41>0,month(B41)&"-"&year(B41),B41),) -> 2-2026 | B41: 46060 | C41: Ionic Pro | D41: 0 | E41: 0 | F41: 0 | G41: =E41/F41 -> #DIV/0! | H41: =D41/E41 -> #DIV/0! | I41: =H41/G41 -> #DIV/0!
A42: =iferror(if(B42>0,month(B42)&"-"&year(B42),B42),) | B42: 2026 - Week 6 | D42: =SUM(D38:D41) -> 3781.45 | E42: =SUM(E38:E41) -> 29 | F42: =SUM(F38:F41) -> 23 | G42: =E42/F42 -> 1.2608696 | H42: =D42/E42 -> 130.39483 | I42: =H42/G42 -> 103.41659 | V42: =IFERROR((D42-#REF!)/D42,) | W42: =IFERROR((E42-#REF!)/E42,) | X42: =IFERROR((D42-#REF!)/D42,) | Y42: =IFERROR((E42-#REF!)/E42,)
...

Sheet Lowes - 2026
A1: DATA SOURCE: https://app.dsco.io/insights/sales-insights
C2: WEEKLY PERFORMANCE | X2: =(#REF!+#REF!+#REF!+#REF!)-(monthly_reporting_2021!D17+monthly_reporting_2021!D23+monthly_reporting_2021!D29+monthly_reporting_2021!D35) -> #REF! | Y2: =((#REF!+#REF!+#REF!+#REF!)-(monthly_reporting_2021!E17+monthly_reporting_2021!E23+monthly_reporting_2021!E29+monthly_reporting_2021!E35))/(#REF!+#REF!+#REF!+#REF!) -> #REF!
C3: Total Sales | F3: Total Orders | J3: Total Units Sold
C4: =VLOOKUP("Current Week",$B$11:$Z$57,match("SALES",$B$11:$Z$11,0),FALSE) -> 0.29774407 | F4: =VLOOKUP("Current Week",$B$11:$Z$57,match("Units Sold",$B$11:$Z$11,0),FALSE) -> 7 | J4: =VLOOKUP("Current Week",$B$11:$Z$57,match("Ordered Items",$B$11:$Z$11,0),FALSE) -> 7
C5: =(C4-(VLOOKUP("Previous Week",$B$11:$Z$61,match("SALES",$B$11:$Z$11,0),FALSE)))/C4 -> 1 | F5: =(F4-(VLOOKUP("Previous Week",$B$11:$Z$71,match("Units Sold",$B$11:$Z$11,0),FALSE)))/F4 -> -0.42857143 | J5: =(J4-(VLOOKUP("Previous Week",$B$11:$Z$71,match("Ordered Items",$B$11:$Z$11,0),FALSE)))/J4 -> -0.42857143
C7: Advertising Sales | F7: Advertising Spend | J7: ACoS
C8: =VLOOKUP("Current Week",$B$11:$Z$57,match("AD SALES",$B$11:$Z$11,0),FALSE) -> #N/A | F8: =VLOOKUP("Current Week",$B$11:$Z$57,match("SP AD SPEND",$B$11:$Z$11,0),FALSE) -> #N/A | J8: =F8/C8 -> #N/A
C9: =(C8-(VLOOKUP("Previous Week",$B$11:$Z$71,match("AD SALES",$B$11:$Z$11,0),FALSE)))/C8 -> #N/A | F9: =(F8-(VLOOKUP("Previous Week",$B$11:$Z$71,match("SP AD SPEND",$B$11:$Z$11,0),FALSE)))/F8 -> #N/A | J9: =(J8-(VLOOKUP("Previous Week",$B$11:$Z$71,match("ACOS",$B$11:$Z$11,0),FALSE)))/J8 -> #N/A
D10: SALES METRICS | V10: MoM | X10: YoY
A11: Month-Code | B11: DATE | C11: BRAND | D11: GWV | E11: UNITS SOLD | F11: ORDERED ITEMS | G11: UNITS PER ORDER | H11: SALES PER ORDER | I11: ASP | V11: SALES | W11: UNITS | X11: SALES | Y11: UNITS
A13: =iferror(if(B13>0,month(B13)&"-"&year(B13),B13),) -> 12-2025 | B13: 46019 | C13: AquaTru | D13: 1724.74 | E13: 15 | F13: 12 | G13: =E13/F13 -> 1.25 | H13: =D13/E13 -> 114.98267 | I13: =H13/G13 -> 91.986133
C14: AirDoctor | D14: 521.25 | E14: 7 | F14: 5 | G14: =E14/F14 -> 1.4 | H14: =D14/E14 -> 74.464286 | I14: =H14/G14 -> 53.188776
A15: =iferror(if(B15>0,month(B15)&"-"&year(B15),B15),) | C15: Rotorazer | D15: 19 | E15: 1 | F15: 1 | G15: =E15/F15 -> 1 | H15: =D15/E15 -> 19 | I15: =H15/G15 -> 19
A16: =iferror(if(B16>0,month(B16)&"-"&year(B16),B16),) -> 1-2026 | B16: 46025 | C16: Ionic Pro | D16: 0 | E16: 0 | F16: 0 | G16: =E16/F16 -> #DIV/0! | H16: =D16/E16 -> #DIV/0! | I16: =H16/G16 -> #DIV/0!
A17: =iferror(if(B17>0,month(B17)&"-"&year(B17),B17),) | B17: 2026 - Week 1 | D17: =SUM(D13:D16) -> 2264.99 | E17: =SUM(E13:E16) -> 23 | F17: =SUM(F13:F16) -> 18 | G17: =E17/F17 -> 1.2777778 | H17: =D17/E17 -> 98.477826 | I17: =H17/G17 -> 77.069603 | V17: =IFERROR((D17-#REF!)/D17,) | W17: =IFERROR((E17-#REF!)/E17,) | X17: =IFERROR((D17-#REF!)/D17,) | Y17: =IFERROR((E17-#REF!)/E17,)
A18: =iferror(if(B18>0,month(B18)&"-"&year(B18),B18),) -> 1-2026 | B18: 46026 | C18: AquaTru | D18: 1821.45 | E18: 11 | F18: 11 | G18: =E18/F18 -> 1 | H18: =D18/E18 -> 165.58636 | I18: =H18/G18 -> 165.58636
C19: AirDoctor | D19: 1649.5 | E19: 11 | F19: 8 | G19: =E19/F19 -> 1.375 | H19: =D19/E19 -> 149.95455 | I19: =H19/G19 -> 109.05785
A20: =iferror(if(B20>0,month(B20)&"-"&year(B20),B20),) | C20: Rotorazer | D20: 0 | E20: 0 | F20: 0 | G20: =E20/F20 -> #DIV/0! | H20: =D20/E20 -> #DIV/0! | I20: =H20/G20 -> #DIV/0!
A21: =iferror(if(B21>0,month(B21)&"-"&year(B21),B21),) -> 1-2026 | B21: 46032 | C21: Ionic Pro | D21: 0 | E21: 0 | F21: 0 | G21: =E21/F21 -> #DIV/0! | H21: =D21/E21 -> #DIV/0! | I21: =H21/G21 -> #DIV/0!
A22: =iferror(if(B22>0,month(B22)&"-"&year(B22),B22),) | B22: 2026 - Week 2 | D22: =SUM(D18:D21) -> 3470.95 | E22: =SUM(E18:E21) -> 22 | F22: =SUM(F18:F21) -> 19 | G22: =E22/F22 -> 1.1578947 | H22: =D22/E22 -> 157.77045 | I22: =H22/G22 -> 136.2563 | V22: =IFERROR((D22-#REF!)/D22,) | W22: =IFERROR((E22-#REF!)/E22,) | X22: =IFERROR((D22-#REF!)/D22,) | Y22: =IFERROR((E22-#REF!)/E22,)
A23: =iferror(if(B23>0,month(B23)&"-"&year(B23),B23),) -> 1-2026 | B23: 46033 | C23: AquaTru | D23: 1038.69 | E23: 13 | F23: 12 | G23: =E23/F23 -> 1.0833333 | H23: =D23/E23 -> 79.899231 | I23: =H23/G23 -> 73.753136
C24: AirDoctor | D24: 2335.43 | E24: 9 | F24: 9 | G24: =E24/F24 -> 1 | H24: =D24/E24 -> 259.49222 | I24: =H24/G24 -> 259.49222
A25: =iferror(if(B25>0,month(B25)&"-"&year(B25),B25),) | C25: Rotorazer | D25: 310 | E25: 3 | F25: 3 | G25: =E25/F25 -> 1 | H25: =D25/E25 -> 103.33333 | I25: =H25/G25 -> 103.33333
A26: =iferror(if(B26>0,month(B26)&"-"&year(B26),B26),) -> 1-2026 | B26: 46039 | C26: Ionic Pro | D26: 0 | E26: 0 | F26: 0 | G26: =E26/F26 -> #DIV/0! | H26: =D26/E26 -> #DIV/0! | I26: =H26/G26 -> #DIV/0!
A27: =iferror(if(B27>0,month(B27)&"-"&year(B27),B27),) | B27: 2026 - Week 3 | D27: =SUM(D23:D26) -> 3684.12 | E27: =SUM(E23:E26) -> 25 | F27: =SUM(F23:F26) -> 24 | G27: =E27/F27 -> 1.0416667 | H27: =D27/E27 -> 147.3648 | I27: =H27/G27 -> 141.47021 | V27: =IFERROR((D27-#REF!)/D27,) | W27: =IFERROR((E27-#REF!)/E27,) | X27: =IFERROR((D27-#REF!)/D27,) | Y27: =IFERROR((E27-#REF!)/E27,)
A28: =iferror(if(B28>0,month(B28)&"-"&year(B28),B28),) -> 1-2026 | B28: 46040 | C28: AquaTru | D28: 888.42 | E28: 7 | F28: 7 | G28: =E28/F28 -> 1 | H28: =D28/E28 -> 126.91714 | I28: =H28/G28 -> 126.91714
A29: =iferror(if(B29>0,month(B29)&"-"&year(B29),B29),) | C29: AirDoctor | D29: 1550.66 | E29: 6 | F29: 5 | G29: =E29/F29 -> 1.2 | H29: =D29/E29 -> 258.44333 | I29: =H29/G29 -> 215.36944
C30: Rotorazer | D30: 129 | E30: 2 | F30: 2 | G30: =E30/F30 -> 1 | H30: =D30/E30 -> 64.5 | I30: =H30/G30 -> 64.5
A31: =iferror(if(B31>0,month(B31)&"-"&year(B31),B31),) -> 1-2026 | B31: 46046 | C31: Ionic Pro | D31: 0 | E31: 0 | F31: 0 | G31: =E31/F31 -> #DIV/0! | H31: =D31/E31 -> #DIV/0! | I31: =H31/G31 -> #DIV/0!
A32: =iferror(if(B32>0,month(B32)&"-"&year(B32),B32),) | B32: 2026 - Week 4 | D32: =SUM(D28:D31) -> 2568.08 | E32: =SUM(E28:E31) -> 15 | F32: =SUM(F28:F31) -> 14 | G32: =E32/F32 -> 1.0714286 | H32: =D32/E32 -> 171.20533 | I32: =H32/G32 -> 159.79164 | V32: =IFERROR((D32-#REF!)/D32,) | W32: =IFERROR((E32-#REF!)/E32,) | X32: =IFERROR((D32-#REF!)/D32,) | Y32: =IFERROR((E32-#REF!)/E32,)
A33: =iferror(if(B33>0,month(B33)&"-"&year(B33),B33),) -> 1-2026 | B33: 46047 | C33: AquaTru | D33: 1240.78 | E33: 7 | F33: 7 | G33: =E33/F33 -> 1 | H33: =D33/E33 -> 177.25429 | I33: =H33/G33 -> 177.25429
C34: AirDoctor | D34: 1017 | E34: 4 | F34: 4 | G34: =E34/F34 -> 1 | H34: =D34/E34 -> 254.25 | I34: =H34/G34 -> 254.25
A35: =iferror(if(B35>0,month(B35)&"-"&year(B35),B35),) | C35: Rotorazer | D35: 109 | E35: 2 | F35: 2 | G35: =E35/F35 -> 1 | H35: =D35/E35 -> 54.5 | I35: =H35/G35 -> 54.5
A36: =iferror(if(B36>0,month(B36)&"-"&year(B36),B36),) -> 1-2026 | B36: 46053 | C36: Ionic Pro | D36: 0 | E36: 0 | F36: 0 | G36: =E36/F36 -> #DIV/0! | H36: =D36/E36 -> #DIV/0! | I36: =H36/G36 -> #DIV/0!
A37: =iferror(if(B37>0,month(B37)&"-"&year(B37),B37),) | B37: 2026 - Week 5 | D37: =SUM(D33:D36) -> 2366.78 | E37: =SUM(E33:E36) -> 13 | F37: =SUM(F33:F36) -> 13 | G37: =E37/F37 -> 1 | H37: =D37/E37 -> 182.06 | I37: =H37/G37 -> 182.06 | V37: =IFERROR((D37-#REF!)/D37,) | W37: =IFERROR((E37-#REF!)/E37,) | X37: =IFERROR((D37-#REF!)/D37,) | Y37: =IFERROR((E37-#REF!)/E37,)
A38: =iferror(if(B38>0,month(B38)&"-"&year(B38),B38),) -> 2-2026 | B38: 46054 | C38: AquaTru | D38: 1386.19 | E38: 7 | F38: 7 | G38: =E38/F38 -> 1 | H38: =D38/E38 -> 198.02714 | I38: =H38/G38 -> 198.02714
C39: AirDoctor | D39: 1709.43 | E39: 11 | F39: 8 | G39: =E39/F39 -> 1.375 | H39: =D39/E39 -> 155.40273 | I39: =H39/G39 -> 113.02017
A40: =iferror(if(B40>0,month(B40)&"-"&year(B40),B40),) | C40: Rotorazer | D40: 38 | E40: 2 | F40: 1 | G40: =E40/F40 -> 2 | H40: =D40/E40 -> 19 | I40: =H40/G40 -> 9.5
A41: =iferror(if(B41>0,month(B41)&"-"&year(B41),B41),) -> 2-2026 | B41: 46060 | C41: Ionic Pro | D41: 0 | E41: 0 | F41: 0 | G41: =E41/F41 -> #DIV/0! | H41: =D41/E41 -> #DIV/0! | I41: =H41/G41 -> #DIV/0!
A42: =iferror(if(B42>0,month(B42)&"-"&year(B42),B42),) | B42: 2026 - Week 6 | D42: =SUM(D38:D41) -> 3133.62 | E42: =SUM(E38:E41) -> 20 | F42: =SUM(F38:F41) -> 16 | G42: =E42/F42 -> 1.25 | H42: =D42/E42 -> 156.681 | I42: =H42/G42 -> 125.3448 | V42: =IFERROR((D42-#REF!)/D42,) | W42: =IFERROR((E42-#REF!)/E42,) | X42: =IFERROR((D42-#REF!)/D42,) | Y42: =IFERROR((E42-#REF!)/E42,)
...

Sheet US
A1: Home Depot RPD - Orange Access - DATA SOURCES: https://us.orangeapronmedia.com/r/organizations
C2: WEEKLY PERFORMANCE | X2: =(#REF!+#REF!+#REF!+#REF!)-(monthly_reporting_2021!D17+monthly_reporting_2021!D23+monthly_reporting_2021!D29+monthly_reporting_2021!D35) -> #REF! | Y2: =((#REF!+#REF!+#REF!+#REF!)-(monthly_reporting_2021!E17+monthly_reporting_2021!E23+monthly_reporting_2021!E29+monthly_reporting_2021!E35))/(#REF!+#REF!+#REF!+#REF!) -> #REF!
K3: Total Sales | N3: Total Orders | S3: Total Units Sold
K4: =VLOOKUP("Current Week",$B$11:$X$96,match("SALES",$B$11:$X$11,0),FALSE) -> 0 | N4: =VLOOKUP("Current Week",$B$11:$X$96,match("Units Sold",$B$11:$X$11,0),FALSE) -> 0 | S4: =VLOOKUP("Current Week",$B$11:$X$96,match("Ordered Items",$B$11:$X$11,0),FALSE) -> 0
K5: =(K4-(VLOOKUP("Previous Week",$B$11:$X$101,match("SALES",$B$11:$X$11,0),FALSE)))/K4 -> #DIV/0! | N5: =(N4-(VLOOKUP("Previous Week",$B$11:$X$101,match("Units Sold",$B$11:$X$11,0),FALSE)))/N4 -> #DIV/0! | S5: =(S4-(VLOOKUP("Previous Week",$B$11:$X$101,match("Ordered Items",$B$11:$X$11,0),FALSE)))/S4 -> #DIV/0!
K7: Advertising Sales | N7: Advertising Spend | S7: ACoS
K8: =VLOOKUP("Current Week",$B$11:$X$96,match("AD SALES",$B$11:$X$11,0),FALSE) -> 571 | N8: =VLOOKUP("Current Week",$B$11:$X$96,match("SP AD SPEND",$B$11:$X$11,0),FALSE) -> 486.92 | S8: =N8/K8 -> 0.85274956
K9: =(K8-(VLOOKUP("Previous Week",$B$11:$X$101,match("AD SALES",$B$11:$X$11,0),FALSE)))/K8 -> -0.93695271 | N9: =(N8-(VLOOKUP("Previous Week",$B$11:$X$101,match("SP AD SPEND",$B$11:$X$11,0),FALSE)))/N8 -> -0.054567485 | S9: =(S8-(VLOOKUP("Previous Week",$B$11:$X$101,match("ACOS",$B$11:$X$11,0),FALSE)))/S8 -> 0.45555331
D10: SALES METRICS | L10: ADVERTISING PERFORMANCE | V10: MoM | X10: YoY
A11: Month-Code | B11: DATE | C11: Campaign Group per Brand | D11: SALES | E11: UNITS SOLD | F11: ORDERED ITEMS | G11: UNITS PER ORDER | H11: SALES PER ORDER | I11: ASP | J11: SP AD SPEND | K11: IMPRESSIONS | L11: UNIT SALES | M11: AD SALES | N11: ACoS | O11: ROAS (return on ad send) | P11: TACoS (Total Advertsing Cost of Sales) | Q11: REVENUE PERCENTAGE OF AD SALES | R11: ORGANIC SALES | S11: CPO | T11: SALES | U11: UNITS | V11: SALES | W11: UNITS
B13: 45921 | C13: AIRDOCTOR - Home Depot US | G13: =E13/F13 -> #DIV/0! | H13: =D13/E13 -> #DIV/0! | I13: =H13/G13 -> #DIV/0! | J13: 0 | K13: 0 | L13: 0 | M13: 0 | N13: =J13/M13 -> #DIV/0! | O13: =M13/J13 -> #DIV/0! | P13: =J13/D13 -> #DIV/0! | Q13: =M13/D13 -> #DIV/0! | R13: =D13-M13 -> 0 | S13: =J13/L13 -> #DIV/0!
C14: AQUA TRU - Home Depot US | G14: =E14/F14 -> #DIV/0! | H14: =D14/E14 -> #DIV/0! | I14: =H14/G14 -> #DIV/0! | J14: 0 | K14: 0 | L14: 0 | M14: 0 | N14: =J14/M14 -> #DIV/0! | O14: =M14/J14 -> #DIV/0! | P14: =J14/D14 -> #DIV/0! | Q14: =M14/D14 -> #DIV/0! | R14: =D14-M14 -> 0 | S14: =J14/L14 -> #DIV/0!
B15: to | C15: PAINT ZOOM - Home Depot US | G15: =E15/F15 -> #DIV/0! | H15: =D15/E15 -> #DIV/0! | I15: =H15/G15 -> #DIV/0! | J15: 0 | K15: 0 | L15: 0 | M15: 0 | N15: =(J15/M15) -> #DIV/0! | O15: =M15/J15 -> #DIV/0! | P15: =J15/D15 -> #DIV/0! | Q15: =M15/D15 -> #DIV/0! | R15: =D15-M15 -> 0 | S15: =J15/L15 -> #DIV/0!
A16: =iferror(if(B16>0,month(B16)&"-"&year(B16),B16),) -> 9-2025 | B16: 45927 | C16: ROTORAZER SAW - Home Depot US / ROTORAZERSAW - Home Depot US | G16: =E16/F16 -> #DIV/0! | H16: =D16/E16 -> #DIV/0! | I16: =H16/G16 -> #DIV/0! | J16: 0 | K16: 0 | L16: 0 | M16: 0 | N16: =J16/M16 -> #DIV/0! | O16: =M16/J16 -> #DIV/0! | P16: =J16/D16 -> #DIV/0! | Q16: =M16/D16 -> #DIV/0! | R16: =D16-M16 -> 0 | S16: =J16/L16 -> #DIV/0!
A17: =iferror(if(B17>0,month(B17)&"-"&year(B17),B17),) | B17: Week 39 | D17: =SUM(D13:D16) -> 0 | E17: =SUM(E13:E16) -> 0 | F17: =SUM(F13:F16) -> 0 | G17: =E17/F17 -> #DIV/0! | H17: =D17/E17 -> #DIV/0! | I17: =H17/G17 -> #DIV/0! | J17: =SUM(J13:J16) -> 0 | K17: =SUM(K13:K16) -> 0 | L17: =SUM(L13:L16) -> 0 | M17: =SUM(M13:M16) -> 0 | N17: =J17/M17 -> #DIV/0! | O17: =M17/J17 -> #DIV/0! | P17: =J17/D17 -> #DIV/0! | Q17: =M17/D17 -> #DIV/0! | R17: =SUM(R13:R16) -> 0 | S17: =J17/L17 -> #DIV/0! | T17: =IFERROR((D17-#REF!)/D17,) | U17: =IFERROR((E17-#REF!)/E17,) | V17: =IFERROR((D17-#REF!)/D17, ) | W17: =IFERROR((E17-#REF!)/E17, )
B18: 45928 | C18: AIRDOCTOR - Home Depot US | G18: =E18/F18 -> #DIV/0! | H18: =D18/E18 -> #DIV/0! | I18: =H18/G18 -> #DIV/0! | J18: 0 | K18: 0 | L18: 0 | M18: 0 | N18: =J18/M18 -> #DIV/0! | O18: =M18/J18 -> #DIV/0! | P18: =J18/D18 -> #DIV/0! | Q18: =M18/D18 -> #DIV/0! | R18: =D18-M18 -> 0 | S18: =J18/L18 -> #DIV/0!
C19: AQUA TRU - Home Depot US | G19: =E19/F19 -> #DIV/0! | H19: =D19/E19 -> #DIV/0! | I19: =H19/G19 -> #DIV/0! | J19: 0 | K19: 0 | L19: 0 | M19: 0 | N19: =J19/M19 -> #DIV/0! | O19: =M19/J19 -> #DIV/0! | P19: =J19/D19 -> #DIV/0! | Q19: =M19/D19 -> #DIV/0! | R19: =D19-M19 -> 0 | S19: =J19/L19 -> #DIV/0!
B20: to | C20: PAINT ZOOM - Home Depot US | G20: =E20/F20 -> #DIV/0! | H20: =D20/E20 -> #DIV/0! | I20: =H20/G20 -> #DIV/0! | J20: 0 | K20: 0 | L20: 0 | M20: 0 | N20: =(J20/M20) -> #DIV/0! | O20: =M20/J20 -> #DIV/0! | P20: =J20/D20 -> #DIV/0! | Q20: =M20/D20 -> #DIV/0! | R20: =D20-M20 -> 0 | S20: =J20/L20 -> #DIV/0!
A21: =iferror(if(B21>0,month(B21)&"-"&year(B21),B21),) -> 10-2025 | B21: 45934 | C21: ROTORAZER SAW - Home Depot US / ROTORAZERSAW - Home Depot US | G21: =E21/F21 -> #DIV/0! | H21: =D21/E21 -> #DIV/0! | I21: =H21/G21 -> #DIV/0! | J21: 0 | K21: 0 | L21: 0 | M21: 0 | N21: =J21/M21 -> #DIV/0! | O21: =M21/J21 -> #DIV/0! | P21: =J21/D21 -> #DIV/0! | Q21: =M21/D21 -> #DIV/0! | R21: =D21-M21 -> 0 | S21: =J21/L21 -> #DIV/0!
A22: =iferror(if(B22>0,month(B22)&"-"&year(B22),B22),) | B22: Week 40 | D22: =SUM(D18:D21) -> 0 | E22: =SUM(E18:E21) -> 0 | F22: =SUM(F18:F21) -> 0 | G22: =E22/F22 -> #DIV/0! | H22: =D22/E22 -> #DIV/0! | I22: =H22/G22 -> #DIV/0! | J22: =SUM(J18:J21) -> 0 | K22: =SUM(K18:K21) -> 0 | L22: =SUM(L18:L21) -> 0 | M22: =SUM(M18:M21) -> 0 | N22: =J22/M22 -> #DIV/0! | O22: =M22/J22 -> #DIV/0! | P22: =J22/D22 -> #DIV/0! | Q22: =M22/D22 -> #DIV/0! | R22: =SUM(R18:R21) -> 0 | S22: =J22/L22 -> #DIV/0! | T22: =IFERROR((D22-#REF!)/D22,) | U22: =IFERROR((E22-#REF!)/E22,) | V22: =IFERROR((D22-#REF!)/D22, ) | W22: =IFERROR((E22-#REF!)/E22, )
B23: 45935 | C23: AIRDOCTOR - Home Depot US | G23: =E23/F23 -> #DIV/0! | H23: =D23/E23 -> #DIV/0! | I23: =H23/G23 -> #DIV/0! | J23: 0 | K23: 0 | L23: 0 | M23: 0 | N23: =J23/M23 -> #DIV/0! | O23: =M23/J23 -> #DIV/0! | P23: =J23/D23 -> #DIV/0! | Q23: =M23/D23 -> #DIV/0! | R23: =D23-M23 -> 0 | S23: =J23/L23 -> #DIV/0!
C24: AQUA TRU - Home Depot US | G24: =E24/F24 -> #DIV/0! | H24: =D24/E24 -> #DIV/0! | I24: =H24/G24 -> #DIV/0! | J24: 0 | K24: 0 | L24: 0 | M24: 0 | N24: =J24/M24 -> #DIV/0! | O24: =M24/J24 -> #DIV/0! | P24: =J24/D24 -> #DIV/0! | Q24: =M24/D24 -> #DIV/0! | R24: =D24-M24 -> 0 | S24: =J24/L24 -> #DIV/0!
B25: to | C25: PAINT ZOOM - Home Depot US | G25: =E25/F25 -> #DIV/0! | H25: =D25/E25 -> #DIV/0! | I25: =H25/G25 -> #DIV/0! | J25: 0 | K25: 0 | L25: 0 | M25: 0 | N25: =(J25/M25) -> #DIV/0! | O25: =M25/J25 -> #DIV/0! | P25: =J25/D25 -> #DIV/0! | Q25: =M25/D25 -> #DIV/0! | R25: =D25-M25 -> 0 | S25: =J25/L25 -> #DIV/0!
